Workbook
Name UPDATE: 'Data Sheet'!$E$1

Sheet Input Sheet
B4: Company Description | C4: Infosys Limited is one of India's leading multinational information technology (IT) services and consulting companies, established in 1981 by N. R. Narayana Murthy and six other engineers. Headquartered in Bengaluru, the company provides a wide range of services, including IT consulting, software development, cloud computing, artificial intelligence (AI), data analytics, cybersecurity, digital transformation, and business process management. Infosys serves clients across various industries such as banking, healthcare, retail, manufacturing, telecommunications, and financial services in more than 50 countries.

Sheet Teaser
B2: ='Data Sheet'!B1&" - One Page Profile" -> INFOSYS LTD - One Page Profile
C4: ='Input Sheet'!C4:Q4 -> Infosys Limited is one of India's leading multinational information technology (IT) services and consulting companies, established in 1981 by N. R. Narayana Murthy and six other engineers. Headquartered in Bengaluru, the company provides a wide range of services, including IT consulting, software development, cloud computing, artificial intelligence (AI), data analytics, cybersecurity, digital transformation, and business process management. Infosys serves clients across various industries such as banking, healthcare, retail, manufacturing, telecommunications, and financial services in more than 50 countries.
B5: INR (Crs)
B6: Key Financials Metrics | C6: ='Profit & Loss'!G3 -> 44651 | D6: ='Profit & Loss'!H3 -> 45016 | E6: ='Profit & Loss'!I3 -> 45382 | F6: ='Profit & Loss'!J3 -> 45747 | G6: ='Profit & Loss'!K3 -> 46112 | I6: Share Price - 5Y
B8: Total Sales | C8: ='Profit & Loss'!G4 -> 121641 | D8: ='Profit & Loss'!H4 -> 146767 | E8: ='Profit & Loss'!I4 -> 153670 | F8: ='Profit & Loss'!J4 -> 162990 | G8: ='Profit & Loss'!K4 -> 178650
B9: Sales Growth (y-o-y) | C9: ='Profit & Loss'!G27 -> 0.21069552 | D9: ='Profit & Loss'!H27 -> 0.20655864 | E9: ='Profit & Loss'!I27 -> 0.047033734 | F9: ='Profit & Loss'!J27 -> 0.060649444 | G9: ='Profit & Loss'!K27 -> 0.096079514
B10: Gross Profit Margins (%) | C10: ='Profit & Loss'!G30 -> 0.82882416 | D10: ='Profit & Loss'!H30 -> 0.81940082 | E10: ='Profit & Loss'!I30 -> 0.82173489 | F10: ='Profit & Loss'!J30 -> 0.81215412 | G10: ='Profit & Loss'!K30 -> 0.81446963
B11: EBITDA Margins (%) | C11: ='Profit & Loss'!G32 -> 0.25888475 | D11: ='Profit & Loss'!H32 -> 0.23935898 | E11: ='Profit & Loss'!I32 -> 0.2370339 | F11: ='Profit & Loss'!J32 -> 0.24072642 | G11: ='Profit & Loss'!K32 -> 0.23666387
B12: EBIT Margins (%) | C12: ='Profit & Loss'!G34 -> 0.23030886 | D12: ='Profit & Loss'!H34 -> 0.21057186 | E12: ='Profit & Loss'!I34 -> 0.20659205 | F12: ='Profit & Loss'!J34 -> 0.21120314 | G12: ='Profit & Loss'!K34 -> 0.20922474
B13: Net Profit Margins (%) | C13: ='Profit & Loss'!G36 -> 0.18176437 | D13: ='Profit & Loss'!H36 -> 0.16417178 | E13: ='Profit & Loss'!I36 -> 0.17070996 | F13: ='Profit & Loss'!J36 -> 0.16389349 | G13: ='Profit & Loss'!K36 -> 0.16479149
B14: Earning per Share (in Rs) | C14: ='Profit & Loss'!G13 -> 52.559013 | D14: ='Profit & Loss'!H13 -> 58.079834 | E14: ='Profit & Loss'!I13 -> 63.198343 | F14: ='Profit & Loss'!J13 -> 64.317531 | G14: ='Profit & Loss'!K13 -> 72.590985
B15: EPS Growth (y-o-y) | C15: ='Profit & Loss'!G38 -> 0.15724348 | D15: ='Profit & Loss'!H38 -> 0.10504043 | E15: ='Profit & Loss'!I38 -> 0.088128839 | F15: ='Profit & Loss'!J38 -> 0.017709137 | G15: ='Profit & Loss'!K38 -> 0.12863452
B16: Dividend per Share (in Rs) | C16: ='Profit & Loss'!G40 -> 30.92115 | D16: ='Profit & Loss'!H40 -> 33.913127 | E16: ='Profit & Loss'!I40 -> 45.901371 | F16: ='Profit & Loss'!J40 -> 42.924422 | G16: ='Profit & Loss'!K40 -> 47.91005
B17: DPS Growth (y-o-y) | C17: ='Profit & Loss'!G41 -> 0.14865158 | D17: ='Profit & Loss'!H41 -> 0.096761529 | E17: ='Profit & Loss'!I41 -> 0.35349861 | F17: ='Profit & Loss'!J41 -> -0.064855345 | G17: ='Profit & Loss'!K41 -> 0.116149
B19: Key Financial Ratios | C19: =C6 -> 44651 | D19: =D6 -> 45016 | E19: =E6 -> 45382 | F19: =F6 -> 45747 | G19: =G6 -> 46112 | I19: Volumn-5Y
B21: Price to Earnings | C21: ='Profit & Loss'!G14 -> 36.280171 | D21: ='Profit & Loss'!H14 -> 24.585986 | E21: ='Profit & Loss'!I14 -> 23.703944 | F21: ='Profit & Loss'!J14 -> 24.420247 | G21: ='Profit & Loss'!K14 -> 17.228035
B22: EV/EBITDA | C22: ='Profit & Loss'!G48 -> 25.091505 | D22: ='Profit & Loss'!H48 -> 16.752785 | E22: ='Profit & Loss'!I48 -> 16.894951 | F22: ='Profit & Loss'!J48 -> 16.212409 | G22: ='Profit & Loss'!K48 -> 11.687993
B23: EV/Sales | C23: ='Profit & Loss'!G49 -> 6.4958081 | D23: ='Profit & Loss'!H49 -> 4.0099296 | E23: ='Profit & Loss'!I49 -> 4.0046761 | F23: ='Profit & Loss'!J49 -> 3.9027552 | G23: ='Profit & Loss'!K49 -> 2.7661256
B24: Price to Book Value | C24: ='Profit & Loss'!G51 -> 10.645715 | D24: ='Profit & Loss'!H51 -> 7.8560258 | E24: ='Profit & Loss'!I51 -> 7.0568974 | F24: ='Profit & Loss'!J51 -> 6.8080952 | G24: ='Profit & Loss'!K51 -> 5.4623846
B25: Retuen on Equity (%) | C25: ='Balance Sheet'!G23 -> 0.29343066 | D25: ='Balance Sheet'!H23 -> 0.31953267 | E25: ='Balance Sheet'!I23 -> 0.29770984 | F25: ='Balance Sheet'!J23 -> 0.27878895 | G25: ='Balance Sheet'!K23 -> 0.31706371
B26: Return on Capital Employed (%) | C26: ='Balance Sheet'!G24 -> 0.37304615 | D26: ='Balance Sheet'!H24 -> 0.40850909 | E26: ='Balance Sheet'!I24 -> 0.40468196 | F26: ='Balance Sheet'!J24 -> 0.37925394 | G26: ='Balance Sheet'!K24 -> 0.39220082
B28: Top 10 Shareholders | C28: ='Share Price'!I18 -> N. Share (In Crs) | E28: ='Share Price'!J18 -> Holding % | F28: ='Share Price'!K18 -> Market Value (In Crs) | I28: Shareholdering Pattern
B30: ='Share Price'!H19 -> LIFE INSURANCE CORPORATION OF INDIA | C30: ='Share Price'!I19 -> 43.278287 | E30: ='Share Price'!J19 -> 0.1154 | F30: ='Share Price'!K19 -> 49358.887
B31: ='Share Price'!H20 -> ICICI PRUDENTIAL MUTUAL FUND | C31: ='Share Price'!I20 -> 17.765388 | E31: ='Share Price'!J20 -> 0.0474 | F31: ='Share Price'!K20 -> 20261.425
B32: ='Share Price'!H21 -> SBI MUTUAL FUND | C32: ='Share Price'!I21 -> 17.46287 | E32: ='Share Price'!J21 -> 0.0466 | F32: ='Share Price'!K21 -> 19916.403
B33: ='Share Price'!H22 -> National Pension System Trust | C33: ='Share Price'!I22 -> 11.218018 | E33: ='Share Price'!J22 -> 0.0299 | F33: ='Share Price'!K22 -> 12794.149
B34: ='Share Price'!H23 -> SUDHA GOPALAKRISHNAN | C34: ='Share Price'!I23 -> 9.5357 | E34: ='Share Price'!J23 -> 0.0254 | F34: ='Share Price'!K23 -> 10875.466
B35: ='Share Price'!H24 -> NIPPON LIFE INDIA TRUSTEE | C35: ='Share Price'!I24 -> 8.4066207 | E35: ='Share Price'!J24 -> 0.0224 | F35: ='Share Price'!K24 -> 9587.7509
B36: ='Share Price'!H25 -> HDFC MUTUAL FUND | C36: ='Share Price'!I25 -> 7.6375295 | E36: ='Share Price'!J25 -> 0.0204 | F36: ='Share Price'!K25 -> 8710.6024
B37: ='Share Price'!H26 -> UTI MUTUAL FUND | C37: ='Share Price'!I26 -> 6.6441623 | E37: ='Share Price'!J26 -> 0.0177 | F37: ='Share Price'!K26 -> 7577.6671
B38: ='Share Price'!H27 -> ROHAN MURTY | C38: ='Share Price'!I27 -> 6.0812892 | E38: ='Share Price'!J27 -> 0.0162 | F38: ='Share Price'!K27 -> 6935.7103
B39: ='Share Price'!H28 -> SBI LIFE INSURANCE CO. LTD | C39: ='Share Price'!I28 -> 5.2826814 | E39: ='Share Price'!J28 -> 0.0141 | F39: ='Share Price'!K28 -> 6024.8981
B41: Managerial Remuneration | C41: Designation | E41: Remuneration | F41: X of Median Salary | I41: Capital Structure
B43: Mr. D. Sundaram | C43: ID | E43: 3.18 | F43: 29 | I43: Share Price as on Jun-26 | K43: ='Data Sheet'!B8 -> 1159.75
B44: Mr. Michael Gibbs | C44: ID | E44: 3.5 | F44: 31 | I44: Number of Share O/s | K44: ='Data Sheet'!B6 -> 405.82829
B45: Mr.Bobby Parik | C45: ID | E45: 2.51 | F45: 23 | I45: Market Capitalization | K45: =K43*K44 -> 470659.36
B46: Mrs. Chitra Nayak | C46: ID | E46: 3.12 | F46: 28 | I46: Less: Cash & Equivalents | K46: ='Data Sheet'!K69*-1 -> -22201
B47: Mr. Govind Iyer | C47: ID | E47: 2.7 | F47: 24 | I47: Add: Total Debt | K47: ='Data Sheet'!K59 -> 9176
B48: Mrs. Helene Auriol Potier | C48: ID | E48: 2.58 | F48: 23 | I48: Add: Minority Interest | K48: 445
B49: Mr. Nitin Paranjpe | C49: ID | E49: 2.31 | F49: 21 | I49: Enterprise Value | K49: =SUM(K45:K48) -> 458079.36
...

Sheet Share Price
B2: Date | C2: Close | D2: Volumn
B3: 44287 | C3: 16.375084 | D3: 4.2131 | E3: 1000000
B4: 44291 | C4: 16.685183 | D4: 3.9191
B5: 44292 | C5: 16.65934 | D5: 4.4286
B6: 44293 | C6: 16.547359 | D6: 4.6436
B7: 44294 | C7: 16.642113 | D7: 3.8623
B8: 44295 | C8: 16.831619 | D8: 5.2142
B9: 44298 | C9: 16.469833 | D9: 8.0592
B10: 44299 | C10: 15.858246 | D10: 11.3563
B11: 44300 | C11: 14.910712 | D11: 16.1775
B12: 44301 | C12: 15.505072 | D12: 13.1176
B13: 44302 | C13: 15.660123 | D13: 15.0055
B14: 44305 | C14: 15.729039 | D14: 5.4695
B15: 44306 | C15: 15.530917 | D15: 6.9852
B16: 44307 | C16: 15.591213 | D16: 7.2251
B17: 44308 | C17: 15.375866 | D17: 9.3738 | I17: 10000000 | J17: 100
B18: 44309 | C18: 15.41032 | D18: 4.6178 | H18: Shareholder's name | I18: N. Share (In Crs) | J18: Holding % | K18: Market Value (In Crs)
B19: 44312 | C19: 15.513689 | D19: 5.3131 | H19: LIFE INSURANCE CORPORATION OF INDIA | I19: 43.278287 | J19: 0.1154 | K19: =1140.5*I19 -> 49358.887
B20: 44313 | C20: 15.599826 | D20: 5.0422 | H20: ICICI PRUDENTIAL MUTUAL FUND | I20: 17.765388 | J20: 0.0474 | K20: =1140.5*I20 -> 20261.425
B21: 44314 | C21: 15.703192 | D21: 5.157 | H21: SBI MUTUAL FUND | I21: 17.46287 | J21: 0.0466 | K21: =1140.5*I21 -> 19916.403
B22: 44315 | C22: 15.901313 | D22: 6.5454 | H22: National Pension System Trust | I22: 11.218018 | J22: 0.0299 | K22: =1140.5*I22 -> 12794.149
B23: 44316 | C23: 15.573988 | D23: 7.0735 | H23: SUDHA GOPALAKRISHNAN | I23: 9.5357 | J23: 0.0254 | K23: =1140.5*I23 -> 10875.466
B24: 44319 | C24: 15.677355 | D24: 3.8005 | H24: NIPPON LIFE INDIA TRUSTEE | I24: 8.4066207 | J24: 0.0224 | K24: =1140.5*I24 -> 9587.7509
B25: 44320 | C25: 15.599826 | D25: 4.0877 | H25: HDFC MUTUAL FUND | I25: 7.6375295 | J25: 0.0204 | K25: =1140.5*I25 -> 8710.6024
B26: 44321 | C26: 15.754875 | D26: 3.7624 | H26: UTI MUTUAL FUND | I26: 6.6441623 | J26: 0.0177 | K26: =1140.5*I26 -> 7577.6671
B27: 44322 | C27: 16.021908 | D27: 10.4266 | H27: ROHAN MURTY | I27: 6.0812892 | J27: 0.0162 | K27: =1140.5*I27 -> 6935.7103
B28: 44323 | C28: ='Share Price'!I181 -> 0 | D28: 5.2208 | H28: SBI LIFE INSURANCE CO. LTD | I28: 5.2826814 | J28: 0.0141 | K28: =1140.5*I28 -> 6024.8981
B29: 44326 | C29: 15.815175 | D29: 9.1795
B30: 44327 | C30: 15.668739 | D30: 3.7294
B31: 44328 | C31: 15.36725 | D31: 5.6706
B32: 44329 | C32: 15.401707 | D32: 6.2649
B33: 44330 | C33: 15.642899 | D33: 3.2932
B34: 44333 | C34: 15.65151 | D34: 2.7345 | I34: DIIs | J34: 0.4319
B35: 44334 | C35: 15.729039 | D35: 5.303 | I35: FIIs | J35: 0.2845
B36: 44335 | C36: 15.884088 | D36: 4.3227 | I36: Promoters | J36: 0.1438
B37: 44336 | C37: 16.06498 | D37: 7.0196 | I37: Public & Government | J37: =13.54%+0.2% -> 0.1374
B38: 44337 | C38: 16.125277 | D38: 6.4483 | I38: Others | J38: 0.0023
B39: 44340 | C39: 16.082207 | D39: 3.8404
B40: 44341 | C40: 16.133886 | D40: 7.172
B41: 44342 | C41: 16.590429 | D41: 3.7535
...

Sheet Profit & Loss
A1: ='Data Sheet'!B1 -> INFOSYS LTD | H1: =UPDATE | M1: SCREENER.IN
A3: Narration | B3: ='Data Sheet'!B16 -> 42825 | C3: ='Data Sheet'!C16 -> 43190 | D3: ='Data Sheet'!D16 -> 43555 | E3: ='Data Sheet'!E16 -> 43921 | F3: ='Data Sheet'!F16 -> 44286 | G3: ='Data Sheet'!G16 -> 44651 | H3: ='Data Sheet'!H16 -> 45016 | I3: ='Data Sheet'!I16 -> 45382 | ... K3: ='Data Sheet'!K16 -> 46112 | L3: Trailing | M3: Best Case | N3: Worst Case
A4: Sales | B4: ='Data Sheet'!B17 -> 68484 | C4: ='Data Sheet'!C17 -> 70522 | D4: ='Data Sheet'!D17 -> 82675 | E4: ='Data Sheet'!E17 -> 90791 | F4: ='Data Sheet'!F17 -> 100472 | G4: ='Data Sheet'!G17 -> 121641 | H4: ='Data Sheet'!H17 -> 146767 | I4: ='Data Sheet'!I17 -> 153670 | ... K4: ='Data Sheet'!K17 -> 178650 | L4: =SUM(Quarters!H4:K4) -> 178650 | M4: =$K4+M23*K4 -> 195814.61 | N4: =$K4+N23*L4 -> 190748.54
A5: Expenses | B5: =SUM('Data Sheet'!B18,'Data Sheet'!B20:B24, -1*'Data Sheet'!B19) -> 49880 | C5: =SUM('Data Sheet'!C18,'Data Sheet'!C20:C24, -1*'Data Sheet'!C19) -> 51700 | D5: =SUM('Data Sheet'!D18,'Data Sheet'!D20:D24, -1*'Data Sheet'!D19) -> 62505 | E5: =SUM('Data Sheet'!E18,'Data Sheet'!E20:E24, -1*'Data Sheet'!E19) -> 68524 | F5: =SUM('Data Sheet'!F18,'Data Sheet'!F20:F24, -1*'Data Sheet'!F19) -> 72583 | G5: =SUM('Data Sheet'!G18,'Data Sheet'!G20:G24, -1*'Data Sheet'!G19) -> 90150 | H5: =SUM('Data Sheet'!H18,'Data Sheet'!H20:H24, -1*'Data Sheet'!H19) -> 111637 | I5: =SUM('Data Sheet'!I18,'Data Sheet'!I20:I24, -1*'Data Sheet'!I19) -> 117245 | ... K5: =SUM('Data Sheet'!K18,'Data Sheet'!K20:K24, -1*'Data Sheet'!K19) -> 136370 | L5: =SUM(Quarters!H5:K5) -> 136371 | M5: =M4-M6 -> 149188.11 | N5: =N4-N6 -> 145606.32
A6: Operating Profit | B6: =B4-B5 -> 18604 | C6: =C4-C5 -> 18822 | D6: =D4-D5 -> 20170 | E6: =E4-E5 -> 22267 | F6: =F4-F5 -> 27889 | G6: =G4-G5 -> 31491 | H6: =H4-H5 -> 35130 | I6: =I4-I5 -> 36425 | ... K6: =K4-K5 -> 42280 | L6: =SUM(Quarters!H6:K6) -> 42279 | M6: =M4*M24 -> 46626.497 | N6: =N4*N24 -> 45142.219
A7: Other Income | B7: ='Data Sheet'!B25 -> 3050 | C7: ='Data Sheet'!C25 -> 3311 | D7: ='Data Sheet'!D25 -> 2882 | E7: ='Data Sheet'!E25 -> 2803 | F7: ='Data Sheet'!F25 -> 2201 | G7: ='Data Sheet'!G25 -> 2295 | H7: ='Data Sheet'!H25 -> 2701 | I7: ='Data Sheet'!I25 -> 4711 | ... K7: ='Data Sheet'!K25 -> 3033 | L7: =SUM(Quarters!H7:K7) -> 3033 | M7: 0 | N7: 0
A8: Depreciation | B8: ='Data Sheet'!B26 -> 1703 | C8: ='Data Sheet'!C26 -> 1863 | D8: ='Data Sheet'!D26 -> 2011 | E8: ='Data Sheet'!E26 -> 2893 | F8: ='Data Sheet'!F26 -> 3267 | G8: ='Data Sheet'!G26 -> 3476 | H8: ='Data Sheet'!H26 -> 4225 | I8: ='Data Sheet'!I26 -> 4678 | ... K8: ='Data Sheet'!K26 -> 4902 | L8: =SUM(Quarters!H8:K8) -> 4901 | M8: =+$L8 -> 4901 | N8: =+$L8 -> 4901
A9: Interest | B9: ='Data Sheet'!B27 -> 0 | C9: ='Data Sheet'!C27 -> 0 | D9: ='Data Sheet'!D27 -> 0 | E9: ='Data Sheet'!E27 -> 170 | F9: ='Data Sheet'!F27 -> 195 | G9: ='Data Sheet'!G27 -> 200 | H9: ='Data Sheet'!H27 -> 284 | I9: ='Data Sheet'!I27 -> 470 | ... K9: ='Data Sheet'!K27 -> 416 | L9: =SUM(Quarters!H9:K9) -> 416 | M9: =+$L9 -> 416 | N9: =+$L9 -> 416
A10: Profit before tax | B10: ='Data Sheet'!B28 -> 19951 | C10: ='Data Sheet'!C28 -> 20270 | D10: ='Data Sheet'!D28 -> 21041 | E10: ='Data Sheet'!E28 -> 22007 | F10: ='Data Sheet'!F28 -> 26628 | G10: ='Data Sheet'!G28 -> 30110 | H10: ='Data Sheet'!H28 -> 33322 | I10: ='Data Sheet'!I28 -> 35988 | ... K10: ='Data Sheet'!K28 -> 39995 | L10: =SUM(Quarters!H10:K10) -> 39995 | M10: =M6+M7-SUM(M8:M9) -> 41309.497 | N10: =N6+N7-SUM(N8:N9) -> 39825.219
A11: Tax | B11: ='Data Sheet'!B29 -> 5598 | C11: ='Data Sheet'!C29 -> 4241 | D11: ='Data Sheet'!D29 -> 5631 | E11: ='Data Sheet'!E29 -> 5368 | F11: ='Data Sheet'!F29 -> 7205 | G11: ='Data Sheet'!G29 -> 7964 | H11: ='Data Sheet'!H29 -> 9214 | I11: ='Data Sheet'!I29 -> 9740 | ... K11: ='Data Sheet'!K29 -> 10521 | L11: =SUM(Quarters!H11:K11) -> 10521 | M11: =IF($L10>0,$L11/$L10,0) -> 0.26305788 | N11: =IF($L10>0,$L11/$L10,0) -> 0.26305788
A12: Net profit | B12: ='Data Sheet'!B30 -> 14353 | C12: ='Data Sheet'!C30 -> 16029 | D12: ='Data Sheet'!D30 -> 15404 | E12: ='Data Sheet'!E30 -> 16594 | F12: ='Data Sheet'!F30 -> 19351 | G12: ='Data Sheet'!G30 -> 22110 | H12: ='Data Sheet'!H30 -> 24095 | I12: ='Data Sheet'!I30 -> 26233 | ... K12: ='Data Sheet'!K30 -> 29440 | L12: =SUM(Quarters!H12:K12) -> 29440 | M12: =M10-M11*M10 -> 30442.708 | N12: =N10-N11*N10 -> 29348.882
A13: EPS | B13: =IF('Data Sheet'!B93>0,B12/'Data Sheet'!B93,0) -> 31.243606 | C13: =IF('Data Sheet'!C93>0,C12/'Data Sheet'!C93,0) -> 36.694748 | D13: =IF('Data Sheet'!D93>0,D12/'Data Sheet'!D93,0) -> 35.258303 | E13: =IF('Data Sheet'!E93>0,E12/'Data Sheet'!E93,0) -> 38.962198 | F13: =IF('Data Sheet'!F93>0,F12/'Data Sheet'!F93,0) -> 45.41742 | G13: =IF('Data Sheet'!G93>0,G12/'Data Sheet'!G93,0) -> 52.559013 | H13: =IF('Data Sheet'!H93>0,H12/'Data Sheet'!H93,0) -> 58.079834 | I13: =IF('Data Sheet'!I93>0,I12/'Data Sheet'!I93,0) -> 63.198343 | ... K13: =IF('Data Sheet'!K93>0,K12/'Data Sheet'!K93,0) -> 72.590985 | L13: =IF('Data Sheet'!$B6>0,'Profit & Loss'!L12/'Data Sheet'!$B6,0) -> 72.542996 | M13: =IF('Data Sheet'!$B6>0,'Profit & Loss'!M12/'Data Sheet'!$B6,0) -> 75.013766 | N13: =IF('Data Sheet'!$B6>0,'Profit & Loss'!N12/'Data Sheet'!$B6,0) -> 72.318471
A14: Price to earning | B14: =IF(B15>0,B15/B13,"") -> 16.359507 | C14: =IF(C15>0,C15/C13,"") -> 15.421825 | D14: =IF(D15>0,D15/D13,"") -> 21.097158 | E14: =IF(E15>0,E15/E13,"") -> 16.464677 | F14: =IF(F15>0,F15/F13,"") -> 30.121702 | G14: =IF(G15>0,G15/G13,"") -> 36.280171 | H14: =IF(H15>0,H15/H13,"") -> 24.585986 | I14: =IF(I15>0,I15/I13,"") -> 23.703944 | ... K14: =IF(K15>0,K15/K13,"") -> 17.228035 | L14: =IF(L13>0,L15/L13,0) -> 15.987071 | M14: =M25 -> 20.334824 | N14: =N25 -> 15.987071
A15: Price | B15: ='Data Sheet'!B90 -> 511.13 | C15: ='Data Sheet'!C90 -> 565.9 | D15: ='Data Sheet'!D90 -> 743.85 | E15: ='Data Sheet'!E90 -> 641.5 | F15: ='Data Sheet'!F90 -> 1368.05 | G15: ='Data Sheet'!G90 -> 1906.85 | H15: ='Data Sheet'!H90 -> 1427.95 | I15: ='Data Sheet'!I90 -> 1498.05 | ... K15: ='Data Sheet'!K90 -> 1250.6 | L15: ='Data Sheet'!B8 -> 1159.75 | M15: =M13*M14 -> 1525.3917 | N15: =N13*N14 -> 1156.1605
A17: RATIOS:
A18: Dividend Payout | B18: =IF('Data Sheet'!B30>0, 'Data Sheet'!B31/'Data Sheet'!B30, 0) -> 0.41047865 | C18: =IF('Data Sheet'!C30>0, 'Data Sheet'!C31/'Data Sheet'!C30, 0) -> 0.59052966 | D18: =IF('Data Sheet'!D30>0, 'Data Sheet'!D31/'Data Sheet'!D30, 0) -> 0.59870813 | E18: =IF('Data Sheet'!E30>0, 'Data Sheet'!E31/'Data Sheet'!E30, 0) -> 0.44757141 | F18: =IF('Data Sheet'!F30>0, 'Data Sheet'!F31/'Data Sheet'!F30, 0) -> 0.59271355 | G18: =IF('Data Sheet'!G30>0, 'Data Sheet'!G31/'Data Sheet'!G30, 0) -> 0.58831298 | H18: =IF('Data Sheet'!H30>0, 'Data Sheet'!H31/'Data Sheet'!H30, 0) -> 0.58390537 | I18: =IF('Data Sheet'!I30>0, 'Data Sheet'!I31/'Data Sheet'!I30, 0) -> 0.72630656 | ... K18: =IF('Data Sheet'!K30>0, 'Data Sheet'!K31/'Data Sheet'!K30, 0) -> 0.66
A19: OPM | B19: =IF(B6>0,B6/B4,0) -> 0.27165469 | C19: =IF(C6>0,C6/C4,0) -> 0.26689544 | D19: =IF(D6>0,D6/D4,0) -> 0.24396734 | E19: =IF(E6>0,E6/E4,0) -> 0.24525559 | F19: =IF(F6>0,F6/F4,0) -> 0.27757982 | G19: =IF(G6>0,G6/G4,0) -> 0.25888475 | H19: =IF(H6>0,H6/H4,0) -> 0.23935898 | I19: =IF(I6>0,I6/I4,0) -> 0.2370339 | ... L19: =IF(L6>0,L6/L4,0) -> 0.23665827
G22: TRENDS: | H22: 10 YEARS | I22: 7 YEARS | J22: 5 YEARS | K22: 3 YEARS | L22: RECENT | M22: BEST | N22: WORST
G23: Sales Growth | H23: =IF(B4=0,"",POWER($K4/B4,1/9)-1) -> 0.11241852 | I23: =IF(D4=0,"",POWER($K4/D4,1/7)-1) -> 0.11635961 | J23: =IF(F4=0,"",POWER($K4/F4,1/5)-1) -> 0.12199674 | K23: =IF(H4=0,"",POWER($K4/H4, 1/3)-1) -> 0.067722024 | L23: =IF(ISERROR(MAX(IF(J4=0,"",(K4-J4)/J4),IF(K4=0,"",(L4-K4)/K4))),"",MAX(IF(J4=0,"",(K4-J4)/J4),IF(K4=0,"",(L4-K4)/K4))) -> 0.096079514 | M23: =MAX(K23:L23) -> 0.096079514 | N23: =MIN(H23:L23) -> 0.067722024
G24: OPM | H24: =IF(SUM(B4:$K$4)=0,"",SUMPRODUCT(B19:$K$19,B4:$K$4)/SUM(B4:$K$4)) -> 0.24842648 | I24: =IF(SUM(E4:$K$4)=0,"",SUMPRODUCT(E19:$K$19,E4:$K$4)/SUM(E4:$K$4)) -> 0.2457829 | J24: =IF(SUM(G4:$K$4)=0,"",SUMPRODUCT(G19:$K$19,G4:$K$4)/SUM(G4:$K$4)) -> 0.2416625 | K24: =IF(SUM(I4:$K$4)=0, "", SUMPRODUCT(I19:$K$19,I4:$K$4)/SUM(I4:$K$4)) -> 0.23811552 | L24: =L19 -> 0.23665827 | M24: =MAX(K24:L24) -> 0.23811552 | N24: =MIN(H24:L24) -> 0.23665827
G25: Price to Earning | H25: =IF(ISERROR(AVERAGEIF(B14:$L14,">0")),"",AVERAGEIF(B14:$L14,">0")) -> 21.97003 | I25: =IF(ISERROR(AVERAGEIF(E14:$L14,">0")),"",AVERAGEIF(E14:$L14,">0")) -> 23.598979 | J25: =IF(ISERROR(AVERAGEIF(G14:$L14,">0")),"",AVERAGEIF(G14:$L14,">0")) -> 23.700909 | K25: =IF(ISERROR(AVERAGEIF(I14:$L14,">0")),"",AVERAGEIF(I14:$L14,">0")) -> 20.334824 | L25: =L14 -> 15.987071 | M25: =MAX(K25:L25) -> 20.334824 | N25: =MIN(H25:L25) -> 15.987071
A27: Sales Growth y-o-y | C27: =C4/B4-1 -> 0.029758776 | D27: =D4/C4-1 -> 0.1723292 | E27: =E4/D4-1 -> 0.098167523 | F27: =F4/E4-1 -> 0.10662951 | G27: =G4/F4-1 -> 0.21069552 | H27: =H4/G4-1 -> 0.20655864 | I27: =I4/H4-1 -> 0.047033734 | J27: =J4/I4-1 -> 0.060649444 | K27: =K4/J4-1 -> 0.096079514
A29: Gross profit | B29: ='Data Sheet'!B17-'Data Sheet'!B18-'Data Sheet'!B19-'Data Sheet'!B20-'Data Sheet'!B21 -> 61544 | C29: ='Data Sheet'!C17-'Data Sheet'!C18-'Data Sheet'!C19-'Data Sheet'!C20-'Data Sheet'!C21 -> 63029 | D29: ='Data Sheet'!D17-'Data Sheet'!D18-'Data Sheet'!D19-'Data Sheet'!D20-'Data Sheet'!D21 -> 72552 | E29: ='Data Sheet'!E17-'Data Sheet'!E18-'Data Sheet'!E19-'Data Sheet'!E20-'Data Sheet'!E21 -> 79476 | F29: ='Data Sheet'!F17-'Data Sheet'!F18-'Data Sheet'!F19-'Data Sheet'!F20-'Data Sheet'!F21 -> 87529 | G29: ='Data Sheet'!G17-'Data Sheet'!G18-'Data Sheet'!G19-'Data Sheet'!G20-'Data Sheet'!G21 -> 100819 | H29: ='Data Sheet'!H17-'Data Sheet'!H18-'Data Sheet'!H19-'Data Sheet'!H20-'Data Sheet'!H21 -> 120261 | I29: ='Data Sheet'!I17-'Data Sheet'!I18-'Data Sheet'!I19-'Data Sheet'!I20-'Data Sheet'!I21 -> 126276 | ... K29: ='Data Sheet'!K17-'Data Sheet'!K18-'Data Sheet'!K19-'Data Sheet'!K20-'Data Sheet'!K21 -> 145505
A30: GPM | B30: =B29/B4 -> 0.89866246 | C30: =C29/C4 -> 0.89374947 | D30: =D29/D4 -> 0.8775567 | E30: =E29/E4 -> 0.87537311 | F30: =F29/F4 -> 0.87117804 | G30: =G29/G4 -> 0.82882416 | H30: =H29/H4 -> 0.81940082 | I30: =I29/I4 -> 0.82173489 | ... K30: =K29/K4 -> 0.81446963
A32: EBITDA Margins | B32: =B6/B4 -> 0.27165469 | C32: =C6/C4 -> 0.26689544 | D32: =D6/D4 -> 0.24396734 | E32: =E6/E4 -> 0.24525559 | F32: =F6/F4 -> 0.27757982 | G32: =G6/G4 -> 0.25888475 | H32: =H6/H4 -> 0.23935898 | I32: =I6/I4 -> 0.2370339 | ... K32: =K6/K4 -> 0.23666387
A34: EBIT Margins | B34: =(B6-B8)/B4 -> 0.24678757 | C34: =(C6-C8)/C4 -> 0.24047815 | D34: =(D6-D8)/D4 -> 0.21964318 | E34: =(E6-E8)/E4 -> 0.2133912 | F34: =(F6-F8)/F4 -> 0.2450633 | G34: =(G6-G8)/G4 -> 0.23030886 | H34: =(H6-H8)/H4 -> 0.21057186 | I34: =(I6-I8)/I4 -> 0.20659205 | ... K34: =(K6-K8)/K4 -> 0.20922474
A36: Net Profit Margins | B36: =B12/B4 -> 0.2095818 | C36: =C12/C4 -> 0.22729077 | D36: =D12/D4 -> 0.18631993 | E36: =E12/E4 -> 0.18277142 | F36: =F12/F4 -> 0.19260092 | G36: =G12/G4 -> 0.18176437 | H36: =H12/H4 -> 0.16417178 | I36: =I12/I4 -> 0.17070996 | ... K36: =K12/K4 -> 0.16479149
A38: EPS Growth | C38: =(C13/B13)-1 -> 0.17447227 | D38: =(D13/C13)-1 -> -0.039145803 | E38: =(E13/D13)-1 -> 0.10505028 | F38: =(F13/E13)-1 -> 0.1656791 | G38: =(G13/F13)-1 -> 0.15724348 | H38: =(H13/G13)-1 -> 0.10504043 | I38: =(I13/H13)-1 -> 0.088128839 | J38: =(J13/I13)-1 -> 0.017709137 | K38: =(K13/J13)-1 -> 0.12863452
A40: Dividend Per Share | B40: ='Profit & Loss'!B13*'Profit & Loss'!B18 -> 12.824833 | C40: ='Profit & Loss'!C13*'Profit & Loss'!C18 -> 21.669337 | D40: ='Profit & Loss'!D13*'Profit & Loss'!D18 -> 21.109433 | E40: ='Profit & Loss'!E13*'Profit & Loss'!E18 -> 17.438366 | F40: ='Profit & Loss'!F13*'Profit & Loss'!F18 -> 26.91952 | G40: ='Profit & Loss'!G13*'Profit & Loss'!G18 -> 30.92115 | H40: ='Profit & Loss'!H13*'Profit & Loss'!H18 -> 33.913127 | I40: ='Profit & Loss'!I13*'Profit & Loss'!I18 -> 45.901371 | ... K40: ='Profit & Loss'!K13*'Profit & Loss'!K18 -> 47.91005
A41: Dividend Growth | C41: =C40/B40-1 -> 0.68963897 | D41: =D40/C40-1 -> -0.02583858 | E41: =E40/D40-1 -> -0.17390646 | F41: =F40/E40-1 -> 0.54369512 | G41: =G40/F40-1 -> 0.14865158 | H41: =H40/G40-1 -> 0.096761529 | I41: =I40/H40-1 -> 0.35349861 | J41: =J40/I40-1 -> -0.064855345 | K41: =K40/J40-1 -> 0.116149
A43: Market Capitalization | B43: ='Data Sheet'!B93*'Data Sheet'!B90 -> 234808.01 | C43: ='Data Sheet'!C93*'Data Sheet'!C90 -> 247196.44 | D43: ='Data Sheet'!D93*'Data Sheet'!D90 -> 324980.63 | E43: ='Data Sheet'!E93*'Data Sheet'!E90 -> 273214.85 | F43: ='Data Sheet'!F93*'Data Sheet'!F90 -> 582885.06 | G43: ='Data Sheet'!G93*'Data Sheet'!G90 -> 802154.59 | H43: ='Data Sheet'!H93*'Data Sheet'!H90 -> 592399.34 | I43: ='Data Sheet'!I93*'Data Sheet'!I90 -> 621825.57 | ... K43: ='Data Sheet'!K93*'Data Sheet'!K90 -> 507193.34
A44: Debt | E44: ='Data Sheet'!E59 -> 4633 | F44: ='Data Sheet'!F59 -> 5325 | G44: ='Data Sheet'!G59 -> 5474 | H44: ='Data Sheet'!H59 -> 8299 | I44: ='Data Sheet'!I59 -> 8359 | J44: ='Data Sheet'!J59 -> 8227 | K44: ='Data Sheet'!K59 -> 9176
A45: Cash | B45: ='Data Sheet'!B69 -> 22625 | C45: ='Data Sheet'!C69 -> 19818 | D45: ='Data Sheet'!D69 -> 19568 | E45: ='Data Sheet'!E69 -> 18649 | F45: ='Data Sheet'!F69 -> 24714 | G45: ='Data Sheet'!G69 -> 17472 | H45: ='Data Sheet'!H69 -> 12173 | I45: ='Data Sheet'!I69 -> 14786 | ... K45: ='Data Sheet'!K69 -> 22201
A46: EV | B46: =B43+B44-B45 -> 212183.01 | C46: =C43+C44-C45 -> 227378.44 | D46: =D43+D44-D45 -> 305412.63 | E46: =E43+E44-E45 -> 259198.85 | F46: =F43+F44-F45 -> 563496.06 | G46: =G43+G44-G45 -> 790156.59 | H46: =H43+H44-H45 -> 588525.34 | I46: =I43+I44-I45 -> 615398.57 | ... K46: =K43+K44-K45 -> 494168.34
A48: EV EBITDA | B48: =B46/B6 -> 11.405236 | C48: =C46/C6 -> 12.080461 | D48: =D46/D6 -> 15.141925 | E48: =E46/E6 -> 11.640493 | F48: =F46/F6 -> 20.204958 | G48: =G46/G6 -> 25.091505 | H48: =H46/H6 -> 16.752785 | I48: =I46/I6 -> 16.894951 | ... K48: =K46/K6 -> 11.687993
A49: EV Sales | B49: =B46/B4 -> 3.0982859 | C49: =C46/C4 -> 3.2242199 | D49: =D46/D4 -> 3.6941352 | E49: =E46/E4 -> 2.8548959 | F49: =F46/F4 -> 5.6084886 | G49: =G46/G4 -> 6.4958081 | H49: =H46/H4 -> 4.0099296 | I49: =I46/I4 -> 4.0046761 | ... K49: =K46/K4 -> 2.7661256
A51: P/B | B51: =B43/'Balance Sheet'!B26 -> 3.4039026 | C51: =C43/'Balance Sheet'!C26 -> 3.8075326 | D51: =D43/'Balance Sheet'!D26 -> 5.0037049 | E51: =E43/'Balance Sheet'!E26 -> 4.1744057 | F51: =F43/'Balance Sheet'!F26 -> 7.634282 | G51: =G43/'Balance Sheet'!G26 -> 10.645715 | H51: =H43/'Balance Sheet'!H26 -> 7.8560258 | I51: =I43/'Balance Sheet'!I26 -> 7.0568974 | ... K51: =K43/'Balance Sheet'!K26 -> 5.4623846

Sheet Quarters
A1: ='Profit & Loss'!A1 -> INFOSYS LTD | E1: =UPDATE | J1: SCREENER.IN
A3: Narration | B3: ='Data Sheet'!B41 -> 45291 | C3: ='Data Sheet'!C41 -> 45382 | D3: ='Data Sheet'!D41 -> 45473 | E3: ='Data Sheet'!E41 -> 45565 | F3: ='Data Sheet'!F41 -> 45657 | G3: ='Data Sheet'!G41 -> 45747 | H3: ='Data Sheet'!H41 -> 45838 | I3: ='Data Sheet'!I41 -> 45930 | ... K3: ='Data Sheet'!K41 -> 46112
A4: Sales | B4: ='Data Sheet'!B42 -> 38821 | C4: ='Data Sheet'!C42 -> 37923 | D4: ='Data Sheet'!D42 -> 39315 | E4: ='Data Sheet'!E42 -> 40986 | F4: ='Data Sheet'!F42 -> 41764 | G4: ='Data Sheet'!G42 -> 40925 | H4: ='Data Sheet'!H42 -> 42279 | I4: ='Data Sheet'!I42 -> 44490 | ... K4: ='Data Sheet'!K42 -> 46402
A5: Expenses | B5: ='Data Sheet'!B43 -> 29684 | C5: ='Data Sheet'!C43 -> 29139 | D5: ='Data Sheet'!D43 -> 29878 | E5: ='Data Sheet'!E43 -> 31177 | F5: ='Data Sheet'!F43 -> 31649 | G5: ='Data Sheet'!G43 -> 31051 | H5: ='Data Sheet'!H43 -> 32336 | I5: ='Data Sheet'!I43 -> 33955 | ... K5: ='Data Sheet'!K43 -> 35235
A6: Operating Profit | B6: ='Data Sheet'!B50 -> 9137 | C6: ='Data Sheet'!C50 -> 8784 | D6: ='Data Sheet'!D50 -> 9437 | E6: ='Data Sheet'!E50 -> 9809 | F6: ='Data Sheet'!F50 -> 10115 | G6: ='Data Sheet'!G50 -> 9874 | H6: ='Data Sheet'!H50 -> 9943 | I6: ='Data Sheet'!I50 -> 10535 | ... K6: ='Data Sheet'!K50 -> 11167
A7: Other Income | B7: ='Data Sheet'!B44 -> 789 | C7: ='Data Sheet'!C44 -> 2729 | D7: ='Data Sheet'!D44 -> 838 | E7: ='Data Sheet'!E44 -> 712 | F7: ='Data Sheet'!F44 -> 859 | G7: ='Data Sheet'!G44 -> 1190 | H7: ='Data Sheet'!H44 -> 1042 | I7: ='Data Sheet'!I44 -> 982 | ... K7: ='Data Sheet'!K44 -> 1159
A8: Depreciation | B8: ='Data Sheet'!B45 -> 1176 | C8: ='Data Sheet'!C45 -> 1163 | D8: ='Data Sheet'!D45 -> 1149 | E8: ='Data Sheet'!E45 -> 1160 | F8: ='Data Sheet'!F45 -> 1203 | G8: ='Data Sheet'!G45 -> 1299 | H8: ='Data Sheet'!H45 -> 1140 | I8: ='Data Sheet'!I45 -> 1182 | ... K8: ='Data Sheet'!K45 -> 1424
A9: Interest | B9: ='Data Sheet'!B46 -> 131 | C9: ='Data Sheet'!C46 -> 110 | D9: ='Data Sheet'!D46 -> 105 | E9: ='Data Sheet'!E46 -> 108 | F9: ='Data Sheet'!F46 -> 101 | G9: ='Data Sheet'!G46 -> 102 | H9: ='Data Sheet'!H46 -> 105 | I9: ='Data Sheet'!I46 -> 106 | ... K9: ='Data Sheet'!K46 -> 105
A10: Profit before tax | B10: ='Data Sheet'!B47 -> 8619 | C10: ='Data Sheet'!C47 -> 10240 | D10: ='Data Sheet'!D47 -> 9021 | E10: ='Data Sheet'!E47 -> 9253 | F10: ='Data Sheet'!F47 -> 9670 | G10: ='Data Sheet'!G47 -> 9663 | H10: ='Data Sheet'!H47 -> 9740 | I10: ='Data Sheet'!I47 -> 10229 | ... K10: ='Data Sheet'!K47 -> 10797
A11: Tax | B11: ='Data Sheet'!B48 -> 2506 | C11: ='Data Sheet'!C48 -> 2265 | D11: ='Data Sheet'!D48 -> 2647 | E11: ='Data Sheet'!E48 -> 2737 | F11: ='Data Sheet'!F48 -> 2848 | G11: ='Data Sheet'!G48 -> 2625 | H11: ='Data Sheet'!H48 -> 2816 | I11: ='Data Sheet'!I48 -> 2854 | ... K11: ='Data Sheet'!K48 -> 2288
A12: Net profit | B12: ='Data Sheet'!B49 -> 6106 | C12: ='Data Sheet'!C49 -> 7969 | D12: ='Data Sheet'!D49 -> 6368 | E12: ='Data Sheet'!E49 -> 6506 | F12: ='Data Sheet'!F49 -> 6806 | G12: ='Data Sheet'!G49 -> 7033 | H12: ='Data Sheet'!H49 -> 6921 | I12: ='Data Sheet'!I49 -> 7364 | ... K12: ='Data Sheet'!K49 -> 8501
A14: OPM | B14: =IF(B4>0,B6/B4,"") -> 0.2353623 | C14: =IF(C4>0,C6/C4,"") -> 0.23162724 | D14: =IF(D4>0,D6/D4,"") -> 0.24003561 | E14: =IF(E4>0,E6/E4,"") -> 0.23932562 | F14: =IF(F4>0,F6/F4,"") -> 0.24219423 | G14: =IF(G4>0,G6/G4,"") -> 0.24127062 | H14: =IF(H4>0,H6/H4,"") -> 0.23517586 | I14: =IF(I4>0,I6/I4,"") -> 0.23679479 | ... K14: =IF(K4>0,K6/K4,"") -> 0.24065773

Sheet Balance Sheet
A1: ='Profit & Loss'!A1 -> INFOSYS LTD | E1: =UPDATE | J1: SCREENER.IN
A3: Narration | B3: ='Data Sheet'!B56 -> 42825 | C3: ='Data Sheet'!C56 -> 43190 | D3: ='Data Sheet'!D56 -> 43555 | E3: ='Data Sheet'!E56 -> 43921 | F3: ='Data Sheet'!F56 -> 44286 | G3: ='Data Sheet'!G56 -> 44651 | H3: ='Data Sheet'!H56 -> 45016 | I3: ='Data Sheet'!I56 -> 45382 | ... K3: ='Data Sheet'!K56 -> 46112
A4: Equity Share Capital | B4: ='Data Sheet'!B57 -> 1144 | C4: ='Data Sheet'!C57 -> 1088 | D4: ='Data Sheet'!D57 -> 2170 | E4: ='Data Sheet'!E57 -> 2122 | F4: ='Data Sheet'!F57 -> 2124 | G4: ='Data Sheet'!G57 -> 2098 | H4: ='Data Sheet'!H57 -> 2069 | I4: ='Data Sheet'!I57 -> 2071 | ... K4: ='Data Sheet'!K57 -> 2024
A5: Reserves | B5: ='Data Sheet'!B58 -> 67838 | C5: ='Data Sheet'!C58 -> 63835 | D5: ='Data Sheet'!D58 -> 62778 | E5: ='Data Sheet'!E58 -> 63328 | F5: ='Data Sheet'!F58 -> 74227 | G5: ='Data Sheet'!G58 -> 73252 | H5: ='Data Sheet'!H58 -> 73338 | I5: ='Data Sheet'!I58 -> 86045 | ... K5: ='Data Sheet'!K58 -> 90828
A6: Borrowings | B6: ='Data Sheet'!B59 -> 0 | C6: ='Data Sheet'!C59 -> 0 | D6: ='Data Sheet'!D59 -> 0 | E6: ='Data Sheet'!E59 -> 4633 | F6: ='Data Sheet'!F59 -> 5325 | G6: ='Data Sheet'!G59 -> 5474 | H6: ='Data Sheet'!H59 -> 8299 | I6: ='Data Sheet'!I59 -> 8359 | ... K6: ='Data Sheet'!K59 -> 9176
A7: Other Liabilities | B7: ='Data Sheet'!B60 -> 14166 | C7: ='Data Sheet'!C60 -> 14426 | D7: ='Data Sheet'!D60 -> 19118 | E7: ='Data Sheet'!E60 -> 21717 | F7: ='Data Sheet'!F60 -> 25835 | G7: ='Data Sheet'!G60 -> 35905 | H7: ='Data Sheet'!H60 -> 40890 | I7: ='Data Sheet'!I60 -> 40885 | ... K7: ='Data Sheet'!K60 -> 52260
A8: Total | B8: ='Data Sheet'!B61 -> 83148 | C8: ='Data Sheet'!C61 -> 79349 | D8: ='Data Sheet'!D61 -> 84066 | E8: ='Data Sheet'!E61 -> 91800 | F8: ='Data Sheet'!F61 -> 107511 | G8: ='Data Sheet'!G61 -> 116729 | H8: ='Data Sheet'!H61 -> 124596 | I8: ='Data Sheet'!I61 -> 137360 | ... K8: ='Data Sheet'!K61 -> 154288
A10: Net Block | B10: ='Data Sheet'!B62 -> 14179 | C10: ='Data Sheet'!C62 -> 12574 | D10: ='Data Sheet'!D62 -> 15710 | E10: ='Data Sheet'!E62 -> 23789 | F10: ='Data Sheet'!F62 -> 25505 | G10: ='Data Sheet'!G62 -> 25800 | H10: ='Data Sheet'!H62 -> 29225 | I10: ='Data Sheet'!I62 -> 27622 | ... K10: ='Data Sheet'!K62 -> 33770
A11: Capital Work in Progress | B11: ='Data Sheet'!B63 -> 1365 | C11: ='Data Sheet'!C63 -> 1606 | D11: ='Data Sheet'!D63 -> 1388 | E11: ='Data Sheet'!E63 -> 954 | F11: ='Data Sheet'!F63 -> 922 | G11: ='Data Sheet'!G63 -> 416 | H11: ='Data Sheet'!H63 -> 288 | I11: ='Data Sheet'!I63 -> 293 | ... K11: ='Data Sheet'!K63 -> 526
A12: Investments | B12: ='Data Sheet'!B64 -> 16423 | C12: ='Data Sheet'!C64 -> 12163 | D12: ='Data Sheet'!D64 -> 11261 | E12: ='Data Sheet'!E64 -> 8792 | F12: ='Data Sheet'!F64 -> 14205 | G12: ='Data Sheet'!G64 -> 20324 | H12: ='Data Sheet'!H64 -> 19478 | I12: ='Data Sheet'!I64 -> 24623 | ... K12: ='Data Sheet'!K64 -> 21880
A13: Other Assets | B13: ='Data Sheet'!B65 -> 51181 | C13: ='Data Sheet'!C65 -> 53006 | D13: ='Data Sheet'!D65 -> 55707 | E13: ='Data Sheet'!E65 -> 58265 | F13: ='Data Sheet'!F65 -> 66879 | G13: ='Data Sheet'!G65 -> 70189 | H13: ='Data Sheet'!H65 -> 75605 | I13: ='Data Sheet'!I65 -> 84822 | ... K13: ='Data Sheet'!K65 -> 98112
A14: Total | B14: ='Data Sheet'!B66 -> 83148 | C14: ='Data Sheet'!C66 -> 79349 | D14: ='Data Sheet'!D66 -> 84066 | E14: ='Data Sheet'!E66 -> 91800 | F14: ='Data Sheet'!F66 -> 107511 | G14: ='Data Sheet'!G66 -> 116729 | H14: ='Data Sheet'!H66 -> 124596 | I14: ='Data Sheet'!I66 -> 137360 | ... K14: ='Data Sheet'!K66 -> 154288
A16: Working Capital | B16: =B13-B7 -> 37015 | C16: =C13-C7 -> 38580 | D16: =D13-D7 -> 36589 | E16: =E13-E7 -> 36548 | F16: =F13-F7 -> 41044 | G16: =G13-G7 -> 34284 | H16: =H13-H7 -> 34715 | I16: =I13-I7 -> 43937 | ... K16: =K13-K7 -> 45852
A17: Debtors | B17: ='Data Sheet'!B67 -> 12322 | C17: ='Data Sheet'!C67 -> 13142 | D17: ='Data Sheet'!D67 -> 14827 | E17: ='Data Sheet'!E67 -> 18487 | F17: ='Data Sheet'!F67 -> 19294 | G17: ='Data Sheet'!G67 -> 22698 | H17: ='Data Sheet'!H67 -> 25424 | I17: ='Data Sheet'!I67 -> 30193 | ... K17: ='Data Sheet'!K67 -> 35234
A18: Inventory | B18: ='Data Sheet'!B68 -> 0 | C18: ='Data Sheet'!C68 -> 0 | D18: ='Data Sheet'!D68 -> 0 | E18: ='Data Sheet'!E68 -> 0 | F18: ='Data Sheet'!F68 -> 0 | G18: ='Data Sheet'!G68 -> 0 | H18: ='Data Sheet'!H68 -> 0 | I18: ='Data Sheet'!I68 -> 0 | ... K18: ='Data Sheet'!K68 -> 0
A20: Debtor Days | B20: =IF('Profit & Loss'!B4>0,'Balance Sheet'!B17/('Profit & Loss'!B4/365),0) -> 65.672712 | C20: =IF('Profit & Loss'!C4>0,'Balance Sheet'!C17/('Profit & Loss'!C4/365),0) -> 68.018916 | D20: =IF('Profit & Loss'!D4>0,'Balance Sheet'!D17/('Profit & Loss'!D4/365),0) -> 65.459389 | E20: =IF('Profit & Loss'!E4>0,'Balance Sheet'!E17/('Profit & Loss'!E4/365),0) -> 74.321849 | F20: =IF('Profit & Loss'!F4>0,'Balance Sheet'!F17/('Profit & Loss'!F4/365),0) -> 70.092265 | G20: =IF('Profit & Loss'!G4>0,'Balance Sheet'!G17/('Profit & Loss'!G4/365),0) -> 68.108368 | H20: =IF('Profit & Loss'!H4>0,'Balance Sheet'!H17/('Profit & Loss'!H4/365),0) -> 63.227837 | I20: =IF('Profit & Loss'!I4>0,'Balance Sheet'!I17/('Profit & Loss'!I4/365),0) -> 71.715006 | ... K20: =IF('Profit & Loss'!K4>0,'Balance Sheet'!K17/('Profit & Loss'!K4/365),0) -> 71.986622
A21: Inventory Turnover | B21: =IF('Balance Sheet'!B18>0,'Profit & Loss'!B4/'Balance Sheet'!B18,0) -> 0 | C21: =IF('Balance Sheet'!C18>0,'Profit & Loss'!C4/'Balance Sheet'!C18,0) -> 0 | D21: =IF('Balance Sheet'!D18>0,'Profit & Loss'!D4/'Balance Sheet'!D18,0) -> 0 | E21: =IF('Balance Sheet'!E18>0,'Profit & Loss'!E4/'Balance Sheet'!E18,0) -> 0 | F21: =IF('Balance Sheet'!F18>0,'Profit & Loss'!F4/'Balance Sheet'!F18,0) -> 0 | G21: =IF('Balance Sheet'!G18>0,'Profit & Loss'!G4/'Balance Sheet'!G18,0) -> 0 | H21: =IF('Balance Sheet'!H18>0,'Profit & Loss'!H4/'Balance Sheet'!H18,0) -> 0 | I21: =IF('Balance Sheet'!I18>0,'Profit & Loss'!I4/'Balance Sheet'!I18,0) -> 0 | ... K21: =IF('Balance Sheet'!K18>0,'Profit & Loss'!K4/'Balance Sheet'!K18,0) -> 0
A23: Return on Equity | B23: =IF(SUM('Balance Sheet'!B4:B5)>0,'Profit & Loss'!B12/SUM('Balance Sheet'!B4:B5),"") -> 0.20806877 | C23: =IF(SUM('Balance Sheet'!C4:C5)>0,'Profit & Loss'!C12/SUM('Balance Sheet'!C4:C5),"") -> 0.24689247 | D23: =IF(SUM('Balance Sheet'!D4:D5)>0,'Profit & Loss'!D12/SUM('Balance Sheet'!D4:D5),"") -> 0.23717435 | E23: =IF(SUM('Balance Sheet'!E4:E5)>0,'Profit & Loss'!E12/SUM('Balance Sheet'!E4:E5),"") -> 0.25353705 | F23: =IF(SUM('Balance Sheet'!F4:F5)>0,'Profit & Loss'!F12/SUM('Balance Sheet'!F4:F5),"") -> 0.25344789 | G23: =IF(SUM('Balance Sheet'!G4:G5)>0,'Profit & Loss'!G12/SUM('Balance Sheet'!G4:G5),"") -> 0.29343066 | H23: =IF(SUM('Balance Sheet'!H4:H5)>0,'Profit & Loss'!H12/SUM('Balance Sheet'!H4:H5),"") -> 0.31953267 | I23: =IF(SUM('Balance Sheet'!I4:I5)>0,'Profit & Loss'!I12/SUM('Balance Sheet'!I4:I5),"") -> 0.29770984 | ... K23: =IF(SUM('Balance Sheet'!K4:K5)>0,'Profit & Loss'!K12/SUM('Balance Sheet'!K4:K5),"") -> 0.31706371
A24: Return on Capital Emp | C24: =IF((B4+B5+B6+C4+C5+C6)>0,('Profit & Loss'!C10+'Profit & Loss'!C9)*2/(B4+B5+B6+C4+C5+C6),"") -> 0.30275195 | D24: =IF((C4+C5+C6+D4+D5+D6)>0,('Profit & Loss'!D10+'Profit & Loss'!D9)*2/(C4+C5+C6+D4+D5+D6),"") -> 0.32402923 | E24: =IF((D4+D5+D6+E4+E5+E6)>0,('Profit & Loss'!E10+'Profit & Loss'!E9)*2/(D4+D5+D6+E4+E5+E6),"") -> 0.32847272 | F24: =IF((E4+E5+E6+F4+F5+F6)>0,('Profit & Loss'!F10+'Profit & Loss'!F9)*2/(E4+E5+E6+F4+F5+F6),"") -> 0.35349469 | G24: =IF((F4+F5+F6+G4+G5+G6)>0,('Profit & Loss'!G10+'Profit & Loss'!G9)*2/(F4+F5+F6+G4+G5+G6),"") -> 0.37304615 | H24: =IF((G4+G5+G6+H4+H5+H6)>0,('Profit & Loss'!H10+'Profit & Loss'!H9)*2/(G4+G5+G6+H4+H5+H6),"") -> 0.40850909 | I24: =IF((H4+H5+H6+I4+I5+I6)>0,('Profit & Loss'!I10+'Profit & Loss'!I9)*2/(H4+H5+H6+I4+I5+I6),"") -> 0.40468196 | J24: =IF((I4+I5+I6+J4+J5+J6)>0,('Profit & Loss'!J10+'Profit & Loss'!J9)*2/(I4+I5+I6+J4+J5+J6),"") -> 0.37925394 | K24: =IF((J4+J5+J6+K4+K5+K6)>0,('Profit & Loss'!K10+'Profit & Loss'!K9)*2/(J4+J5+J6+K4+K5+K6),"") -> 0.39220082
A26: Book Value | B26: =B4+B5 -> 68982 | C26: =C4+C5 -> 64923 | D26: =D4+D5 -> 64948 | E26: =E4+E5 -> 65450 | F26: =F4+F5 -> 76351 | G26: =G4+G5 -> 75350 | H26: =H4+H5 -> 75407 | I26: =I4+I5 -> 88116 | ... K26: =K4+K5 -> 92852

Sheet Cash Flow
A1: ='Balance Sheet'!A1 -> INFOSYS LTD | E1: =UPDATE | J1: SCREENER.IN
A3: Narration | B3: ='Data Sheet'!B81 -> 42825 | C3: ='Data Sheet'!C81 -> 43190 | D3: ='Data Sheet'!D81 -> 43555 | E3: ='Data Sheet'!E81 -> 43921 | F3: ='Data Sheet'!F81 -> 44286 | G3: ='Data Sheet'!G81 -> 44651 | H3: ='Data Sheet'!H81 -> 45016 | I3: ='Data Sheet'!I81 -> 45382 | ... K3: ='Data Sheet'!K81 -> 46112
A4: Cash from Operating Activity | B4: ='Data Sheet'!B82 -> 11531 | C4: ='Data Sheet'!C82 -> 13218 | D4: ='Data Sheet'!D82 -> 14841 | E4: ='Data Sheet'!E82 -> 17003 | F4: ='Data Sheet'!F82 -> 23224 | G4: ='Data Sheet'!G82 -> 23885 | H4: ='Data Sheet'!H82 -> 22467 | I4: ='Data Sheet'!I82 -> 25210 | ... K4: ='Data Sheet'!K82 -> 33986
A5: Cash from Investing Activity | B5: ='Data Sheet'!B83 -> -14664 | C5: ='Data Sheet'!C83 -> 4533 | D5: ='Data Sheet'!D83 -> -632 | E5: ='Data Sheet'!E83 -> -331 | F5: ='Data Sheet'!F83 -> -7373 | G5: ='Data Sheet'!G83 -> -6485 | H5: ='Data Sheet'!H83 -> -1071 | I5: ='Data Sheet'!I83 -> -5093 | ... K5: ='Data Sheet'!K83 -> 3546
A6: Cash from Financing Activity | B6: ='Data Sheet'!B84 -> -6939 | C6: ='Data Sheet'!C84 -> -20505 | D6: ='Data Sheet'!D84 -> -14512 | E6: ='Data Sheet'!E84 -> -17591 | F6: ='Data Sheet'!F84 -> -9786 | G6: ='Data Sheet'!G84 -> -24642 | H6: ='Data Sheet'!H84 -> -26695 | I6: ='Data Sheet'!I84 -> -17504 | ... K6: ='Data Sheet'!K84 -> -39786
A7: Net Cash Flow | B7: ='Data Sheet'!B85 -> -10072 | C7: ='Data Sheet'!C85 -> -2754 | D7: ='Data Sheet'!D85 -> -303 | E7: ='Data Sheet'!E85 -> -919 | F7: ='Data Sheet'!F85 -> 6065 | G7: ='Data Sheet'!G85 -> -7242 | H7: ='Data Sheet'!H85 -> -5299 | I7: ='Data Sheet'!I85 -> 2613 | ... K7: ='Data Sheet'!K85 -> -2254

Sheet Customization
A1: How to use it?
A3: You can customize this workbook as you want.
B4: You can add custom formating, add conditional formating, add your own formulas… do ANYTHING.
B5: Please don't edit the "Data Sheet" only.
A7: After customization, you can upload this back on Screener.
B8: Upload on: | C8: https://www.screener.in/excel/
A10: Download your customized workbooks now onwards.
B11: Now whenever you will "Export to excel" from Screener, it will export your customized file.
A14: TESTING:
B15: This is a testing feature currently.
B16: You can report any formula errors on the worksheet at: support@screener.in

Sheet Data Sheet
A1: COMPANY NAME | B1: INFOSYS LTD | E1: =IF(B2<>B3, "A NEW VERSION OF THE WORKSHEET IS AVAILABLE", "")
A2: LATEST VERSION | B2: 2.1 | E2: PLEASE DO NOT MAKE ANY CHANGES TO THIS SHEET
A3: CURRENT VERSION | B3: 2.1
A5: META
A6: Number of shares | B6: =IF(B9>0, B9/B8, 0) -> 405.82829
A7: Face Value | B7: 5
A8: Current Price | B8: 1159.75
A9: Market Capitalization | B9: 470659.36
A15: PROFIT & LOSS
A16: Report Date | B16: 42825 | C16: 43190 | D16: 43555 | E16: 43921 | F16: 44286 | G16: 44651 | H16: 45016 | I16: 45382 | J16: 45747 | K16: 46112
A17: Sales | B17: 68484 | C17: 70522 | D17: 82675 | E17: 90791 | F17: 100472 | G17: 121641 | H17: 146767 | I17: 153670 | J17: 162990 | K17: 178650
A18: Raw Material Cost
A19: Change in Inventory
A20: Power and Fuel | B20: 228 | C20: 207 | D20: 221 | E20: 229 | F20: 143 | G20: 132 | H20: 176 | I20: 199 | J20: 222 | K20: 223
A21: Other Mfr. Exp | B21: 6712 | C21: 7286 | D21: 9902 | E21: 11086 | F21: 12800 | G21: 20690 | H21: 26330 | I21: 27195 | J21: 30395 | K21: 32922
A22: Employee Cost | B22: 37669 | C22: 38902 | D22: 45323 | E22: 50895 | F22: 55547 | G22: 63997 | H22: 78374 | I22: 82636 | J22: 85968 | K22: 95112
A23: Selling and admin | B23: 4584 | C23: 4585 | D23: 5553 | E23: 5375 | F23: 3194 | G23: 4305 | H23: 5300 | I23: 5705 | J23: 6039 | K23: 6784
A24: Other Expenses | B24: 687 | C24: 720 | D24: 1506 | E24: 939 | F24: 899 | G24: 1026 | H24: 1457 | I24: 1510 | J24: 1130 | K24: 1329
A25: Other Income | B25: 3050 | C25: 3311 | D25: 2882 | E25: 2803 | F25: 2201 | G25: 2295 | H25: 2701 | I25: 4711 | J25: 3600 | K25: 3033
A26: Depreciation | B26: 1703 | C26: 1863 | D26: 2011 | E26: 2893 | F26: 3267 | G26: 3476 | H26: 4225 | I26: 4678 | J26: 4812 | K26: 4902
A27: Interest | E27: 170 | F27: 195 | G27: 200 | H27: 284 | I27: 470 | J27: 416 | K27: 416
A28: Profit before tax | B28: 19951 | C28: 20270 | D28: 21041 | E28: 22007 | F28: 26628 | G28: 30110 | H28: 33322 | I28: 35988 | J28: 37608 | K28: 39995
A29: Tax | B29: 5598 | C29: 4241 | D29: 5631 | E29: 5368 | F29: 7205 | G29: 7964 | H29: 9214 | I29: 9740 | J29: 10858 | K29: 10521
A30: Net profit | B30: 14353 | C30: 16029 | D30: 15404 | E30: 16594 | F30: 19351 | G30: 22110 | H30: 24095 | I30: 26233 | J30: 26713 | K30: 29440
A31: Dividend Amount | B31: 5891.6 | C31: 9465.6 | D31: 9222.5 | E31: 7427 | F31: 11469.6 | G31: 13007.6 | H31: 14069.2 | I31: 19053.2 | J31: 17827.8 | K31: 19430.4
A40: Quarters
A41: Report Date | B41: 45291 | C41: 45382 | D41: 45473 | E41: 45565 | F41: 45657 | G41: 45747 | H41: 45838 | I41: 45930 | J41: 46022 | K41: 46112
A42: Sales | B42: 38821 | C42: 37923 | D42: 39315 | E42: 40986 | F42: 41764 | G42: 40925 | H42: 42279 | I42: 44490 | J42: 45479 | K42: 46402
A43: Expenses | B43: 29684 | C43: 29139 | D43: 29878 | E43: 31177 | F43: 31649 | G43: 31051 | H43: 32336 | I43: 33955 | J43: 34845 | K43: 35235
A44: Other Income | B44: 789 | C44: 2729 | D44: 838 | E44: 712 | F44: 859 | G44: 1190 | H44: 1042 | I44: 982 | J44: -150 | K44: 1159
A45: Depreciation | B45: 1176 | C45: 1163 | D45: 1149 | E45: 1160 | F45: 1203 | G45: 1299 | H45: 1140 | I45: 1182 | J45: 1155 | K45: 1424
A46: Interest | B46: 131 | C46: 110 | D46: 105 | E46: 108 | F46: 101 | G46: 102 | H46: 105 | I46: 106 | J46: 100 | K46: 105
A47: Profit before tax | B47: 8619 | C47: 10240 | D47: 9021 | E47: 9253 | F47: 9670 | G47: 9663 | H47: 9740 | I47: 10229 | J47: 9229 | K47: 10797
A48: Tax | B48: 2506 | C48: 2265 | D48: 2647 | E48: 2737 | F48: 2848 | G48: 2625 | H48: 2816 | I48: 2854 | J48: 2563 | K48: 2288
A49: Net profit | B49: 6106 | C49: 7969 | D49: 6368 | E49: 6506 | F49: 6806 | G49: 7033 | H49: 6921 | I49: 7364 | J49: 6654 | K49: 8501
A50: Operating Profit | B50: 9137 | C50: 8784 | D50: 9437 | E50: 9809 | F50: 10115 | G50: 9874 | H50: 9943 | I50: 10535 | J50: 10634 | K50: 11167
A55: BALANCE SHEET
A56: Report Date | B56: 42825 | C56: 43190 | D56: 43555 | E56: 43921 | F56: 44286 | G56: 44651 | H56: 45016 | I56: 45382 | J56: 45747 | K56: 46112
A57: Equity Share Capital | B57: 1144 | C57: 1088 | D57: 2170 | E57: 2122 | F57: 2124 | G57: 2098 | H57: 2069 | I57: 2071 | J57: 2073 | K57: 2024
A58: Reserves | B58: 67838 | C58: 63835 | D58: 62778 | E58: 63328 | F58: 74227 | G58: 73252 | H58: 73338 | I58: 86045 | J58: 93745 | K58: 90828
...
