Workbook

Sheet DCF>

Sheet WACC
B2: Weighted Average Cost of Capital
B4: All figure are in INR unless stated otherwise
B6: Peer Comps
H7: Debt/ | I7: Debt/ | J7: Levered | K7: Unlevered
B8: Name of the Comp | D8: Country | E8: Total Debt | F8: Total Equity | G8: Tax Rate 1 | H8: Equity | I8: Capital | J8: Beta 2 | K8: Beta 3
B10: Hind Unilever | D10: India | E10: 1139 | F10: 611503.89 | G10: 0.3 | H10: =E10/F10 -> 0.001862621 | I10: =E10/(E10+F10) -> 0.0018591581 | J10: 1 | K10: =J10/(1+(1-G10)*H10) -> 0.99869786
B11: Nestle India | D11: India | E11: 279.9 | F11: 182975.03 | G11: 0.3 | H11: =E11/F11 -> 0.0015297169 | I11: =E11/(E11+F11) -> 0.0015273805 | J11: 1 | K11: =J11/(1+(1-G11)*H11) -> 0.99893034
B12: Britannia Inds | D12: India | E12: 3037.7 | F12: 110689.96 | G12: 0.3 | H12: =E12/F12 -> 0.02744332 | I12: =E12/(E12+F12) -> 0.026710301 | J12: 1 | K12: =J12/(1+(1-G12)*H12) -> 0.98115176
B13: Godrej Consumer | D13: India | E13: 1164.5 | F13: 96256.38 | G13: 0.3 | H13: =E13/F13 -> 0.012097899 | I13: =E13/(E13+F13) -> 0.01195329 | J13: 1 | K13: =J13/(1+(1-G13)*H13) -> 0.99160258
B14: Dabur India | D14: India | E14: 1068.1 | F14: 94940.38 | G14: 0.3 | H14: =E14/F14 -> 0.011250218 | I14: =E14/(E14+F14) -> 0.011125059 | J14: 1 | K14: =J14/(1+(1-G14)*H14) -> 0.99218638
F16: Average | G16: =AVERAGE(G10:G14) -> 0.3 | H16: =AVERAGE(H10:H14) -> 0.010836755 | I16: =AVERAGE(I10:I14) -> 0.010635038 | J16: =AVERAGE(J10:J14) -> 1 | K16: =AVERAGE(K10:K14) -> 0.99251379
F17: Median | G17: =MEDIAN(G10:G14) -> 0.3 | H17: =MEDIAN(H10:H14) -> 0.011250218 | I17: =MEDIAN(I10:I14) -> 0.011125059 | J17: =MEDIAN(J10:J14) -> 1 | K17: =MEDIAN(K10:K14) -> 0.99218638
B19: Cost of Debt | G19: Cost of Equity
B21: Pre -Tax Cost of Debt | E21: 0.084 | G21: Risk Free Rate | K21: 0.065
B22: Tax Rate | E22: 0.3 | G22: Equity Risk Premium | K22: 0.08
B23: Post Tax Cost of Debt | E23: =E21*(1-E22) -> 0.0588 | G23: Levered Beta 4 | K23: =K32 -> 1.505535
G24: Cost of Equity | K24: =K21+K22*K23 -> 0.1854428
B27: Capital Structure | G27: Levered Beta
D29: Current | E29: Target | G29: Comps Median Unlevered Beta | K29: =K17 -> 0.99218638
B30: Total Debt | C30: 17440 | D30: =C30/$C$32 -> 0.35087013 | E30: 0.425 | G30: Target Debt/Equity | K30: =E34 -> 0.73913043
B31: Market Capitalization (Total Equity) | C31: 32265 | D31: =C31/$C$32 -> 0.64912987 | E31: =E32-E30 -> 0.575 | G31: Tax Rate | K31: =E22 -> 0.3
B32: Total Capital | C32: =SUM(C30:C31) -> 49705 | D32: =C32/$C$32 -> 1 | E32: =D32 -> 1 | G32: Levered Beta | K32: =K29*(1+(1-K31)*K30) -> 1.505535
B34: Debt/Equity | D34: =D30/D31 -> 0.54052379 | E34: =E30/E31 -> 0.73913043
G35: Weighted Average Cost of Capital
B36: Note
B37: 1. Tax Rate considered as marginal Tax Rate for the country | I37: Total Cost | J37: Total Weight
B38: 2. Levered beta is based on 5 year monthly data | G38: Debt | I38: =E23 -> 0.0588 | J38: =E30 -> 0.425
B39: 3. Unlevered Beta = Levered beta/(1+(1- Tax Rate)*Debt/Equity | G39: Equity | I39: =K24 -> 0.1854428 | J39: =E31 -> 0.575
B40: 3. Levered Beta = Unlevered beta*(1+(1- Tax Rate)*Debt/Equity | G40: Weighted Average Cost of Capital | J40: =SUMPRODUCT(I38:I39,J38:J39) -> 0.13161961

Sheet WACC (2)
B2: Weighted Average Cost of Capital
B4: All figure are in INR unless stated otherwise
B6: Peer Comps
H7: Debt/ | I7: Debt/ | J7: Levered | K7: Unlevered
B8: Name of the Comp | D8: Country | E8: Total Debt | F8: Total Equity | G8: Tax Rate 1 | H8: Equity | I8: Capital | J8: Beta 2 | K8: Beta 3
B10: Avenue Supermart | D10: India | E10: ='Beta Comps'!F4 -> 1609.19 | F10: ='Beta Comps'!E4 -> 263787.66 | G10: 0.3 | H10: =E10/F10 -> 0.0061003233 | I10: =E10/(E10+F10) -> 0.006063335 | J10: =Beta!P6 -> 0.67806987 | K10: =J10/(1+(1-G10)*H10) -> 0.67518667
B11: Trent | D11: India | E11: ='Beta Comps'!F5 -> 2348.57 | F11: ='Beta Comps'!E5 -> 156101.65 | G11: 0.3 | H11: =E11/F11 -> 0.015045132 | I11: =E11/(E11+F11) -> 0.014822132 | J11: ='Beta 2'!P6 -> 1.4029028 | K11: =J11/(1+(1-G11)*H11) -> 1.388282
B12: Swiggy Ltd | D12: India | E12: ='Beta Comps'!F6 -> 2491 | F12: ='Beta Comps'!E6 -> 98025.26 | G12: 0.3 | H12: =E12/F12 -> 0.025411817 | I12: =E12/(E12+F12) -> 0.02478206 | J12: ='Beta 3'!P6 -> 1.2287861 | K12: =J12/(1+(1-G12)*H12) -> 1.2073101
B13: Info Edg. | D13: India | E13: ='Beta Comps'!F7 -> 275.62 | F13: ='Beta Comps'!E7 -> 85818.47 | G13: 0.3 | H13: =E13/F13 -> 0.0032116629 | I13: =E13/(E13+F13) -> 0.0032013812 | J13: ='Beta 4'!P6 -> 1.5841972 | K13: =J13/(1+(1-G13)*H13) -> 1.5806437
B14: FSN E-Commerce | D14: India | E14: ='Beta Comps'!F8 -> 1407.02 | F14: ='Beta Comps'!E8 -> 74438.8 | G14: 0.3 | H14: =E14/F14 -> 0.018901702 | I14: =E14/(E14+F14) -> 0.018551055 | J14: ='Beta 5'!P6 -> 0.73329945 | K14: =J14/(1+(1-G14)*H14) -> 0.72372372
F16: Average | G16: =AVERAGE(G10:G14) -> 0.3 | H16: =AVERAGE(H10:H14) -> 0.013734128 | I16: =AVERAGE(I10:I14) -> 0.013483993 | J16: =AVERAGE(J10:J14) -> 1.1254511 | K16: =AVERAGE(K10:K14) -> 1.1150292
F17: Median | G17: =MEDIAN(G10:G14) -> 0.3 | H17: =MEDIAN(H10:H14) -> 0.015045132 | I17: =MEDIAN(I10:I14) -> 0.014822132 | J17: =MEDIAN(J10:J14) -> 1.2287861 | K17: =MEDIAN(K10:K14) -> 1.2073101
B19: Cost of Debt | G19: Cost of Equity
B21: Pre -Tax Cost of Debt | E21: =101/E10 -> 0.062764496 | G21: Risk Free Rate | K21: 0.06527
B22: Tax Rate | E22: =G17 -> 0.3 | G22: Equity Risk Premium | K22: =RM!F8-'WACC (2)'!K21 -> 0.088078
B23: Post Tax Cost of Debt | E23: =E21*(1-E22) -> 0.043935147 | G23: Levered Beta 4 | K23: =K32 -> 1.2188614
G24: Cost of Equity | K24: =K21+(K22-K21)*K23 -> 0.093069791
B27: Capital Structure | G27: Levered Beta
D29: Current | E29: Target | G29: Comps Median Unlevered Beta | K29: =K17 -> 1.2073101
B30: Total Debt | C30: =E10 -> 1609.19 | D30: =C30/$C$32 -> 0.006063335 | E30: =I16 -> 0.013483993 | G30: Target Debt/Equity | K30: =E34 -> 0.013668296
B31: Market Capitalization (Total Equity) | C31: =F10 -> 263787.66 | D31: =C31/$C$32 -> 0.99393667 | E31: =E32-E30 -> 0.98651601 | G31: Tax Rate | K31: =E22 -> 0.3
B32: Total Capital | C32: =SUM(C30:C31) -> 265396.85 | D32: =C32/$C$32 -> 1 | E32: =D32 -> 1 | G32: Levered Beta | K32: =K29*(1+(1-K31)*K30) -> 1.2188614
B34: Debt/Equity | D34: =D30/D31 -> 0.0061003233 | E34: =E30/E31 -> 0.013668296
G35: Weighted Average Cost of Capital
B36: Note
B37: 1. Tax Rate considered as marginal Tax Rate for the country | G37: Cost of Equity | K37: =K24 -> 0.093069791
B38: 2. Levered beta is based on 5 year monthly data | G38: Equity Weight | K38: =E31 -> 0.98651601
B39: 3. Unlevered Beta = Levered beta/(1+(1- Tax Rate)*Debt/Equity
B40: 3. Levered Beta = Unlevered beta*(1+(1- Tax Rate)*Debt/Equity | G40: Cost of Debt | K40: =E23 -> 0.043935147
G41: Debt Weight | K41: =E30 -> 0.013483993
G43: WACC | K43: =(K37*K38)+(K40*K41) -> 0.09240726

Sheet Beta Comps
B2: Comparable Beta
B3: SL.No | C3: Name | D3: CMP Rs. | E3: Mar Cap Rs.Cr. | F3: Debt Rs.Cr. | G3: Debt / Eq
B4: 1 | C4: Avenue Super. | D4: 4053.7 | E4: 263787.66 | F4: 1609.19 | G4: 0.07
B5: 2 | C5: Trent | D5: 4391.2 | E5: 156101.65 | F5: 2348.57 | G5: 0.38
B6: 3 | C6: Swiggy Ltd | D6: 393.1 | E6: 98025.26 | F6: 2491 | G6: 0.25
B7: 4 | C7: Info Edg.(India) | D7: 1323.5 | E7: 85818.47 | F7: 275.62 | G7: 0.01
B8: 5 | C8: FSN E-Commerce | D8: 260.13 | E8: 74438.8 | F8: 1407.02 | G8: 1.01

Sheet Data>

Sheet Beta
B2: Regression Beta -1 Years
B4: Avenue Supermart Weekly Returns | G4: Nifty Returns | L4: Beta Drifting
B6: Date | C6: Closing Price | D6: Return | G6: Date | H6: Closing Price | I6: Return | L6: Levered Raw Beta | M6: =P6 -> 0.67806987 | O6: Beta | P6: =O33 -> 0.67806987
B7: 45614 | C7: 3790.55 | G7: 45614 | H7: 23453.801 | L7: Raw Beta Weight | M7: 0.75
B8: 45615 | C8: 3752.45 | D8: =C8/C7-1 -> -0.010051337 | G8: 45615 | H8: 23518.5 | I8: =H8/H7-1 -> 0.0027585814
B9: 45617 | C9: 3622.8999 | D9: =C9/C8-1 -> -0.034524124 | G9: 45617 | H9: 23349.9 | I9: =H9/H8-1 -> -0.0071688079 | L9: Market Beta | M9: 1
B10: 45618 | C10: 3613.6499 | D10: =C10/C9-1 -> -0.0025532033 | G10: 45618 | H10: 23907.25 | I10: =H10/H9-1 -> 0.023869464 | L10: Market Beta Weight | M10: 0.25
B11: 45621 | C11: 3621.05 | D11: =C11/C10-1 -> 0.0020478316 | G11: 45621 | H11: 24221.9 | I11: =H11/H10-1 -> 0.013161296
B12: 45622 | C12: 3659.1499 | D12: =C12/C11-1 -> 0.010521769 | G12: 45622 | H12: 24194.5 | I12: =H12/H11-1 -> -0.0011312238 | L12: Adjusted Beta | M12: =(M6*M7)+(M9*M10) -> 0.7585524
B13: 45623 | C13: 3661.25 | D13: =C13/C12-1 -> 0.00057393048 | G13: 45623 | H13: 24274.9 | I13: =H13/H12-1 -> 0.0033230854 | N13: SUMMARY OUTPUT
B14: 45624 | C14: 3716.55 | D14: =C14/C13-1 -> 0.015104144 | G14: 45624 | H14: 23914.15 | I14: =H14/H13-1 -> -0.014861029
B15: 45625 | C15: 3709.6001 | D15: =C15/C14-1 -> -0.0018700007 | G15: 45625 | H15: 24131.1 | I15: =H15/H14-1 -> 0.0090720019 | N15: Regression Statistics
B16: 45628 | C16: 3678.3999 | D16: =C16/C15-1 -> -0.0084106627 | G16: 45628 | H16: 24276.051 | I16: =H16/H15-1 -> 0.00600682 | N16: SUMMARY OUTPUT
B17: 45629 | C17: 3829.8501 | D17: =C17/C16-1 -> 0.041172847 | G17: 45629 | H17: 24457.15 | I17: =H17/H16-1 -> 0.0074600111
B18: 45630 | C18: 3850.1001 | D18: =C18/C17-1 -> 0.0052874132 | G18: 45630 | H18: 24467.449 | I18: =H18/H17-1 -> 0.00042109681 | N18: Regression Statistics
B19: 45631 | C19: 3863.95 | D19: =C19/C18-1 -> 0.003597271 | G19: 45631 | H19: 24708.4 | I19: =H19/H18-1 -> 0.0098478256 | N19: Multiple R | O19: 0.29549164
B20: 45632 | C20: 3805.55 | D20: =C20/C19-1 -> -0.015114042 | G20: 45632 | H20: 24677.801 | I20: =H20/H19-1 -> -0.0012384294 | N20: R Square | O20: 0.087315307
B21: 45635 | C21: 3829.05 | D21: =C21/C20-1 -> 0.0061751914 | G21: 45635 | H21: 24619 | I21: =H21/H20-1 -> -0.0023827399 | N21: Adjusted R Square | O21: 0.083574796
B22: 45636 | C22: 3816.8999 | D22: =C22/C21-1 -> -0.003173149 | G22: 45636 | H22: 24610.051 | I22: =H22/H21-1 -> -0.00036350862 | N22: Standard Error | O22: 0.017217976
B23: 45637 | C23: 3708.3 | D23: =C23/C22-1 -> -0.028452371 | G23: 45637 | H23: 24641.801 | I23: =H23/H22-1 -> 0.0012901233 | N23: Observations | O23: 246
B24: 45638 | C24: 3688.45 | D24: =C24/C23-1 -> -0.0053528834 | G24: 45638 | H24: 24548.699 | I24: =H24/H23-1 -> -0.0037781964
B25: 45639 | C25: 3652.3 | D25: =C25/C24-1 -> -0.0098008385 | G25: 45639 | H25: 24768.301 | I25: =H25/H24-1 -> 0.0089455478 | N25: ANOVA
B26: 45642 | C26: 3623.8 | D26: =C26/C25-1 -> -0.0078033019 | G26: 45642 | H26: 24668.25 | I26: =H26/H25-1 -> -0.0040394689 | O26: df | P26: SS | Q26: MS | R26: F | S26: Significance F
B27: 45643 | C27: 3542.95 | D27: =C27/C26-1 -> -0.022310861 | G27: 45643 | H27: 24336 | I27: =H27/H26-1 -> -0.01346873 | N27: Regression | O27: 1 | P27: 0.0069202797 | Q27: 0.0069202797 | R27: 23.343149 | S27: 2.396424e-06
B28: 45644 | C28: 3515.7 | D28: =C28/C27-1 -> -0.0076913308 | G28: 45644 | H28: 24198.85 | I28: =H28/H27-1 -> -0.0056356998 | N28: Residual | O28: 244 | P28: 0.072335923 | Q28: 0.0002964587
B29: 45645 | C29: 3498.1499 | D29: =C29/C28-1 -> -0.0049919075 | G29: 45645 | H29: 23951.699 | I29: =H29/H28-1 -> -0.010213312 | N29: Total | O29: 245 | P29: 0.079256202
B30: 45646 | C30: 3408.3 | D30: =C30/C29-1 -> -0.025684964 | G30: 45646 | H30: 23587.5 | I30: =H30/H29-1 -> -0.015205569
B31: 45649 | C31: 3460.55 | D31: =C31/C30-1 -> 0.015330223 | G31: 45649 | H31: 23753.449 | I31: =H31/H30-1 -> 0.007035473 | O31: Coefficients | P31: Standard Error | Q31: t Stat | R31: P-value | S31: Lower 95% | T31: Upper 95% | U31: Lower 95.0% | V31: Upper 95.0%
B32: 45650 | C32: 3459.6499 | D32: =C32/C31-1 -> -0.00026011659 | G32: 45650 | H32: 23727.65 | I32: =H32/H31-1 -> -0.0010861087 | N32: Intercept | O32: 0.00014420176 | P32: 0.0010994781 | Q32: 0.13115474 | R32: 0.89576097 | S32: -0.0020214776 | T32: 0.0023098811 | U32: -0.0020214776 | V32: 0.0023098811
B33: 45652 | C33: 3511.6499 | D33: =C33/C32-1 -> 0.015030423 | G33: 45652 | H33: 23750.199 | I33: =H33/H32-1 -> 0.00095031863 | N33: X Variable 1 | O33: 0.67806987 | P33: 0.14034428 | Q33: 4.8314749 | R33: 2.396424e-06 | S33: 0.40162897 | T33: 0.95451077 | U33: 0.40162897 | V33: 0.95451077
B34: 45653 | C34: 3568.3501 | D34: =C34/C33-1 -> 0.016146312 | G34: 45653 | H34: 23813.4 | I34: =H34/H33-1 -> 0.0026610797
B35: 45656 | C35: 3588.55 | D35: =C35/C34-1 -> 0.0056608658 | G35: 45656 | H35: 23644.9 | I35: =H35/H34-1 -> -0.0070758479
B36: 45657 | C36: 3561.8501 | D36: =C36/C35-1 -> -0.0074403173 | G36: 45657 | H36: 23644.801 | I36: =H36/H35-1 -> -4.2127213e-06
B37: 45658 | C37: 3561 | D37: =C37/C36-1 -> -0.00023866744 | G37: 45658 | H37: 23742.9 | I37: =H37/H36-1 -> 0.0041488871
B38: 45659 | C38: 3611.1001 | D38: =C38/C37-1 -> 0.014069109 | G38: 45659 | H38: 24188.65 | I38: =H38/H37-1 -> 0.018774033
B39: 45660 | C39: 4025.2 | D39: =C39/C38-1 -> 0.11467416 | G39: 45660 | H39: 24004.75 | I39: =H39/H38-1 -> -0.0076027553
B40: 45663 | C40: 3934.75 | D40: =C40/C39-1 -> -0.022470921 | G40: 45663 | H40: 23616.051 | I40: =H40/H39-1 -> -0.016192596
B41: 45664 | C41: 3830.3 | D41: =C41/C40-1 -> -0.026545511 | G41: 45664 | H41: 23707.9 | I41: =H41/H40-1 -> 0.0038892874
B42: 45665 | C42: 3843 | D42: =C42/C41-1 -> 0.0033156544 | G42: 45665 | H42: 23688.949 | I42: =H42/H41-1 -> -0.00079936104
B43: 45666 | C43: 3813.8 | D43: =C43/C42-1 -> -0.0075982178 | G43: 45666 | H43: 23526.5 | I43: =H43/H42-1 -> -0.006857595
...

Sheet Beta 2
B2: Regression Beta -1 Years
B4: Trent Limited Returns | G4: Nifty Returns | L4: Beta Drifting
B6: Date | C6: Closing Price | D6: Return | G6: Date | H6: Closing Price | I6: Return | L6: Levered Raw Beta | M6: =P6 -> 1.4029028 | O6: Beta | P6: =N33 -> 1.4029028
B7: 45614 | C7: 6296.1953 | G7: 45614 | H7: 23453.801 | L7: Raw Beta Weight | M7: 0.75
B8: 45615 | C8: 6418.2896 | D8: =C8/C7-1 -> 0.019391749 | G8: 45615 | H8: 23518.5 | I8: =H8/H7-1 -> 0.0027585814
B9: 45617 | C9: 6454.8584 | D9: =C9/C8-1 -> 0.0056976002 | G9: 45617 | H9: 23349.9 | I9: =H9/H8-1 -> -0.0071688079 | L9: Market Beta | M9: 1
B10: 45618 | C10: 6647.0415 | D10: =C10/C9-1 -> 0.029773404 | G10: 45618 | H10: 23907.25 | I10: =H10/H9-1 -> 0.023869464 | L10: Market Beta Weight | M10: 0.25
B11: 45621 | C11: 6769.0859 | D11: =C11/C10-1 -> 0.018360715 | G11: 45621 | H11: 24221.9 | I11: =H11/H10-1 -> 0.013161296
B12: 45622 | C12: 6663.5771 | D12: =C12/C11-1 -> -0.015586859 | G12: 45622 | H12: 24194.5 | I12: =H12/H11-1 -> -0.0011312238 | L12: Adjusted Beta | M12: =(M6*M7)+(M9*M10) -> 1.3021771
B13: 45623 | C13: 6839.1753 | D13: =C13/C12-1 -> 0.026351934 | G13: 45623 | H13: 24274.9 | I13: =H13/H12-1 -> 0.0033230854
B14: 45624 | C14: 6737.3633 | D14: =C14/C13-1 -> -0.014886592 | G14: 45624 | H14: 23914.15 | I14: =H14/H13-1 -> -0.014861029
B15: 45625 | C15: 6789.5181 | D15: =C15/C14-1 -> 0.0077411271 | G15: 45625 | H15: 24131.1 | I15: =H15/H14-1 -> 0.0090720019
B16: 45628 | C16: 6799.4092 | D16: =C16/C15-1 -> 0.0014568211 | G16: 45628 | H16: 24276.051 | I16: =H16/H15-1 -> 0.00600682 | M16: SUMMARY OUTPUT
B17: 45629 | C17: 6835.4282 | D17: =C17/C16-1 -> 0.0052973783 | G17: 45629 | H17: 24457.15 | I17: =H17/H16-1 -> 0.0074600111
B18: 45630 | C18: 6817.8931 | D18: =C18/C17-1 -> -0.002565334 | G18: 45630 | H18: 24467.449 | I18: =H18/H17-1 -> 0.00042109681 | M18: Regression Statistics
B19: 45631 | C19: 6964.0669 | D19: =C19/C18-1 -> 0.021439736 | G19: 45631 | H19: 24708.4 | I19: =H19/H18-1 -> 0.0098478256 | M19: Multiple R | N19: 0.44770061
B20: 45632 | C20: 6993.8911 | D20: =C20/C19-1 -> 0.0042825865 | G20: 45632 | H20: 24677.801 | I20: =H20/H19-1 -> -0.0012384294 | M20: R Square | N20: 0.20043584
B21: 45635 | C21: 6943.6846 | D21: =C21/C20-1 -> -0.0071786281 | G21: 45635 | H21: 24619 | I21: =H21/H20-1 -> -0.0023827399 | M21: Adjusted R Square | N21: 0.19715893
B22: 45636 | C22: 6872.0962 | D22: =C22/C21-1 -> -0.010309855 | G22: 45636 | H22: 24610.051 | I22: =H22/H21-1 -> -0.00036350862 | M22: Standard Error | N22: 0.022006908
B23: 45637 | C23: 7057.186 | D23: =C23/C22-1 -> 0.026933535 | G23: 45637 | H23: 24641.801 | I23: =H23/H22-1 -> 0.0012901233 | M23: Observations | N23: 246
B24: 45638 | C24: 7006.4302 | D24: =C24/C23-1 -> -0.0071920818 | G24: 45638 | H24: 24548.699 | I24: =H24/H23-1 -> -0.0037781964
B25: 45639 | C25: 6994.1909 | D25: =C25/C24-1 -> -0.0017468607 | G25: 45639 | H25: 24768.301 | I25: =H25/H24-1 -> 0.0089455478 | M25: ANOVA
B26: 45642 | C26: 6994.2905 | D26: =C26/C25-1 -> 1.4241729e-05 | G26: 45642 | H26: 24668.25 | I26: =H26/H25-1 -> -0.0040394689 | N26: df | O26: SS | P26: MS | Q26: F | R26: Significance F
B27: 45643 | C27: 6935.6416 | D27: =C27/C26-1 -> -0.0083852573 | G27: 45643 | H27: 24336 | I27: =H27/H26-1 -> -0.01346873 | M27: Regression | N27: 1 | O27: 0.029623061 | P27: 0.029623061 | Q27: 61.166253 | R27: 1.5781124e-13
B28: 45644 | C28: 7107.5923 | D28: =C28/C27-1 -> 0.024792325 | G28: 45644 | H28: 24198.85 | I28: =H28/H27-1 -> -0.0056356998 | M28: Residual | N28: 244 | O28: 0.11817018 | P28: 0.000484304
B29: 45645 | C29: 7085.8613 | D29: =C29/C28-1 -> -0.0030574288 | G29: 45645 | H29: 23951.699 | I29: =H29/H28-1 -> -0.010213312 | M29: Total | N29: 245 | O29: 0.14779324
B30: 45646 | C30: 6825.6367 | D30: =C30/C29-1 -> -0.036724485 | G30: 45646 | H30: 23587.5 | I30: =H30/H29-1 -> -0.015205569
B31: 45649 | C31: 6939.9878 | D31: =C31/C30-1 -> 0.016753173 | G31: 45649 | H31: 23753.449 | I31: =H31/H30-1 -> 0.007035473 | N31: Coefficients | O31: Standard Error | P31: t Stat | Q31: P-value | R31: Lower 95% | S31: Upper 95% | T31: Lower 95.0% | U31: Upper 95.0%
B32: 45650 | C32: 7001.0845 | D32: =C32/C31-1 -> 0.0088035716 | G32: 45650 | H32: 23727.65 | I32: =H32/H31-1 -> -0.0010861087 | M32: Intercept | N32: -0.0018267105 | O32: 0.0014052821 | P32: -1.2998888 | Q32: 0.19486571 | R32: -0.0045947424 | S32: 0.0009413214 | T32: -0.0045947424 | U32: 0.0009413214
B33: 45652 | C33: 7057.5859 | D33: =C33/C32-1 -> 0.0080703875 | G33: 45652 | H33: 23750.199 | I33: =H33/H32-1 -> 0.00095031863 | M33: X Variable 1 | N33: 1.4029028 | O33: 0.17937902 | P33: 7.8208857 | Q33: 1.5781124e-13 | R33: 1.0495739 | S33: 1.7562318 | T33: 1.0495739 | U33: 1.7562318
B34: 45653 | C34: 7112.1382 | D34: =C34/C33-1 -> 0.0077295901 | G34: 45653 | H34: 23813.4 | I34: =H34/H33-1 -> 0.0026610797
B35: 45656 | C35: 6948.3306 | D35: =C35/C34-1 -> -0.02303212 | G35: 45656 | H35: 23644.9 | I35: =H35/H34-1 -> -0.0070758479
B36: 45657 | C36: 7117.1841 | D36: =C36/C35-1 -> 0.024301307 | G36: 45657 | H36: 23644.801 | I36: =H36/H35-1 -> -4.2127213e-06
B37: 45658 | C37: 7061.9316 | D37: =C37/C36-1 -> -0.0077632447 | G37: 45658 | H37: 23742.9 | I37: =H37/H36-1 -> 0.0041488871
B38: 45659 | C38: 7314.6631 | D38: =C38/C37-1 -> 0.035787863 | G38: 45659 | H38: 24188.65 | I38: =H38/H37-1 -> 0.018774033
B39: 45660 | C39: 7301.375 | D39: =C39/C38-1 -> -0.0018166368 | G39: 45660 | H39: 24004.75 | I39: =H39/H38-1 -> -0.0076027553
B40: 45663 | C40: 6992.2925 | D40: =C40/C39-1 -> -0.042332098 | G40: 45663 | H40: 23616.051 | I40: =H40/H39-1 -> -0.016192596
B41: 45664 | C41: 6868.3496 | D41: =C41/C40-1 -> -0.017725642 | G41: 45664 | H41: 23707.9 | I41: =H41/H40-1 -> 0.0038892874
B42: 45665 | C42: 6693.3013 | D42: =C42/C41-1 -> -0.02548623 | G42: 45665 | H42: 23688.949 | I42: =H42/H41-1 -> -0.00079936104
B43: 45666 | C43: 6615.9688 | D43: =C43/C42-1 -> -0.011553719 | G43: 45666 | H43: 23526.5 | I43: =H43/H42-1 -> -0.006857595
...

Sheet Beta 3
B2: Regression Beta -1 Years
B4: Swiggy Ltd Returns | G4: Nifty Returns | L4: Beta Drifting
B6: Date | C6: Closing Price | D6: Return | G6: Date | H6: Closing Price | I6: Return | L6: Levered Raw Beta | M6: =P6 -> 1.2287861 | O6: Beta | P6: =N33 -> 1.2287861
B7: 45614 | C7: 420 | G7: 45614 | H7: 23453.801 | L7: Raw Beta Weight | M7: 0.75
B8: 45615 | C8: 413.10001 | D8: =C8/C7-1 -> -0.016428557 | G8: 45615 | H8: 23518.5 | I8: =H8/H7-1 -> 0.0027585814
B9: 45617 | C9: 417.10001 | D9: =C9/C8-1 -> 0.0096828854 | G9: 45617 | H9: 23349.9 | I9: =H9/H8-1 -> -0.0071688079 | L9: Market Beta | M9: 1
B10: 45618 | C10: 416.25 | D10: =C10/C9-1 -> -0.0020378952 | G10: 45618 | H10: 23907.25 | I10: =H10/H9-1 -> 0.023869464 | L10: Market Beta Weight | M10: 0.25
B11: 45621 | C11: 431.25 | D11: =C11/C10-1 -> 0.036036036 | G11: 45621 | H11: 24221.9 | I11: =H11/H10-1 -> 0.013161296
B12: 45622 | C12: 461.70001 | D12: =C12/C11-1 -> 0.070608724 | G12: 45622 | H12: 24194.5 | I12: =H12/H11-1 -> -0.0011312238 | L12: Adjusted Beta | M12: =(M6*M7)+(M9*M10) -> 1.1715895
B13: 45623 | C13: 498.79999 | D13: =C13/C12-1 -> 0.080355154 | G13: 45623 | H13: 24274.9 | I13: =H13/H12-1 -> 0.0033230854
B14: 45624 | C14: 491.70001 | D14: =C14/C13-1 -> -0.014234113 | G14: 45624 | H14: 23914.15 | I14: =H14/H13-1 -> -0.014861029
B15: 45625 | C15: 471.29999 | D15: =C15/C14-1 -> -0.041488761 | G15: 45625 | H15: 24131.1 | I15: =H15/H14-1 -> 0.0090720019 | M15: SUMMARY OUTPUT
B16: 45628 | C16: 495.35001 | D16: =C16/C15-1 -> 0.051029109 | G16: 45628 | H16: 24276.051 | I16: =H16/H15-1 -> 0.00600682 | M16: SUMMARY OUTPUT
B17: 45629 | C17: 501.29999 | D17: =C17/C16-1 -> 0.012011672 | G17: 45629 | H17: 24457.15 | I17: =H17/H16-1 -> 0.0074600111
B18: 45630 | C18: 518.09998 | D18: =C18/C17-1 -> 0.033512843 | G18: 45630 | H18: 24467.449 | I18: =H18/H17-1 -> 0.00042109681 | M18: Regression Statistics
B19: 45631 | C19: 539.59998 | D19: =C19/C18-1 -> 0.041497782 | G19: 45631 | H19: 24708.4 | I19: =H19/H18-1 -> 0.0098478256 | M19: Multiple R | N19: 0.31421261
B20: 45632 | C20: 544.65002 | D20: =C20/C19-1 -> 0.0093588752 | G20: 45632 | H20: 24677.801 | I20: =H20/H19-1 -> -0.0012384294 | M20: R Square | N20: 0.098729563
B21: 45635 | C21: 537.5 | D21: =C21/C20-1 -> -0.013127741 | G21: 45635 | H21: 24619 | I21: =H21/H20-1 -> -0.0023827399 | M21: Adjusted R Square | N21: 0.095020631
B22: 45636 | C22: 543.54999 | D22: =C22/C21-1 -> 0.011255791 | G22: 45636 | H22: 24610.051 | I22: =H22/H21-1 -> -0.00036350862 | M22: Standard Error | N22: 0.02921838
B23: 45637 | C23: 522.70001 | D23: =C23/C22-1 -> -0.038358893 | G23: 45637 | H23: 24641.801 | I23: =H23/H22-1 -> 0.0012901233 | M23: Observations | N23: 245
B24: 45638 | C24: 504.54999 | D24: =C24/C23-1 -> -0.034723597 | G24: 45638 | H24: 24548.699 | I24: =H24/H23-1 -> -0.0037781964
B25: 45639 | C25: 532.5 | D25: =C25/C24-1 -> 0.055395923 | G25: 45639 | H25: 24768.301 | I25: =H25/H24-1 -> 0.0089455478 | M25: ANOVA
B26: 45642 | C26: 594.79999 | D26: =C26/C25-1 -> 0.11699528 | G26: 45642 | H26: 24668.25 | I26: =H26/H25-1 -> -0.0040394689 | N26: df | O26: SS | P26: MS | Q26: F | R26: Significance F
B27: 45643 | C27: 586 | D27: =C27/C26-1 -> -0.014794869 | G27: 45643 | H27: 24336 | I27: =H27/H26-1 -> -0.01346873 | M27: Regression | N27: 1 | O27: 0.022725353 | P27: 0.022725353 | Q27: 26.619406 | R27: 5.1458708e-07
B28: 45644 | C28: 577.34998 | D28: =C28/C27-1 -> -0.014761134 | G28: 45644 | H28: 24198.85 | I28: =H28/H27-1 -> -0.0056356998 | M28: Residual | N28: 243 | O28: 0.20745244 | P28: 0.00085371374
B29: 45645 | C29: 582.25 | D29: =C29/C28-1 -> 0.0084870956 | G29: 45645 | H29: 23951.699 | I29: =H29/H28-1 -> -0.010213312 | M29: Total | N29: 244 | O29: 0.23017779
B30: 45646 | C30: 597.5 | D30: =C30/C29-1 -> 0.026191498 | G30: 45646 | H30: 23587.5 | I30: =H30/H29-1 -> -0.015205569
B31: 45649 | C31: 583.90002 | D31: =C31/C30-1 -> -0.022761465 | G31: 45649 | H31: 23753.449 | I31: =H31/H30-1 -> 0.007035473 | N31: Coefficients | O31: Standard Error | P31: t Stat | Q31: P-value | R31: Lower 95% | S31: Upper 95% | T31: Lower 95.0% | U31: Upper 95.0%
B32: 45650 | C32: 567.45001 | D32: =C32/C31-1 -> -0.028172652 | G32: 45650 | H32: 23727.65 | I32: =H32/H31-1 -> -0.0010861087 | M32: Intercept | N32: -0.00033571179 | O32: 0.0018695322 | P32: -0.17956994 | Q32: 0.85763985 | R32: -0.0040182685 | S32: 0.0033468449 | T32: -0.0040182685 | U32: 0.0033468449
B33: 45652 | C33: 559.15002 | D33: =C33/C32-1 -> -0.014626818 | G33: 45652 | H33: 23750.199 | I33: =H33/H32-1 -> 0.00095031863 | M33: X Variable 1 | N33: 1.2287861 | O33: 0.23816454 | P33: 5.1593998 | Q33: 5.1458708e-07 | R33: 0.75965565 | S33: 1.6979165 | T33: 0.75965565 | U33: 1.6979165
B34: 45653 | C34: 546 | D34: =C34/C33-1 -> -0.023517882 | G34: 45653 | H34: 23813.4 | I34: =H34/H33-1 -> 0.0026610797
B35: 45656 | C35: 550.09998 | D35: =C35/C34-1 -> 0.0075091128 | G35: 45656 | H35: 23644.9 | I35: =H35/H34-1 -> -0.0070758479
B36: 45657 | C36: 540.59998 | D36: =C36/C35-1 -> -0.017269588 | G36: 45657 | H36: 23644.801 | I36: =H36/H35-1 -> -4.2127213e-06
B37: 45658 | C37: 542.15002 | D37: =C37/C36-1 -> 0.0028672751 | G37: 45658 | H37: 23742.9 | I37: =H37/H36-1 -> 0.0041488871
B38: 45659 | C38: 556.90002 | D38: =C38/C37-1 -> 0.027206491 | G38: 45659 | H38: 24188.65 | I38: =H38/H37-1 -> 0.018774033
B39: 45660 | C39: 541.40002 | D39: =C39/C38-1 -> -0.027832644 | G39: 45660 | H39: 24004.75 | I39: =H39/H38-1 -> -0.0076027553
B40: 45663 | C40: 532.45001 | D40: =C40/C39-1 -> -0.016531237 | G40: 45663 | H40: 23616.051 | I40: =H40/H39-1 -> -0.016192596
B41: 45664 | C41: 508.95001 | D41: =C41/C40-1 -> -0.044135599 | G41: 45664 | H41: 23707.9 | I41: =H41/H40-1 -> 0.0038892874
B42: 45665 | C42: 490.64999 | D42: =C42/C41-1 -> -0.035956416 | G42: 45665 | H42: 23688.949 | I42: =H42/H41-1 -> -0.00079936104
B43: 45666 | C43: 507.60001 | D43: =C43/C42-1 -> 0.034546036 | G43: 45666 | H43: 23526.5 | I43: =H43/H42-1 -> -0.006857595
...

Sheet Beta 4
B2: Regression Beta -1 Years
B4: Info Edg. Returns | G4: Nifty Returns | L4: Beta Drifting
B6: Date | C6: Closing Price | D6: Return | G6: Date | H6: Closing Price | I6: Return | L6: Levered Raw Beta | M6: =P6 -> 1.5841972 | O6: Beta | P6: =N33 -> 1.5841972
B7: 45614 | C7: 1511.786 | G7: 45614 | H7: 23453.801 | L7: Raw Beta Weight | M7: 0.75
B8: 45615 | C8: 1521.2524 | D8: =C8/C7-1 -> 0.0062617531 | G8: 45615 | H8: 23518.5 | I8: =H8/H7-1 -> 0.0027585814
B9: 45617 | C9: 1499.3566 | D9: =C9/C8-1 -> -0.014393321 | G9: 45617 | H9: 23349.9 | I9: =H9/H8-1 -> -0.0071688079 | L9: Market Beta | M9: 1
B10: 45618 | C10: 1596.0372 | D10: =C10/C9-1 -> 0.064481436 | G10: 45618 | H10: 23907.25 | I10: =H10/H9-1 -> 0.023869464 | L10: Market Beta Weight | M10: 0.25
B11: 45621 | C11: 1635.0107 | D11: =C11/C10-1 -> 0.024418923 | G11: 45621 | H11: 24221.9 | I11: =H11/H10-1 -> 0.013161296
B12: 45622 | C12: 1645.4349 | D12: =C12/C11-1 -> 0.0063756121 | G12: 45622 | H12: 24194.5 | I12: =H12/H11-1 -> -0.0011312238 | L12: Adjusted Beta | M12: =(M6*M7)+(M9*M10) -> 1.4381479
B13: 45623 | C13: 1664.4379 | D13: =C13/C12-1 -> 0.011548879 | G13: 45623 | H13: 24274.9 | I13: =H13/H12-1 -> 0.0033230854
B14: 45624 | C14: 1636.3374 | D14: =C14/C13-1 -> -0.016882855 | G14: 45624 | H14: 23914.15 | I14: =H14/H13-1 -> -0.014861029
B15: 45625 | C15: 1646.9811 | D15: =C15/C14-1 -> 0.0065045734 | G15: 45625 | H15: 24131.1 | I15: =H15/H14-1 -> 0.0090720019 | M15: SUMMARY OUTPUT
B16: 45628 | C16: 1685.2662 | D16: =C16/C15-1 -> 0.023245656 | G16: 45628 | H16: 24276.051 | I16: =H16/H15-1 -> 0.00600682 | M16: SUMMARY OUTPUT
B17: 45629 | C17: 1690.3137 | D17: =C17/C16-1 -> 0.002995067 | G17: 45629 | H17: 24457.15 | I17: =H17/H16-1 -> 0.0074600111
B18: 45630 | C18: 1684.937 | D18: =C18/C17-1 -> -0.0031808941 | G18: 45630 | H18: 24467.449 | I18: =H18/H17-1 -> 0.00042109681 | M18: Regression Statistics
B19: 45631 | C19: 1700.0996 | D19: =C19/C18-1 -> 0.0089989107 | G19: 45631 | H19: 24708.4 | I19: =H19/H18-1 -> 0.0098478256 | M19: Multiple R | N19: 0.59773132
B20: 45632 | C20: 1692.5881 | D20: =C20/C19-1 -> -0.0044182556 | G20: 45632 | H20: 24677.801 | I20: =H20/H19-1 -> -0.0012384294 | M20: R Square | N20: 0.35728273
B21: 45635 | C21: 1679.6102 | D21: =C21/C20-1 -> -0.0076674916 | G21: 45635 | H21: 24619 | I21: =H21/H20-1 -> -0.0023827399 | M21: Adjusted R Square | N21: 0.35464864
B22: 45636 | C22: 1699.7106 | D22: =C22/C21-1 -> 0.011967266 | G22: 45636 | H22: 24610.051 | I22: =H22/H21-1 -> -0.00036350862 | M22: Standard Error | N22: 0.016688054
B23: 45637 | C23: 1707.182 | D23: =C23/C22-1 -> 0.0043957105 | G23: 45637 | H23: 24641.801 | I23: =H23/H22-1 -> 0.0012901233 | M23: Observations | N23: 246
B24: 45638 | C24: 1718.6036 | D24: =C24/C23-1 -> 0.0066903416 | G24: 45638 | H24: 24548.699 | I24: =H24/H23-1 -> -0.0037781964
B25: 45639 | C25: 1736.1802 | D25: =C25/C24-1 -> 0.01022722 | G25: 45639 | H25: 24768.301 | I25: =H25/H24-1 -> 0.0089455478 | M25: ANOVA
B26: 45642 | C26: 1757.4375 | D26: =C26/C25-1 -> 0.012243732 | G26: 45642 | H26: 24668.25 | I26: =H26/H25-1 -> -0.0040394689 | N26: df | O26: SS | P26: MS | Q26: F | R26: Significance F
B27: 45643 | C27: 1766.3954 | D27: =C27/C26-1 -> 0.0050971291 | G27: 45643 | H27: 24336 | I27: =H27/H26-1 -> -0.01346873 | M27: Regression | N27: 1 | O27: 0.037774025 | P27: 0.037774025 | Q27: 135.63816 | R27: 3.2107777e-25
B28: 45644 | C28: 1770.4054 | D28: =C28/C27-1 -> 0.0022701654 | G28: 45644 | H28: 24198.85 | I28: =H28/H27-1 -> -0.0056356998 | M28: Residual | N28: 244 | O28: 0.067951838 | P28: 0.00027849114
B29: 45645 | C29: 1735.1128 | D29: =C29/C28-1 -> -0.019934758 | G29: 45645 | H29: 23951.699 | I29: =H29/H28-1 -> -0.010213312 | M29: Total | N29: 245 | O29: 0.10572586
B30: 45646 | C30: 1694.7926 | D30: =C30/C29-1 -> -0.023237792 | G30: 45646 | H30: 23587.5 | I30: =H30/H29-1 -> -0.015205569
B31: 45649 | C31: 1720.6985 | D31: =C31/C30-1 -> 0.015285578 | G31: 45649 | H31: 23753.449 | I31: =H31/H30-1 -> 0.007035473 | N31: Coefficients | O31: Standard Error | P31: t Stat | Q31: P-value | R31: Lower 95% | S31: Upper 95% | T31: Lower 95.0% | U31: Upper 95.0%
B32: 45650 | C32: 1730.3246 | D32: =C32/C31-1 -> 0.0055942971 | G32: 45650 | H32: 23727.65 | I32: =H32/H31-1 -> -0.0010861087 | M32: Intercept | N32: -0.00094285649 | O32: 0.0010656392 | P32: -0.88478026 | Q32: 0.3771462 | R32: -0.0030418822 | S32: 0.0011561692 | T32: -0.0030418822 | U32: 0.0011561692
B33: 45652 | C33: 1729.2174 | D33: =C33/C32-1 -> -0.00063986708 | G33: 45652 | H33: 23750.199 | I33: =H33/H32-1 -> 0.00095031863 | M33: X Variable 1 | N33: 1.5841972 | O33: 0.13602487 | P33: 11.64638 | Q33: 3.2107777e-25 | R33: 1.3162644 | S33: 1.85213 | T33: 1.3162644 | U33: 1.85213
B34: 45653 | C34: 1723.2223 | D34: =C34/C33-1 -> -0.003466954 | G34: 45653 | H34: 23813.4 | I34: =H34/H33-1 -> 0.0026610797
B35: 45656 | C35: 1738.2451 | D35: =C35/C34-1 -> 0.0087178696 | G35: 45656 | H35: 23644.9 | I35: =H35/H34-1 -> -0.0070758479
B36: 45657 | C36: 1731.1625 | D36: =C36/C35-1 -> -0.0040745931 | G36: 45657 | H36: 23644.801 | I36: =H36/H35-1 -> -4.2127213e-06
B37: 45658 | C37: 1741.7662 | D37: =C37/C36-1 -> 0.0061252251 | G37: 45658 | H37: 23742.9 | I37: =H37/H36-1 -> 0.0041488871
B38: 45659 | C38: 1771.403 | D38: =C38/C37-1 -> 0.017015325 | G38: 45659 | H38: 24188.65 | I38: =H38/H37-1 -> 0.018774033
B39: 45660 | C39: 1800.6405 | D39: =C39/C38-1 -> 0.016505307 | G39: 45660 | H39: 24004.75 | I39: =H39/H38-1 -> -0.0076027553
B40: 45663 | C40: 1758.7942 | D40: =C40/C39-1 -> -0.023239682 | G40: 45663 | H40: 23616.051 | I40: =H40/H39-1 -> -0.016192596
B41: 45664 | C41: 1683.5604 | D41: =C41/C40-1 -> -0.042775764 | G41: 45664 | H41: 23707.9 | I41: =H41/H40-1 -> 0.0038892874
B42: 45665 | C42: 1643.3501 | D42: =C42/C41-1 -> -0.023884101 | G42: 45665 | H42: 23688.949 | I42: =H42/H41-1 -> -0.00079936104
B43: 45666 | C43: 1585.9323 | D43: =C43/C42-1 -> -0.03493951 | G43: 45666 | H43: 23526.5 | I43: =H43/H42-1 -> -0.006857595
...

Sheet Beta 5
B2: Regression Beta -1 Years
B4: FSN E-Commerce Ventures Limited Returns | G4: Nifty Returns | L4: Beta Drifting
B6: Date | C6: Closing Price | D6: Return | G6: Date | H6: Closing Price | I6: Return | L6: Levered Raw Beta | M6: =P6 -> 0.73329945 | O6: Beta | P6: =N32 -> 0.73329945
B7: 45614 | C7: 169.69 | G7: 45614 | H7: 23453.801 | L7: Raw Beta Weight | M7: 0.75
B8: 45615 | C8: 170.31 | D8: =C8/C7-1 -> 0.0036536927 | G8: 45615 | H8: 23518.5 | I8: =H8/H7-1 -> 0.0027585814
B9: 45617 | C9: 167.92999 | D9: =C9/C8-1 -> -0.013974546 | G9: 45617 | H9: 23349.9 | I9: =H9/H8-1 -> -0.0071688079 | L9: Market Beta | M9: 1
B10: 45618 | C10: 169.39999 | D10: =C10/C9-1 -> 0.008753655 | G10: 45618 | H10: 23907.25 | I10: =H10/H9-1 -> 0.023869464 | L10: Market Beta Weight | M10: 0.25
B11: 45621 | C11: 168.05 | D11: =C11/C10-1 -> -0.0079692497 | G11: 45621 | H11: 24221.9 | I11: =H11/H10-1 -> 0.013161296
B12: 45622 | C12: 168.06 | D12: =C12/C11-1 -> 5.9473411e-05 | G12: 45622 | H12: 24194.5 | I12: =H12/H11-1 -> -0.0011312238 | L12: Adjusted Beta | M12: =(M6*M7)+(M9*M10) -> 0.79997459
B13: 45623 | C13: 170.28 | D13: =C13/C12-1 -> 0.013209575 | G13: 45623 | H13: 24274.9 | I13: =H13/H12-1 -> 0.0033230854
B14: 45624 | C14: 174.00999 | D14: =C14/C13-1 -> 0.021905073 | G14: 45624 | H14: 23914.15 | I14: =H14/H13-1 -> -0.014861029
B15: 45625 | C15: 172.06 | D15: =C15/C14-1 -> -0.011206235 | G15: 45625 | H15: 24131.1 | I15: =H15/H14-1 -> 0.0090720019 | M15: SUMMARY OUTPUT
B16: 45628 | C16: 171.21001 | D16: =C16/C15-1 -> -0.004940084 | G16: 45628 | H16: 24276.051 | I16: =H16/H15-1 -> 0.00600682
B17: 45629 | C17: 171.88 | D17: =C17/C16-1 -> 0.003913312 | G17: 45629 | H17: 24457.15 | I17: =H17/H16-1 -> 0.0074600111 | M17: Regression Statistics
B18: 45630 | C18: 169.10001 | D18: =C18/C17-1 -> -0.016174067 | G18: 45630 | H18: 24467.449 | I18: =H18/H17-1 -> 0.00042109681 | M18: Multiple R | N18: 0.3211226
B19: 45631 | C19: 167.42999 | D19: =C19/C18-1 -> -0.0098758922 | G19: 45631 | H19: 24708.4 | I19: =H19/H18-1 -> 0.0098478256 | M19: R Square | N19: 0.10311972
B20: 45632 | C20: 166.41 | D20: =C20/C19-1 -> -0.0060920328 | G20: 45632 | H20: 24677.801 | I20: =H20/H19-1 -> -0.0012384294 | M20: Adjusted R Square | N20: 0.099443983
B21: 45635 | C21: 166.03999 | D21: =C21/C20-1 -> -0.0022234864 | G21: 45635 | H21: 24619 | I21: =H21/H20-1 -> -0.0023827399 | M21: Standard Error | N21: 0.016985182
B22: 45636 | C22: 172.56 | D22: =C22/C21-1 -> 0.039267674 | G22: 45636 | H22: 24610.051 | I22: =H22/H21-1 -> -0.00036350862 | M22: Observations | N22: 246
B23: 45637 | C23: 169.91 | D23: =C23/C22-1 -> -0.015356942 | G23: 45637 | H23: 24641.801 | I23: =H23/H22-1 -> 0.0012901233
B24: 45638 | C24: 169.8 | D24: =C24/C23-1 -> -0.00064740514 | G24: 45638 | H24: 24548.699 | I24: =H24/H23-1 -> -0.0037781964 | M24: ANOVA
B25: 45639 | C25: 168.17999 | D25: =C25/C24-1 -> -0.009540697 | G25: 45639 | H25: 24768.301 | I25: =H25/H24-1 -> 0.0089455478 | N25: df | O25: SS | P25: MS | Q25: F | R25: Significance F
B26: 45642 | C26: 174.56 | D26: =C26/C25-1 -> 0.037935576 | G26: 45642 | H26: 24668.25 | I26: =H26/H25-1 -> -0.0040394689 | M26: Regression | N26: 1 | O26: 0.0080935206 | P26: 0.0080935206 | Q26: 28.054148 | R26: 2.6335274e-07
B27: 45643 | C27: 176.37 | D27: =C27/C26-1 -> 0.010368914 | G27: 45643 | H27: 24336 | I27: =H27/H26-1 -> -0.01346873 | M27: Residual | N27: 244 | O27: 0.07039312 | P27: 0.00028849639
B28: 45644 | C28: 173.3 | D28: =C28/C27-1 -> -0.017406544 | G28: 45644 | H28: 24198.85 | I28: =H28/H27-1 -> -0.0056356998 | M28: Total | N28: 245 | O28: 0.078486641
B29: 45645 | C29: 170 | D29: =C29/C28-1 -> -0.019042141 | G29: 45645 | H29: 23951.699 | I29: =H29/H28-1 -> -0.010213312
B30: 45646 | C30: 167.33 | D30: =C30/C29-1 -> -0.015705872 | G30: 45646 | H30: 23587.5 | I30: =H30/H29-1 -> -0.015205569 | N30: Coefficients | O30: Standard Error | P30: t Stat | Q30: P-value | R30: Lower 95% | S30: Upper 95% | T30: Lower 95.0% | U30: Upper 95.0%
B31: 45649 | C31: 160.05 | D31: =C31/C30-1 -> -0.043506835 | G31: 45649 | H31: 23753.449 | I31: =H31/H30-1 -> 0.007035473 | M31: Intercept | N31: 0.0015272421 | O31: 0.0010846127 | P31: 1.4080991 | Q31: 0.16037455 | R31: -0.00060915634 | S31: 0.0036636406 | T31: -0.00060915634 | U31: 0.0036636406
B32: 45650 | C32: 161.94 | D32: =C32/C31-1 -> 0.011808806 | G32: 45650 | H32: 23727.65 | I32: =H32/H31-1 -> -0.0010861087 | M32: X Variable 1 | N32: 0.73329945 | O32: 0.13844677 | P32: 5.2966167 | Q32: 2.6335274e-07 | R32: 0.46059615 | S32: 1.0060028 | T32: 0.46059615 | U32: 1.0060028
B33: 45652 | C33: 160.85001 | D33: =C33/C32-1 -> -0.0067308653 | G33: 45652 | H33: 23750.199 | I33: =H33/H32-1 -> 0.00095031863
B34: 45653 | C34: 159.66 | D34: =C34/C33-1 -> -0.007398212 | G34: 45653 | H34: 23813.4 | I34: =H34/H33-1 -> 0.0026610797
B35: 45656 | C35: 161.95 | D35: =C35/C34-1 -> 0.014342936 | G35: 45656 | H35: 23644.9 | I35: =H35/H34-1 -> -0.0070758479
B36: 45657 | C36: 163.75999 | D36: =C36/C35-1 -> 0.011176274 | G36: 45657 | H36: 23644.801 | I36: =H36/H35-1 -> -4.2127213e-06
B37: 45658 | C37: 164.67999 | D37: =C37/C36-1 -> 0.0056179665 | G37: 45658 | H37: 23742.9 | I37: =H37/H36-1 -> 0.0041488871
B38: 45659 | C38: 165.32001 | D38: =C38/C37-1 -> 0.0038864141 | G38: 45659 | H38: 24188.65 | I38: =H38/H37-1 -> 0.018774033
B39: 45660 | C39: 167.84 | D39: =C39/C38-1 -> 0.015243098 | G39: 45660 | H39: 24004.75 | I39: =H39/H38-1 -> -0.0076027553
B40: 45663 | C40: 171.52 | D40: =C40/C39-1 -> 0.021925691 | G40: 45663 | H40: 23616.051 | I40: =H40/H39-1 -> -0.016192596
B41: 45664 | C41: 172.31 | D41: =C41/C40-1 -> 0.0046058376 | G41: 45664 | H41: 23707.9 | I41: =H41/H40-1 -> 0.0038892874
B42: 45665 | C42: 169.52 | D42: =C42/C41-1 -> -0.016191709 | G42: 45665 | H42: 23688.949 | I42: =H42/H41-1 -> -0.00079936104
B43: 45666 | C43: 170.2 | D43: =C43/C42-1 -> 0.0040112828 | G43: 45666 | H43: 23526.5 | I43: =H43/H42-1 -> -0.006857595
...

Sheet RM
A2: Returns on Markets
B4: Year | C4: Annual
B5: 2000 | C5: -0.1465
B6: 2001 | C6: -0.1618 | E6: Average Return | F6: =AVERAGE(C5:C29) -> 0.153348
B7: 2002 | C7: 0.0325 | E7: Dividend Yield | F7: 1.35% 1
B8: 2003 | C8: 0.719 | E8: Total Market Return | F8: =SUM(F6:F7) -> 0.153348
B9: 2004 | C9: 0.1068
B10: 2005 | C10: 0.3634
B11: 2006 | C11: 0.3983
B12: 2007 | C12: 0.5477
B13: 2008 | C13: -0.5179
B14: 2009 | C14: 0.7576
B15: 2010 | C15: 0.1795
B16: 2011 | C16: -0.2462
B17: 2012 | C17: 0.277
B18: 2013 | C18: 0.0676
B19: 2014 | C19: 0.3139
B20: 2015 | C20: -0.0406
... B29: 2024 | C29: 0.0875
B30: 2025
