Workbook

Sheet Financial>

Sheet Ratio Analysis
B2: ="Ratio Analysis - "&'Data Sheet'!B1 -> Ratio Analysis - INFOSYS LTD
B3: Years | C3: ='[1]Data Sheet'!B16 -> 42460 | D3: ='[1]Data Sheet'!C16 -> 42825 | E3: ='[1]Data Sheet'!D16 -> 43190 | F3: ='[1]Data Sheet'!E16 -> 43555 | G3: ='[1]Data Sheet'!F16 -> 43921 | H3: ='[1]Data Sheet'!G16 -> 44286 | I3: ='[1]Data Sheet'!H16 -> 44651 | J3: ='[1]Data Sheet'!I16 -> 45016 | ... L3: ='[1]Data Sheet'!K16 -> 45747 | M3: Trend | N3: Mean | O3: Median
B5: Sales Growth | D5: =IFERROR('Historical FS'!D7,0) -> 0.09677936 | E5: =IFERROR('Historical FS'!E7,0) -> 0.029758776 | F5: =IFERROR('Historical FS'!F7,0) -> 0.1723292 | G5: =IFERROR('Historical FS'!G7,0) -> 0.098167523 | H5: =IFERROR('Historical FS'!H7,0) -> 0.10662951 | I5: =IFERROR('Historical FS'!I7,0) -> 0.21069552 | J5: =IFERROR('Historical FS'!J7,0) -> 0.20655864 | K5: =IFERROR('Historical FS'!K7,0) -> 0.047033734 | L5: =IFERROR('Historical FS'!L7,0) -> 0.060649444 | N5: =IFERROR(AVERAGE(D5:L5),0) -> 0.11428908 | O5: =IFERROR(MEDIAN(D5:L5),0) -> 0.098167523
B6: EBITDA Growth | D6: =IFERROR('Historical FS'!D18/'Historical FS'!C18-1,0) -> 0.089290942 | E6: =IFERROR('Historical FS'!E18/'Historical FS'!D18-1,0) -> 0.01171791 | F6: =IFERROR('Historical FS'!F18/'Historical FS'!E18-1,0) -> 0.071618319 | G6: =IFERROR('Historical FS'!G18/'Historical FS'!F18-1,0) -> 0.10396629 | H6: =IFERROR('Historical FS'!H18/'Historical FS'!G18-1,0) -> 0.25248125 | I6: =IFERROR('Historical FS'!I18/'Historical FS'!H18-1,0) -> 0.12915486 | J6: =IFERROR('Historical FS'!J18/'Historical FS'!I18-1,0) -> 0.11555683 | K6: =IFERROR('Historical FS'!K18/'Historical FS'!J18-1,0) -> 0.03686308 | L6: =IFERROR('Historical FS'!L18/'Historical FS'!K18-1,0) -> 0.077172272 | N6: =IFERROR(AVERAGE(D6:L6),0) -> 0.098646861 | O6: =IFERROR(MEDIAN(D6:L6),0) -> 0.089290942
B7: EBIT Growth | D7: =IFERROR('Historical FS'!D27/'Historical FS'!C27-1,0) -> 0.082010243 | E7: =IFERROR('Historical FS'!E27/'Historical FS'!D27-1,0) -> 0.0034317496 | F7: =IFERROR('Historical FS'!F27/'Historical FS'!E27-1,0) -> 0.070758889 | G7: =IFERROR('Historical FS'!G27/'Historical FS'!F27-1,0) -> 0.057547222 | H7: =IFERROR('Historical FS'!H27/'Historical FS'!G27-1,0) -> 0.27197459 | I7: =IFERROR('Historical FS'!I27/'Historical FS'!H27-1,0) -> 0.13869898 | J7: =IFERROR('Historical FS'!J27/'Historical FS'!I27-1,0) -> 0.10088082 | K7: =IFERROR('Historical FS'!K27/'Historical FS'!J27-1,0) -> 0.021423206 | L7: =IFERROR('Historical FS'!L27/'Historical FS'!K27-1,0) -> 0.087316558 | N7: =IFERROR(AVERAGE(D7:L7),0) -> 0.092671362 | O7: =IFERROR(MEDIAN(D7:L7),0) -> 0.082010243
B8: Net Profit Growth | D8: =IFERROR('Historical FS'!D33/'Historical FS'!C33-1,0) -> 0.090076189 | E8: =IFERROR('Historical FS'!E33/'Historical FS'!D33-1,0) -> 0.125188 | F8: =IFERROR('Historical FS'!F33/'Historical FS'!E33-1,0) -> -0.014939456 | G8: =IFERROR('Historical FS'!G33/'Historical FS'!F33-1,0) -> 0.10440613 | H8: =IFERROR('Historical FS'!H33/'Historical FS'!G33-1,0) -> 0.24472391 | I8: =IFERROR('Historical FS'!I33/'Historical FS'!H33-1,0) -> 0.15265358 | J8: =IFERROR('Historical FS'!J33/'Historical FS'!I33-1,0) -> 0.078383961 | K8: =IFERROR('Historical FS'!K33/'Historical FS'!J33-1,0) -> 0.0060727799 | L8: =IFERROR('Historical FS'!L33/'Historical FS'!K33-1,0) -> 0.074894368 | N8: =IFERROR(AVERAGE(D8:L8),0) -> 0.095717718 | O8: =IFERROR(MEDIAN(D8:L8),0) -> 0.090076189
B9: Dividend Growth | D9: =IFERROR('Historical FS'!D41/'Historical FS'!C41-1,0) -> 0.06185567 | E9: =IFERROR('Historical FS'!E41/'Historical FS'!D41-1,0) -> 0.68963897 | F9: =IFERROR('Historical FS'!F41/'Historical FS'!E41-1,0) -> -0.02583858 | G9: =IFERROR('Historical FS'!G41/'Historical FS'!F41-1,0) -> -0.17390646 | H9: =IFERROR('Historical FS'!H41/'Historical FS'!G41-1,0) -> 0.54369512 | I9: =IFERROR('Historical FS'!I41/'Historical FS'!H41-1,0) -> 0.14865158 | J9: =IFERROR('Historical FS'!J41/'Historical FS'!I41-1,0) -> 0.096761529 | K9: =IFERROR('Historical FS'!K41/'Historical FS'!J41-1,0) -> 0.35349861 | L9: =IFERROR('Historical FS'!L41/'Historical FS'!K41-1,0) -> -0.064855345 | N9: =IFERROR(AVERAGE(D9:L9),0) -> 0.18105568 | O9: =IFERROR(MEDIAN(D9:L9),0) -> 0.096761529
B11: Gross Margin | C11: =IFERROR('Historical FS'!C13,0) -> 0.35151583 | D11: =IFERROR('Historical FS'!D13,0) -> 0.34862158 | E11: =IFERROR('Historical FS'!E13,0) -> 0.34212019 | F11: =IFERROR('Historical FS'!F13,0) -> 0.32934986 | G11: =IFERROR('Historical FS'!G13,0) -> 0.31479993 | H11: =IFERROR('Historical FS'!H13,0) -> 0.31831754 | I11: =IFERROR('Historical FS'!I13,0) -> 0.30271043 | J11: =IFERROR('Historical FS'!J13,0) -> 0.28539794 | ... L11: =IFERROR('Historical FS'!L13,0) -> 0.28471072 | N11: =IFERROR(AVERAGE(C11:L11),0) -> 0.31615292 | O11: =IFERROR(MEDIAN(C11:L11),0) -> 0.31655873
B12: EBITDA Margin | C12: =IFERROR('Historical FS'!C19,0) -> 0.2735222 | D12: =IFERROR('Historical FS'!D19,0) -> 0.27165469 | E12: =IFERROR('Historical FS'!E19,0) -> 0.26689544 | F12: =IFERROR('Historical FS'!F19,0) -> 0.24396734 | G12: =IFERROR('Historical FS'!G19,0) -> 0.24525559 | H12: =IFERROR('Historical FS'!H19,0) -> 0.27757982 | I12: =IFERROR('Historical FS'!I19,0) -> 0.25888475 | J12: =IFERROR('Historical FS'!J19,0) -> 0.23935898 | ... L12: =IFERROR('Historical FS'!L19,0) -> 0.24072642 | N12: =IFERROR(AVERAGE(C12:L12),0) -> 0.25548792 | O12: =IFERROR(MEDIAN(C12:L12),0) -> 0.25207017
B13: EBIT Margin | C13: =IFERROR(('Historical FS'!C18-'Historical FS'!C24)/'Historical FS'!C6,0) -> 0.25015615 | D13: =IFERROR(('Historical FS'!D18-'Historical FS'!D24)/'Historical FS'!D6,0) -> 0.24678757 | E13: =IFERROR(('Historical FS'!E18-'Historical FS'!E24)/'Historical FS'!E6,0) -> 0.24047815 | F13: =IFERROR(('Historical FS'!F18-'Historical FS'!F24)/'Historical FS'!F6,0) -> 0.21964318 | G13: =IFERROR(('Historical FS'!G18-'Historical FS'!G24)/'Historical FS'!G6,0) -> 0.2133912 | H13: =IFERROR(('Historical FS'!H18-'Historical FS'!H24)/'Historical FS'!H6,0) -> 0.2450633 | I13: =IFERROR(('Historical FS'!I18-'Historical FS'!I24)/'Historical FS'!I6,0) -> 0.23030886 | J13: =IFERROR(('Historical FS'!J18-'Historical FS'!J24)/'Historical FS'!J6,0) -> 0.21057186 | ... L13: =IFERROR(('Historical FS'!L18-'Historical FS'!L24)/'Historical FS'!L6,0) -> 0.21120314 | N13: =IFERROR(AVERAGE(C13:L13),0) -> 0.22741955 | O13: =IFERROR(MEDIAN(C13:L13),0) -> 0.22497602
B14: EBT Margin | C14: =IFERROR('Historical FS'!C28,0) -> 0.25015615 | D14: =IFERROR('Historical FS'!D28,0) -> 0.24678757 | E14: =IFERROR('Historical FS'!E28,0) -> 0.24047815 | F14: =IFERROR('Historical FS'!F28,0) -> 0.21964318 | G14: =IFERROR('Historical FS'!G28,0) -> 0.21151876 | H14: =IFERROR('Historical FS'!H28,0) -> 0.24312246 | I14: =IFERROR('Historical FS'!I28,0) -> 0.22866468 | J14: =IFERROR('Historical FS'!J28,0) -> 0.20863682 | ... L14: =IFERROR('Historical FS'!L28,0) -> 0.20865084 | N14: =IFERROR(AVERAGE(C14:L14),0) -> 0.22611922 | O14: =IFERROR(MEDIAN(C14:L14),0) -> 0.22415393
B15: Net profit Margin | C15: =IFERROR('Historical FS'!C34,0) -> 0.16606076 | D15: =IFERROR('Historical FS'!D34,0) -> 0.16504585 | E15: =IFERROR('Historical FS'!E34,0) -> 0.18034089 | F15: =IFERROR('Historical FS'!F34,0) -> 0.15153311 | G15: =IFERROR('Historical FS'!G34,0) -> 0.15239396 | H15: =IFERROR('Historical FS'!H34,0) -> 0.17141094 | I15: =IFERROR('Historical FS'!I34,0) -> 0.16319333 | J15: =IFERROR('Historical FS'!J34,0) -> 0.14585704 | ... L15: =IFERROR('Historical FS'!L34,0) -> 0.14203325 | N15: =IFERROR(AVERAGE(C15:L15),0) -> 0.15780201 | O15: =IFERROR(MEDIAN(C15:L15),0) -> 0.15779365
B17: SalesExpenses%Sales | C17: =IFERROR('Historical FS'!C16,0) -> 0.077993626 | D17: =IFERROR('Historical FS'!D16,0) -> 0.076966883 | E17: =IFERROR('Historical FS'!E16,0) -> 0.075224753 | F17: =IFERROR('Historical FS'!F16,0) -> 0.085382522 | G17: =IFERROR('Historical FS'!G16,0) -> 0.069544338 | H17: =IFERROR('Historical FS'!H16,0) -> 0.040737718 | I17: =IFERROR('Historical FS'!I16,0) -> 0.043825684 | J17: =IFERROR('Historical FS'!J16,0) -> 0.04603896 | ... L17: =IFERROR('Historical FS'!L16,0) -> 0.043984294 | N17: =IFERROR(AVERAGE(C17:L17),0) -> 0.060665004 | O17: =IFERROR(MEDIAN(C17:L17),0) -> 0.058247799
B18: Depreciation%Sales | C18: =IFERROR('Historical FS'!C25,0) -> 0.023366058 | D18: =IFERROR('Historical FS'!D25,0) -> 0.024867122 | E18: =IFERROR('Historical FS'!E25,0) -> 0.026417288 | F18: =IFERROR('Historical FS'!F25,0) -> 0.024324161 | G18: =IFERROR('Historical FS'!G25,0) -> 0.031864392 | H18: =IFERROR('Historical FS'!H25,0) -> 0.032516522 | I18: =IFERROR('Historical FS'!I25,0) -> 0.028575891 | J18: =IFERROR('Historical FS'!J25,0) -> 0.028787125 | ... L18: =IFERROR('Historical FS'!L25,0) -> 0.029523284 | N18: =IFERROR(AVERAGE(C18:L18),0) -> 0.02806837 | O18: =IFERROR(MEDIAN(C18:L18),0) -> 0.028681508
B19: OperatingIncome%Sales | C19: =IFERROR('Ratio Analysis'!C13,0) -> 0.25015615 | D19: =IFERROR('Ratio Analysis'!D13,0) -> 0.24678757 | E19: =IFERROR('Ratio Analysis'!E13,0) -> 0.24047815 | F19: =IFERROR('Ratio Analysis'!F13,0) -> 0.21964318 | G19: =IFERROR('Ratio Analysis'!G13,0) -> 0.2133912 | H19: =IFERROR('Ratio Analysis'!H13,0) -> 0.2450633 | I19: =IFERROR('Ratio Analysis'!I13,0) -> 0.23030886 | J19: =IFERROR('Ratio Analysis'!J13,0) -> 0.21057186 | ... L19: =IFERROR('Ratio Analysis'!L13,0) -> 0.21120314 | N19: =IFERROR(AVERAGE(C19:L19),0) -> 0.22741955 | O19: =IFERROR(MEDIAN(C19:L19),0) -> 0.22497602
B21: Return on Capital Employed | C21: =IFERROR(('Historical FS'!C18-'Historical FS'!C24)/SUM('Historical FS'!C47:C49),0) -> 0.25298005 | D21: =IFERROR(('Historical FS'!D18-'Historical FS'!D24)/SUM('Historical FS'!D47:D49),0) -> 0.24500594 | E21: =IFERROR(('Historical FS'!E18-'Historical FS'!E24)/SUM('Historical FS'!E47:E49),0) -> 0.26121713 | F21: =IFERROR(('Historical FS'!F18-'Historical FS'!F24)/SUM('Historical FS'!F47:F49),0) -> 0.27959291 | G21: =IFERROR(('Historical FS'!G18-'Historical FS'!G24)/SUM('Historical FS'!G47:G49),0) -> 0.27644365 | H21: =IFERROR(('Historical FS'!H18-'Historical FS'!H24)/SUM('Historical FS'!H47:H49),0) -> 0.30145943 | I21: =IFERROR(('Historical FS'!I18-'Historical FS'!I24)/SUM('Historical FS'!I47:I49),0) -> 0.34661734 | J21: =IFERROR(('Historical FS'!J18-'Historical FS'!J24)/SUM('Historical FS'!J47:J49),0) -> 0.3692089 | ... L21: =IFERROR(('Historical FS'!L18-'Historical FS'!L24)/SUM('Historical FS'!L47:L49),0) -> 0.33085684 | N21: =IFERROR(AVERAGE(C21:L21),0) -> 0.29924519 | O21: =IFERROR(MEDIAN(C21:L21),0) -> 0.29052617
B22: Retain Earnings% | C22: =IFERROR('Historical FS'!C44,0) -> 0 | D22: =IFERROR('Historical FS'!D44,0) -> 0 | E22: =IFERROR('Historical FS'!E44,0) -> 0 | F22: =IFERROR('Historical FS'!F44,0) -> 0 | G22: =IFERROR('Historical FS'!G44,0) -> 0 | H22: =IFERROR('Historical FS'!H44,0) -> 0 | I22: =IFERROR('Historical FS'!I44,0) -> 0 | J22: =IFERROR('Historical FS'!J44,0) -> 0 | ... L22: =IFERROR('Historical FS'!L44,0) -> 0 | N22: =IFERROR(AVERAGE(C22:L22),0) -> 0 | O22: =IFERROR(MEDIAN(C22:L22),0) -> 0
B23: Return on Equity% | C23: =IFERROR('Historical FS'!C33/SUM('Historical FS'!C47:C48),0) -> 0.16793535 | D23: =IFERROR('Historical FS'!D33/SUM('Historical FS'!D47:D48),0) -> 0.16385434 | E23: =IFERROR('Historical FS'!E33/SUM('Historical FS'!E47:E48),0) -> 0.1958936 | F23: =IFERROR('Historical FS'!F33/SUM('Historical FS'!F47:F48),0) -> 0.19289278 | G23: =IFERROR('Historical FS'!G33/SUM('Historical FS'!G47:G48),0) -> 0.21139801 | H23: =IFERROR('Historical FS'!H33/SUM('Historical FS'!H47:H48),0) -> 0.22556352 | I23: =IFERROR('Historical FS'!I33/SUM('Historical FS'!I47:I48),0) -> 0.26345056 | J23: =IFERROR('Historical FS'!J33/SUM('Historical FS'!J47:J48),0) -> 0.28388611 | ... L23: =IFERROR('Historical FS'!L33/SUM('Historical FS'!L47:L48),0) -> 0.24160387 | N23: =IFERROR(AVERAGE(C23:L23),0) -> 0.21908946 | O23: =IFERROR(MEDIAN(C23:L23),0) -> 0.21848076
B24: Self Sustained Growth Rate | C24: =IFERROR(C22*C23,0) -> 0 | D24: =IFERROR(D22*D23,0) -> 0 | E24: =IFERROR(E22*E23,0) -> 0 | F24: =IFERROR(F22*F23,0) -> 0 | G24: =IFERROR(G22*G23,0) -> 0 | H24: =IFERROR(H22*H23,0) -> 0 | I24: =IFERROR(I22*I23,0) -> 0 | J24: =IFERROR(J22*J23,0) -> 0 | ... L24: =IFERROR(L22*L23,0) -> 0 | N24: =IFERROR(AVERAGE(C24:L24),0) -> 0 | O24: =IFERROR(MEDIAN(C24:L24),0) -> 0
B25: Interest Coverage Ratio | C25: =IFERROR(('Historical FS'!C18-'Historical FS'!C24)/'Historical FS'!C21,0) -> 0 | D25: =IFERROR(('Historical FS'!D18-'Historical FS'!D24)/'Historical FS'!D21,0) -> 0 | E25: =IFERROR(('Historical FS'!E18-'Historical FS'!E24)/'Historical FS'!E21,0) -> 0 | F25: =IFERROR(('Historical FS'!F18-'Historical FS'!F24)/'Historical FS'!F21,0) -> 0 | G25: =IFERROR(('Historical FS'!G18-'Historical FS'!G24)/'Historical FS'!G21,0) -> 113.96471 | H25: =IFERROR(('Historical FS'!H18-'Historical FS'!H24)/'Historical FS'!H21,0) -> 126.26667 | I25: =IFERROR(('Historical FS'!I18-'Historical FS'!I24)/'Historical FS'!I21,0) -> 140.075 | J25: =IFERROR(('Historical FS'!J18-'Historical FS'!J24)/'Historical FS'!J21,0) -> 108.82042 | ... L25: =IFERROR(('Historical FS'!L18-'Historical FS'!L24)/'Historical FS'!L21,0) -> 82.75 | N25: =IFERROR(AVERAGE(C25:L25),0) -> 63.94236 | O25: =IFERROR(MEDIAN(C25:L25),0) -> 75.148404
B27: Debtor Turnover Ratio | C27: =IFERROR('Historical FS'!C6/'Historical FS'!C59,0) -> 5.5111209 | D27: =IFERROR('Historical FS'!D6/'Historical FS'!D59,0) -> 5.557864 | E27: =IFERROR('Historical FS'!E6/'Historical FS'!E59,0) -> 5.3661543 | F27: =IFERROR('Historical FS'!F6/'Historical FS'!F59,0) -> 5.5759763 | G27: =IFERROR('Historical FS'!G6/'Historical FS'!G59,0) -> 4.9110726 | H27: =IFERROR('Historical FS'!H6/'Historical FS'!H59,0) -> 5.207422 | I27: =IFERROR('Historical FS'!I6/'Historical FS'!I59,0) -> 5.3591065 | J27: =IFERROR('Historical FS'!J6/'Historical FS'!J59,0) -> 5.7727738 | ... L27: =IFERROR('Historical FS'!L6/'Historical FS'!L59,0) -> 5.2310803 | N27: =IFERROR(AVERAGE(C27:L27),0) -> 5.3582161 | O27: =IFERROR(MEDIAN(C27:L27),0) -> 5.3626304
B28: Creditor Turnover Ratio | C28: =IFERROR('Historical FS'!C6/'Historical FS'!C50,0) -> 4.6758275 | D28: =IFERROR('Historical FS'!D6/'Historical FS'!D50,0) -> 4.8343922 | E28: =IFERROR('Historical FS'!E6/'Historical FS'!E50,0) -> 4.8885346 | F28: =IFERROR('Historical FS'!F6/'Historical FS'!F50,0) -> 4.3244586 | G28: =IFERROR('Historical FS'!G6/'Historical FS'!G50,0) -> 4.1806419 | H28: =IFERROR('Historical FS'!H6/'Historical FS'!H50,0) -> 3.8889878 | I28: =IFERROR('Historical FS'!I6/'Historical FS'!I50,0) -> 3.3878568 | J28: =IFERROR('Historical FS'!J6/'Historical FS'!J50,0) -> 3.5893128 | ... L28: =IFERROR('Historical FS'!L6/'Historical FS'!L50,0) -> 3.7254857 | N28: =IFERROR(AVERAGE(C28:L28),0) -> 4.1254089 | O28: =IFERROR(MEDIAN(C28:L28),0) -> 4.0348149
B29: Inventory Turnover | C29: =IFERROR('Historical FS'!C6/'Historical FS'!C60,0) -> 0 | D29: =IFERROR('Historical FS'!D6/'Historical FS'!D60,0) -> 0 | E29: =IFERROR('Historical FS'!E6/'Historical FS'!E60,0) -> 0 | F29: =IFERROR('Historical FS'!F6/'Historical FS'!F60,0) -> 0 | G29: =IFERROR('Historical FS'!G6/'Historical FS'!G60,0) -> 0 | H29: =IFERROR('Historical FS'!H6/'Historical FS'!H60,0) -> 0 | I29: =IFERROR('Historical FS'!I6/'Historical FS'!I60,0) -> 0 | J29: =IFERROR('Historical FS'!J6/'Historical FS'!J60,0) -> 0 | ... L29: =IFERROR('Historical FS'!L6/'Historical FS'!L60,0) -> 0 | N29: =IFERROR(AVERAGE(C29:L29),0) -> 0 | O29: =IFERROR(MEDIAN(C29:L29),0) -> 0
B30: Fixed Asset Turnover | C30: =IFERROR('Historical FS'!C6/'Historical FS'!C53,0) -> 4.6646496 | D30: =IFERROR('Historical FS'!D6/'Historical FS'!D53,0) -> 4.8299598 | E30: =IFERROR('Historical FS'!E6/'Historical FS'!E53,0) -> 5.6085573 | F30: =IFERROR('Historical FS'!F6/'Historical FS'!F53,0) -> 5.2625716 | G30: =IFERROR('Historical FS'!G6/'Historical FS'!G53,0) -> 3.8165118 | H30: =IFERROR('Historical FS'!H6/'Historical FS'!H53,0) -> 3.939306 | I30: =IFERROR('Historical FS'!I6/'Historical FS'!I53,0) -> 4.7147674 | J30: =IFERROR('Historical FS'!J6/'Historical FS'!J53,0) -> 5.0219675 | ... L30: =IFERROR('Historical FS'!L6/'Historical FS'!L53,0) -> 5.2643648 | N30: =IFERROR(AVERAGE(C30:L30),0) -> 4.8685975 | O30: =IFERROR(MEDIAN(C30:L30),0) -> 4.9259636
B31: Capital Turnover Ratio | C31: =IFERROR('Historical FS'!C6/SUM('Historical FS'!C47:C48),0) -> 1.0112885 | D31: =IFERROR('Historical FS'!D6/SUM('Historical FS'!D47:D48),0) -> 0.99278073 | E31: =IFERROR('Historical FS'!E6/SUM('Historical FS'!E47:E48),0) -> 1.0862406 | F31: =IFERROR('Historical FS'!F6/SUM('Historical FS'!F47:F48),0) -> 1.2729414 | G31: =IFERROR('Historical FS'!G6/SUM('Historical FS'!G47:G48),0) -> 1.3871811 | H31: =IFERROR('Historical FS'!H6/SUM('Historical FS'!H47:H48),0) -> 1.3159225 | I31: =IFERROR('Historical FS'!I6/SUM('Historical FS'!I47:I48),0) -> 1.6143464 | J31: =IFERROR('Historical FS'!J6/SUM('Historical FS'!J47:J48),0) -> 1.9463312 | ... L31: =IFERROR('Historical FS'!L6/SUM('Historical FS'!L47:L48),0) -> 1.7010374 | N31: =IFERROR(AVERAGE(C31:L31),0) -> 1.4072021 | O31: =IFERROR(MEDIAN(C31:L31),0) -> 1.3515518
B34: Debtor Days | C34: =IFERROR(365/C27,0) -> 66.229721 | D34: =IFERROR(365/D27,0) -> 65.672712 | E34: =IFERROR(365/E27,0) -> 68.018916 | F34: =IFERROR(365/F27,0) -> 65.459389 | G34: =IFERROR(365/G27,0) -> 74.321849 | H34: =IFERROR(365/H27,0) -> 70.092265 | I34: =IFERROR(365/I27,0) -> 68.108368 | J34: =IFERROR(365/J27,0) -> 63.227837 | ... L34: =IFERROR(365/L27,0) -> 69.775262 | N34: =IFERROR(AVERAGE(C34:L34),0) -> 68.262133 | O34: =IFERROR(MEDIAN(C34:L34),0) -> 68.063642
B35: Payable Days | C35: =IFERROR(365/C28,0) -> 78.06105 | D35: =IFERROR(365/D28,0) -> 75.500701 | E35: =IFERROR(365/E28,0) -> 74.664502 | F35: =IFERROR(365/F28,0) -> 84.403629 | G35: =IFERROR(365/G28,0) -> 87.307167 | H35: =IFERROR(365/H28,0) -> 93.854756 | I35: =IFERROR(365/I28,0) -> 107.73773 | J35: =IFERROR(365/J28,0) -> 101.69078 | ... L35: =IFERROR(365/L28,0) -> 97.973802 | N35: =IFERROR(AVERAGE(C35:L35),0) -> 89.830496 | O35: =IFERROR(MEDIAN(C35:L35),0) -> 90.580961
B36: Inventory Days | C36: =IFERROR(365/C29,0) -> 0 | D36: =IFERROR(365/D29,0) -> 0 | E36: =IFERROR(365/E29,0) -> 0 | F36: =IFERROR(365/F29,0) -> 0 | G36: =IFERROR(365/G29,0) -> 0 | H36: =IFERROR(365/H29,0) -> 0 | I36: =IFERROR(365/I29,0) -> 0 | J36: =IFERROR(365/J29,0) -> 0 | ... L36: =IFERROR(365/L29,0) -> 0 | N36: =IFERROR(AVERAGE(C36:L36),0) -> 0 | O36: =IFERROR(MEDIAN(C36:L36),0) -> 0
B37: Cash Conversion Cycle (in Days) | C37: =IFERROR(SUM(C34+C36)-C35,0) -> -11.831329 | D37: =IFERROR(SUM(D34+D36)-D35,0) -> -9.827989 | E37: =IFERROR(SUM(E34+E36)-E35,0) -> -6.6455858 | F37: =IFERROR(SUM(F34+F36)-F35,0) -> -18.944239 | G37: =IFERROR(SUM(G34+G36)-G35,0) -> -12.985318 | H37: =IFERROR(SUM(H34+H36)-H35,0) -> -23.762491 | I37: =IFERROR(SUM(I34+I36)-I35,0) -> -39.62936 | J37: =IFERROR(SUM(J34+J36)-J35,0) -> -38.462938 | ... L37: =IFERROR(SUM(L34+L36)-L35,0) -> -28.19854 | N37: =IFERROR(AVERAGE(C37:L37),0) -> -21.568364 | O37: =IFERROR(MEDIAN(C37:L37),0) -> -21.353365
B39: CFO/ Sales | C39: =IFERROR('Historical FS'!C80/'Historical FS'!C6,0) -> 0.12943419 | D39: =IFERROR('Historical FS'!D80/'Historical FS'!D6,0) -> 0.13689329 | E39: =IFERROR('Historical FS'!E80/'Historical FS'!E6,0) -> 0.18862199 | F39: =IFERROR('Historical FS'!F80/'Historical FS'!F6,0) -> 0.17403084 | G39: =IFERROR('Historical FS'!G80/'Historical FS'!G6,0) -> 0.16120541 | H39: =IFERROR('Historical FS'!H80/'Historical FS'!H6,0) -> 0.2387929 | I39: =IFERROR('Historical FS'!I80/'Historical FS'!I6,0) -> 0.18464991 | J39: =IFERROR('Historical FS'!J80/'Historical FS'!J6,0) -> 0.1098544 | ... L39: =IFERROR('Historical FS'!L80/'Historical FS'!L6,0) -> 0.2171851 | N39: =IFERROR(AVERAGE(C39:L39),0) -> 0.167165 | O39: =IFERROR(MEDIAN(C39:L39),0) -> 0.16761812
B40: CFO/Total Assets | C40: =IFERROR('Historical FS'!C80/'Historical FS'!C64,0) -> 0.10761938 | D40: =IFERROR('Historical FS'!D80/'Historical FS'!D64,0) -> 0.11275076 | E40: =IFERROR('Historical FS'!E80/'Historical FS'!E64,0) -> 0.16763916 | F40: =IFERROR('Historical FS'!F80/'Historical FS'!F64,0) -> 0.17115124 | G40: =IFERROR('Historical FS'!G80/'Historical FS'!G64,0) -> 0.15943355 | H40: =IFERROR('Historical FS'!H80/'Historical FS'!H64,0) -> 0.22315856 | I40: =IFERROR('Historical FS'!I80/'Historical FS'!I64,0) -> 0.19242005 | J40: =IFERROR('Historical FS'!J80/'Historical FS'!J64,0) -> 0.12940223 | ... L40: =IFERROR('Historical FS'!L80/'Historical FS'!L64,0) -> 0.23951419 | N40: =IFERROR(AVERAGE(C40:L40),0) -> 0.16496238 | O40: =IFERROR(MEDIAN(C40:L40),0) -> 0.16353636
B41: CFO/Total Debt | C41: =IFERROR('Historical FS'!C80/'Historical FS'!C49,0) -> 0 | D41: =IFERROR('Historical FS'!D80/'Historical FS'!D49,0) -> 0 | E41: =IFERROR('Historical FS'!E80/'Historical FS'!E49,0) -> 0 | F41: =IFERROR('Historical FS'!F80/'Historical FS'!F49,0) -> 0 | G41: =IFERROR('Historical FS'!G80/'Historical FS'!G49,0) -> 3.1590762 | H41: =IFERROR('Historical FS'!H80/'Historical FS'!H49,0) -> 4.5055399 | I41: =IFERROR('Historical FS'!I80/'Historical FS'!I49,0) -> 4.1032152 | J41: =IFERROR('Historical FS'!J80/'Historical FS'!J49,0) -> 1.9427642 | ... L41: =IFERROR('Historical FS'!L80/'Historical FS'!L49,0) -> 4.3027835 | N41: =IFERROR(AVERAGE(C41:L41),0) -> 2.0421323 | O41: =IFERROR(MEDIAN(C41:L41),0) -> 2.1753539

Sheet Forecasting
B2: ='Data Sheet'!$B$1&" - "&'Data Sheet'!A17&" Forecasting" -> INFOSYS LTD - Sales Forecasting | G2: ='Data Sheet'!$B$1&" - "&'Data Sheet'!A30&" Forecasting" -> INFOSYS LTD - Net profit Forecasting | L2: ='Data Sheet'!$B$1&" - "&'Historical FS'!B38&" Forecasting" -> INFOSYS LTD - Earning per Share Forecasting | Q2: ='Data Sheet'!$B$1&" - "&'Historical FS'!B18&" Forecasting" -> INFOSYS LTD - EBITDA Forecasting
B3: Year Weight | C3: Year | D3: Sales | E3: Sales Growth | G3: Year Weight | H3: Year | I3: Net Profit | J3: Net Profit Growth | L3: Year Weight | M3: Year | N3: Earning per Share | O3: Earning per Share Growth | Q3: Year Weight | R3: Year | S3: EBITDA | T3: EBITDA Growth
B4: 1 | C4: ='Data Sheet'!$B$16 -> 42460 | D4: {=TRANSPOSE('Data Sheet'!B17:K17)} -> 62441 | G4: 1 | H4: ='Data Sheet'!$B$16 -> 42460 | I4: {=TRANSPOSE('Data Sheet'!B30:K30)} -> 13489 | L4: 1 | M4: ='Data Sheet'!$B$16 -> 42460 | N4: {=TRANSPOSE('Historical FS'!C38:L38)} -> 0.044304176 | Q4: 1 | R4: ='Data Sheet'!$B$16 -> 42460 | S4: {=TRANSPOSE('Historical FS'!C18:L18)} -> 17079
B5: =B4+1 -> 2 | C5: =C4+365 -> 42825 | D5: 68484 | E5: =D5/D4-1 -> 0.09677936 | G5: =G4+1 -> 2 | H5: =H4+365 -> 42825 | I5: 14353 | J5: =I5/I4-1 -> 0.064052191 | L5: =L4+1 -> 2 | M5: =M4+365 -> 42825 | N5: 0.040643192 | O5: =N5/N4-1 -> -0.082632929 | Q5: =Q4+1 -> 2 | R5: =R4+365 -> 42825 | S5: 18604 | T5: =S5/S4-1 -> 0.089290942
B6: =B5+1 -> 3 | C6: =C5+365 -> 43190 | D6: 70522 | E6: =D6/D5-1 -> 0.029758776 | G6: =G5+1 -> 3 | H6: =H5+365 -> 43190 | I6: 16029 | J6: =I6/I5-1 -> 0.11677001 | L6: =L5+1 -> 3 | M6: =M5+365 -> 43190 | N6: 0.034346595 | O6: =N6/N5-1 -> -0.15492377 | Q6: =Q5+1 -> 3 | R6: =R5+365 -> 43190 | S6: 18822 | T6: =S6/S5-1 -> 0.01171791
B7: =B6+1 -> 4 | C7: =C6+365 -> 43555 | D7: 82675 | E7: =D7/D6-1 -> 0.1723292 | G7: =G6+1 -> 4 | H7: =H6+365 -> 43555 | I7: 15404 | J7: =I7/I6-1 -> -0.038991827 | L7: =L6+1 -> 4 | M7: =M6+365 -> 43555 | N7: 0.034873084 | O7: =N7/N6-1 -> 0.015328708 | Q7: =Q6+1 -> 4 | R7: =R6+365 -> 43555 | S7: 20170 | T7: =S7/S6-1 -> 0.071618319
B8: =B7+1 -> 5 | C8: =C7+365 -> 43920 | D8: 90791 | E8: =D8/D7-1 -> 0.098167523 | G8: =G7+1 -> 5 | H8: =H7+365 -> 43920 | I8: 16594 | J8: =I8/I7-1 -> 0.077252662 | L8: =L7+1 -> 5 | M8: =M7+365 -> 43920 | N8: 0.030782018 | O8: =N8/N7-1 -> -0.11731301 | Q8: =Q7+1 -> 5 | R8: =R7+365 -> 43920 | S8: 22267 | T8: =S8/S7-1 -> 0.10396629
B9: =B8+1 -> 6 | C9: =C8+365 -> 44285 | D9: 100472 | E9: =D9/D8-1 -> 0.10662951 | G9: =G8+1 -> 6 | H9: =H8+365 -> 44285 | I9: 19351 | J9: =I9/I8-1 -> 0.16614439 | L9: =L8+1 -> 6 | M9: =M8+365 -> 44285 | N9: 0.024739868 | O9: =N9/N8-1 -> -0.19628831 | Q9: =Q8+1 -> 6 | R9: =R8+365 -> 44285 | S9: 27889 | T9: =S9/S8-1 -> 0.25248125
B10: =B9+1 -> 7 | C10: =C9+365 -> 44650 | D10: 121641 | E10: =D10/D9-1 -> 0.21069552 | G10: =G9+1 -> 7 | H10: =H9+365 -> 44650 | I10: 22110 | J10: =I10/I9-1 -> 0.14257661 | L10: =L9+1 -> 7 | M10: =M9+365 -> 44650 | N10: 0.021191376 | O10: =N10/N9-1 -> -0.14343213 | Q10: =Q9+1 -> 7 | R10: =R9+365 -> 44650 | S10: 31491 | T10: =S10/S9-1 -> 0.12915486
B11: =B10+1 -> 8 | C11: =C10+365 -> 45015 | D11: 146767 | E11: =D11/D10-1 -> 0.20655864 | G11: =G10+1 -> 8 | H11: =H10+365 -> 45015 | I11: 24095 | J11: =I11/I10-1 -> 0.089778381 | L11: =L10+1 -> 8 | M11: =M10+365 -> 45015 | N11: 0.019379642 | O11: =N11/N10-1 -> -0.08549391 | Q11: =Q10+1 -> 8 | R11: =R10+365 -> 45015 | S11: 35130 | T11: =S11/S10-1 -> 0.11555683
B12: =B11+1 -> 9 | C12: =C11+365 -> 45380 | D12: 153670 | E12: =D12/D11-1 -> 0.047033734 | G12: =G11+1 -> 9 | H12: =H11+365 -> 45380 | I12: 26233 | J12: =I12/I11-1 -> 0.088732102 | L12: =L11+1 -> 9 | M12: =M11+365 -> 45380 | N12: 0.019273344 | O12: =N12/N11-1 -> -0.0054850664 | Q12: =Q11+1 -> 9 | R12: =R11+365 -> 45380 | S12: 36425 | T12: =S12/S11-1 -> 0.03686308
B13: =B12+1 -> 10 | C13: =C12+365 -> 45745 | D13: 162990 | E13: =D13/D12-1 -> 0.060649444 | G13: =G12+1 -> 10 | H13: =H12+365 -> 45745 | I13: 26713 | J13: =I13/I12-1 -> 0.018297564 | L13: =L12+1 -> 10 | M13: =M12+365 -> 45745 | N13: 0.017940821 | O13: =N13/N12-1 -> -0.069138124 | Q13: =Q12+1 -> 10 | R13: =R12+365 -> 45745 | S13: 39236 | T13: =S13/S12-1 -> 0.077172272
B14: =B13+1 -> 11 | C14: =C13+365 -> 46110 | D14: =FORECAST(B14,$D$4:$D$13,$B$4:$B$13) -> 173013.53 | E14: =D14/D13-1 -> 0.061497842 | G14: =G13+1 -> 11 | H14: =H13+365 -> 46110 | I14: =FORECAST(G14,$I$4:$I$13,$G$4:$G$13) -> 28283.133 | J14: =I14/I13-1 -> 0.058777873 | L14: =L13+1 -> 11 | M14: =M13+365 -> 46110 | N14: =FORECAST(L14,$N$4:$N$13,$L$4:$L$13) -> 0.011788039 | O14: =N14/N13-1 -> -0.34294874 | Q14: =Q13+1 -> 11 | R14: =R13+365 -> 46110 | S14: =FORECAST(Q14,$S$4:$S$13,$Q$4:$Q$13) -> 41554.133 | T14: =S14/S13-1 -> 0.059081796
B15: =B14+1 -> 12 | C15: =C14+365 -> 46475 | D15: =FORECAST(B15,$D$4:$D$13,$B$4:$B$13) -> 185189.58 | E15: =D15/D14-1 -> 0.070376243 | G15: =G14+1 -> 12 | H15: =H14+365 -> 46475 | I15: =FORECAST(G15,$I$4:$I$13,$G$4:$G$13) -> 29891.503 | J15: =I15/I14-1 -> 0.056866744 | L15: =L14+1 -> 12 | M15: =M14+365 -> 46475 | N15: =FORECAST(L15,$N$4:$N$13,$L$4:$L$13) -> 0.0087045166 | O15: =N15/N14-1 -> -0.2615806 | Q15: =Q14+1 -> 12 | R15: =R14+365 -> 46475 | S15: =FORECAST(Q15,$S$4:$S$13,$Q$4:$Q$13) -> 44252.83 | T15: =S15/S14-1 -> 0.064944128
B16: =B15+1 -> 13 | C16: =C15+365 -> 46840 | D16: =FORECAST(B16,$D$4:$D$13,$B$4:$B$13) -> 197365.62 | E16: =D16/D15-1 -> 0.06574907 | G16: =G15+1 -> 13 | H16: =H15+365 -> 46840 | I16: =FORECAST(G16,$I$4:$I$13,$G$4:$G$13) -> 31499.873 | J16: =I16/I15-1 -> 0.053806919 | L16: =L15+1 -> 13 | M16: =M15+365 -> 46840 | N16: =FORECAST(L16,$N$4:$N$13,$L$4:$L$13) -> 0.0056209943 | O16: =N16/N15-1 -> -0.35424394 | Q16: =Q15+1 -> 13 | R16: =R15+365 -> 46840 | S16: =FORECAST(Q16,$S$4:$S$13,$Q$4:$Q$13) -> 46951.527 | T16: =S16/S15-1 -> 0.060983602
B17: =B16+1 -> 14 | C17: =C16+365 -> 47205 | D17: =FORECAST(B17,$D$4:$D$13,$B$4:$B$13) -> 209541.66 | E17: =D17/D16-1 -> 0.061692824 | G17: =G16+1 -> 14 | H17: =H16+365 -> 47205 | I17: =FORECAST(G17,$I$4:$I$13,$G$4:$G$13) -> 33108.242 | J17: =I17/I16-1 -> 0.051059562 | L17: =L16+1 -> 14 | M17: =M16+365 -> 47205 | N17: =FORECAST(L17,$N$4:$N$13,$L$4:$L$13) -> 0.0025374721 | O17: =N17/N16-1 -> -0.54857239 | Q17: =Q16+1 -> 14 | R17: =R16+365 -> 47205 | S17: =FORECAST(Q17,$S$4:$S$13,$Q$4:$Q$13) -> 49650.224 | T17: =S17/S16-1 -> 0.057478364
B18: =B17+1 -> 15 | C18: =C17+365 -> 47570 | D18: =FORECAST(B18,$D$4:$D$13,$B$4:$B$13) -> 221717.7 | E18: =D18/D17-1 -> 0.058107979 | G18: =G17+1 -> 15 | H18: =H17+365 -> 47570 | I18: =FORECAST(G18,$I$4:$I$13,$G$4:$G$13) -> 34716.612 | J18: =I18/I17-1 -> 0.048579133 | L18: =L17+1 -> 15 | M18: =M17+365 -> 47570 | N18: =FORECAST(L18,$N$4:$N$13,$L$4:$L$13) -> -0.00054605024 | O18: =N18/N17-1 -> -1.2151946 | Q18: =Q17+1 -> 15 | R18: =R17+365 -> 47570 | S18: =FORECAST(Q18,$S$4:$S$13,$Q$4:$Q$13) -> 52348.921 | T18: =S18/S17-1 -> 0.054354175

Sheet Intrinsic Growth
A2: # | B2: Calculating of ROIC | D2: ='[1]Raw FS'!J2 -> 44256 | E2: ='[1]Raw FS'!K2 -> 44621 | F2: ='[1]Raw FS'!L2 -> 44986 | G2: ='[1]Raw FS'!M2 -> 45352 | H2: ='[1]Raw FS'!N2 -> 45717
B4: Current Assets
B5: ='Raw FS'!B34 -> Trade receivables | D5: ='Raw FS'!J34 -> 19294 | E5: ='Raw FS'!K34 -> 22698 | F5: ='Raw FS'!L34 -> 25424 | G5: ='Raw FS'!M34 -> 30193 | H5: ='Raw FS'!N34 -> 31158
B6: ='Raw FS'!B36 -> Loans n Advances | D6: ='Raw FS'!J36 -> 1460 | E6: ='Raw FS'!K36 -> 2491 | F6: ='Raw FS'!L36 -> 3242 | G6: ='Raw FS'!M36 -> 10330 | H6: ='Raw FS'!N36 -> 6717
B7: ='Raw FS'!B37 -> Other asset items | D7: ='Raw FS'!J37 -> 21411 | E7: ='Raw FS'!K37 -> 27528 | F7: ='Raw FS'!L37 -> 34766 | G7: ='Raw FS'!M37 -> 29513 | H7: ='Raw FS'!N37 -> 30149
B8: Total Current Assets | D8: =SUM(D5:D7) -> 42165 | E8: =SUM(E5:E7) -> 52717 | F8: =SUM(F5:F7) -> 63432 | G8: =SUM(G5:G7) -> 70036 | H8: =SUM(H5:H7) -> 68024
B10: Current Liabilities
B11: ='Raw FS'!B10 -> Trade Payables | D11: ='Raw FS'!J10 -> 2645 | E11: ='Raw FS'!K10 -> 4134 | F11: ='Raw FS'!L10 -> 3865 | G11: ='Raw FS'!M10 -> 3956 | H11: ='Raw FS'!N10 -> 4164
B12: ='Raw FS'!B11 -> Advance from Customers | D12: ='Raw FS'!J11 -> 0 | E12: ='Raw FS'!K11 -> 0 | F12: ='Raw FS'!L11 -> 0 | G12: ='Raw FS'!M11 -> 0 | H12: ='Raw FS'!N11 -> 0
B13: ='Raw FS'!B12 -> Other liability items | D13: ='Raw FS'!J12 -> 22759 | E13: ='Raw FS'!K12 -> 31385 | F13: ='Raw FS'!L12 -> 36637 | G13: ='Raw FS'!M12 -> 36584 | H13: ='Raw FS'!N12 -> 39201
B14: Total Current Assets | D14: =SUM(D11:D13) -> 25404 | E14: =SUM(E11:E13) -> 35519 | F14: =SUM(F11:F13) -> 40502 | G14: =SUM(G11:G13) -> 40540 | H14: =SUM(H11:H13) -> 43365
A16: # | B16: Net Working Capital | D16: =D8-D14 -> 16761 | E16: =E8-E14 -> 17198 | F16: =F8-F14 -> 22930 | G16: =G8-G14 -> 29496 | H16: =H8-H14 -> 24659
B18: Non Current Assets
B19: ='Raw FS'!B16 -> Land | D19: ='Raw FS'!J16 -> 2036 | E19: ='Raw FS'!K16 -> 2065 | F19: ='Raw FS'!L16 -> 2054 | G19: ='Raw FS'!M16 -> 2037 | H19: ='Raw FS'!N16 -> 2079
B20: ='Raw FS'!B17 -> Building | D20: ='Raw FS'!J17 -> 16328 | E20: ='Raw FS'!K17 -> 16761 | F20: ='Raw FS'!L17 -> 16903 | G20: ='Raw FS'!M17 -> 16515 | H20: ='Raw FS'!N17 -> 16376
B21: ='Raw FS'!B18 -> Plant Machinery | D21: ='Raw FS'!J18 -> 3296 | E21: ='Raw FS'!K18 -> 3210 | F21: ='Raw FS'!L18 -> 3302 | G21: ='Raw FS'!M18 -> 3428 | H21: ='Raw FS'!N18 -> 3461
B22: ='Raw FS'!B19 -> Equipments | D22: ='Raw FS'!J19 -> 1371 | E22: ='Raw FS'!K19 -> 1427 | F22: ='Raw FS'!L19 -> 1482 | G22: ='Raw FS'!M19 -> 1528 | H22: ='Raw FS'!N19 -> 1628
B23: ='Raw FS'!B20 -> Computers | D23: ='Raw FS'!J20 -> 8650 | E23: ='Raw FS'!K20 -> 9936 | F23: ='Raw FS'!L20 -> 11898 | G23: ='Raw FS'!M20 -> 12353 | H23: ='Raw FS'!N20 -> 12925
B24: ='Raw FS'!B21 -> Furniture n fittings | D24: ='Raw FS'!J21 -> 2149 | E24: ='Raw FS'!K21 -> 2279 | F24: ='Raw FS'!L21 -> 2303 | G24: ='Raw FS'!M21 -> 2326 | H24: ='Raw FS'!N21 -> 2340
B25: ='Raw FS'!B22 -> Vehicles | D25: ='Raw FS'!J22 -> 74 | E25: ='Raw FS'!K22 -> 71 | F25: ='Raw FS'!L22 -> 60 | G25: ='Raw FS'!M22 -> 62 | H25: ='Raw FS'!N22 -> 72
B26: ='Raw FS'!B23 -> Intangible Assets | D26: ='Raw FS'!J23 -> 6372 | E26: ='Raw FS'!K23 -> 6495 | F26: ='Raw FS'!L23 -> 7594 | G26: ='Raw FS'!M23 -> 7653 | H26: ='Raw FS'!N23 -> 10626
B27: ='Raw FS'!B24 -> Other fixed assets | D27: ='Raw FS'!J24 -> 2730 | E27: ='Raw FS'!K24 -> 2766 | F27: ='Raw FS'!L24 -> 3281 | G27: ='Raw FS'!M24 -> 3294 | H27: ='Raw FS'!N24 -> 5184
B28: ='Raw FS'!B25 -> Gross Block | D28: =SUM(D19:D27) -> 43006 | E28: =SUM(E19:E27) -> 45010 | F28: =SUM(F19:F27) -> 48877 | G28: =SUM(G19:G27) -> 49196 | H28: =SUM(H19:H27) -> 54691
B30: ='Raw FS'!B26 -> Accumulated Depreciation | D30: =-'Raw FS'!J26 -> -17501 | E30: =-'Raw FS'!K26 -> -19210 | F30: =-'Raw FS'!L26 -> -19652 | G30: =-'Raw FS'!M26 -> -21574 | H30: =-'Raw FS'!N26 -> -23730
A31: # | B31: Net Non Current Assets | D31: =SUM(D28:D30) -> 25505 | E31: =SUM(E28:E30) -> 25800 | F31: =SUM(F28:F30) -> 29225 | G31: =SUM(G28:G30) -> 27622 | H31: =SUM(H28:H30) -> 30961
A33: # | B33: Invested Capital | D33: =D31+D16 -> 42266 | E33: =E31+E16 -> 42998 | F33: =F31+F16 -> 52155 | G33: =G31+G16 -> 57118 | H33: =H31+H16 -> 55620
B34: EBIT | D34: =('Historical FS'!H27+'Historical FS'!H21) -> 24622 | E34: =('Historical FS'!I27+'Historical FS'!I21) -> 28015 | F34: =('Historical FS'!J27+'Historical FS'!J21) -> 30905 | G34: =('Historical FS'!K27+'Historical FS'!K21) -> 31747 | H34: =('Historical FS'!L27+'Historical FS'!L21) -> 34424
B36: ROIC | D36: =D34/D33 -> 0.58254862 | E36: =E34/E33 -> 0.65154193 | F36: =F34/F33 -> 0.59256064 | G36: =G34/G33 -> 0.55581428 | H36: =H34/H33 -> 0.61891406
B38: Calculating of Renivestement Rate | D38: =D2 -> 44256 | E38: =E2 -> 44621 | F38: =F2 -> 44986 | G38: =G2 -> 45352 | H38: =H2 -> 45717
B40: Net Capex | D40: =-SUM('Raw FS'!J51:J52) -> 2107 | E40: =-SUM('Raw FS'!K51:K52) -> 2161 | F40: =-SUM('Raw FS'!L51:L52) -> 2579 | G40: =-SUM('Raw FS'!M51:M52) -> 2201 | H40: =-SUM('Raw FS'!N51:N52) -> 2237
B41: Change in Working Capital | E41: =E16-D16 -> 437 | F41: =F16-E16 -> 5732 | G41: =G16-F16 -> 6566 | H41: =H16-G16 -> -4837
B43: EBIT | D43: =D34 -> 24622 | E43: =E34 -> 28015 | F43: =F34 -> 30905 | G43: =G34 -> 31747 | H43: =H34 -> 34424
B44: Marginal Tax Rate | D44: 0.27 | E44: 0.27 | F44: 0.27 | G44: 0.27 | H44: 0.27
B45: EBIT(1-T) | D45: =D43*(1-D44) -> 17974.06 | E45: =E43*(1-E44) -> 20450.95 | F45: =F43*(1-F44) -> 22560.65 | G45: =G43*(1-G44) -> 23175.31 | H45: =H43*(1-H44) -> 25129.52
B47: Reinvestment | E47: =SUM(E40:E41) -> 2598 | F47: =SUM(F40:F41) -> 8311 | G47: =SUM(G40:G41) -> 8767 | H47: =SUM(H40:H41) -> -2600
B49: Reinvestment Rate | E49: =E47/E45 -> 0.12703566 | F49: =F47/F45 -> 0.36838478 | G49: =G47/G45 -> 0.37829052 | H49: =H47/H45 -> -0.10346397
G51: 4 Years Average | H51: =AVERAGE(E49:H49) -> 0.19256175
G52: 4 Years Median | H52: =MEDIAN(E49:H49) -> 0.24771022
B54: Calculating of Growth Rate | D54: =D2 -> 44256 | E54: =E2 -> 44621 | F54: =F2 -> 44986 | G54: =G2 -> 45352 | H54: =H2 -> 45717
B56: Reinvestment Rate | E56: =E49 -> 0.12703566 | F56: =F49 -> 0.36838478 | G56: =G49 -> 0.37829052 | H56: =H49 -> -0.10346397
...

Sheet DCF
B2: Calculation of PV of FCFF | D2: ='Intrinsic Growth'!H2 -> 45717 | E2: =D2+366 -> 46083 | F2: =E2+366 -> 46449 | G2: =F2+366 -> 46815 | H2: =G2+366 -> 47181 | I2: =H2+366 -> 47547
B4: EBIT | D4: ='Data Sheet'!K33-'Data Sheet'!K26 -> 37987 | E4: =D4*(1+$C$14) -> 41063.947 | F4: =E4*(1+$C$14) -> 44390.127 | G4: =F4*(1+$C$14) -> 47985.727 | H4: =G4*(1+$C$14) -> 51872.571 | I4: =H4*(1+$C$14) -> 56074.249
B5: Tax Rate | D5: 0.29 | E5: =D5 -> 0.29 | F5: =E5 -> 0.29 | G5: =F5 -> 0.29 | H5: =G5 -> 0.29 | I5: =H5 -> 0.29
B6: EBIT(1-T) | D6: =D4*(1-D5) -> 26970.77 | E6: =E4*(1-E5) -> 29155.402 | F6: =F4*(1-F5) -> 31516.99 | G6: =G4*(1-G5) -> 34069.866 | H6: =H4*(1-H5) -> 36829.525 | I6: =I4*(1-I5) -> 39812.717
B7: less: Reinvestment Rate | D7: ='Intrinsic Growth'!H52 -> 0.24771022 | E7: =D7+(($I$7-$D$7)/4) -> 0.30978266 | F7: =E7+(($I$7-$D$7)/4) -> 0.37185511 | G7: =F7+(($I$7-$D$7)/4) -> 0.43392755 | H7: =G7+(($I$7-$D$7)/4) -> 0.496 | I7: 0.496
B8: Free Cash Flow to Firm (FCFF) | D8: =D6*(1-D7) -> 20289.835 | E8: =E6*(1-E7) -> 20123.564 | F8: =F6*(1-F7) -> 19797.236 | G8: =G6*(1-G7) -> 19286.012 | H8: =H6*(1-H7) -> 18562.081 | I8: =I6*(1-I7) -> 20065.609
B9: Mid Year Convention | E9: 0.5 | F9: =E9+1 -> 1.5 | G9: =F9+1 -> 2.5 | H9: =G9+1 -> 3.5 | I9: =H9+1 -> 4.5
B10: Discount Factor | E10: =1/(1+$C$16)^E9 -> 0.96247977 | F10: =1/(1+$C$16)^F9 -> 0.8916098 | G10: =1/(1+$C$16)^G9 -> 0.82595817 | H10: =1/(1+$C$16)^H9 -> 0.76514065 | I10: =1/(1+$C$16)^I9 -> 0.70880129
B12: PV of FCFF | E12: =E8*E10 -> 19368.523 | F12: =F8*F10 -> 17651.41 | G12: =G8*G10 -> 15929.44 | H12: =H8*H10 -> 14202.603 | I12: =I8*I10 -> 14222.53 | N12: .
B14: Expected Growth | C14: 0.081
B15: Terminal Growth | C15: 0.068
B16: WACC | C16: =WACC!K37 -> 0.079485413
B18: Calculation of Terminal Value | F18: Sensitivity Analysis
F19: =C37 -> 3457.1004 | G19: 0.03 | H19: 0.06 | I19: 0.0795 | J19: 0.09
B20: FCFF (n+1) | C20: =I8*(1+C14) -> 21690.924 | F20: 0.04 | G20: -3465.8494 | H20: 2085.3311 | I20: 1171.8457 | J20: 975.095
B21: WACC | C21: =C16 -> 0.079485413 | F21: 0.05 | G21: -1615.4559 | H21: 3935.7246 | I21: 1489.4417 | J21: 1160.1344
B22: Terminal Growth Rate | C22: =C15 -> 0.068 | F22: 0.068 | G22: -738.95373 | H22: -4391.0462 | I22: 3453.0133 | J22: 1917.1135
F23: 0.07 | G23: -690.25917 | H23: -3465.8494 | I23: 4130.5029 | J23: 2085.3311
B24: Terminal Value | C24: =C20/(C21-C22) -> 1888562.8 | F24: 0.08 | G24: -505.21981 | H24: -1615.4559 | I24: -73780.803 | J24: 3935.7246
B26: Calculation of Equity Value per Share
B28: PV of FCFF | C28: =SUM(E12:I12) -> 81374.505
B29: PV of Terminal Value | C29: =C24*I10 -> 1338615.7
B30: Value of Operating Assets | C30: =SUM(C28:C29) -> 1419990.2
B32: Add : Cash | C32: ='Data Sheet'!K69 -> 24455
B33: Less: Debt | C33: =SUM('Raw FS'!N7) -> 8227
B34: Value of Equity | C34: =C30+C32-C33 -> 1436218.2
B35: No of Share | C35: ='Data Sheet'!B6 -> 415.44013
B37: Equity Value per Share | C37: =C34/C35 -> 3457.1004
B39: Share Price | C39: 1639
B40: Discount/ Premium | C40: =C39/C37-1 -> -0.52590326

Sheet Comps Val
B2: Amount in Crores
B3: Comparable Company Valuation
D5: Market Data | J5: Financials | N5: Valuation
B6: Company | C6: Ticker | D6: Share Price | E6: Share Outstanding | F6: Equity Value | G6: Net Debt | H6: Enterprise Value | J6: Revenue | K6: EBITDA | L6: Net Income | N6: EV/ Revenue | O6: EV/ EBITDA | P6: P/E
B8: ='RV Data'!C4 -> Infosys | C8: INFY | D8: ='RV Data'!D4 -> 1638.7 | E8: ='RV Data'!E4 -> 405.47 | F8: =D8*E8 -> 664443.69 | G8: ='RV Data'!I4 -> -15700 | H8: =F8+G8 -> 648743.69 | J8: ='RV Data'!K4 -> 169458 | K8: ='RV Data'!L4 -> 44059.08 | L8: ='RV Data'!M4 -> 28159 | N8: =$H8/J8 -> 3.828345 | O8: =$H8/K8 -> 14.724404 | P8: =F8/L8 -> 23.596139
B9: ='RV Data'!C3 -> TCS | C9: TCS.NS | D9: ='RV Data'!D3 -> 3282 | E9: ='RV Data'!E3 -> 361.81 | F9: =D9*E9 -> 1187460.4 | G9: ='RV Data'!I3 -> -4531 | H9: =F9+G9 -> 1182929.4 | J9: ='RV Data'!K3 -> 257688 | K9: ='RV Data'!L3 -> 74729.52 | L9: ='RV Data'!M3 -> 49687 | N9: =$H9/J9 -> 4.5905491 | O9: =$H9/K9 -> 15.82948 | P9: =F9/L9 -> 23.898815
B10: ='RV Data'!C5 -> HCL Technologies | C10: HCLTECH.NS | D10: ='RV Data'!D5 -> 1642.4 | E10: ='RV Data'!E5 -> 271.37 | F10: =D10*E10 -> 445698.09 | G10: ='RV Data'!I5 -> -14509 | H10: =F10+G10 -> 431189.09 | J10: ='RV Data'!K5 -> 122427 | K10: ='RV Data'!L5 -> 28158.21 | L10: ='RV Data'!M5 -> 16983 | N10: =$H10/J10 -> 3.5220098 | O10: =$H10/K10 -> 15.313086 | P10: =F10/L10 -> 26.243778
B11: ='RV Data'!C6 -> Wipro | C11: WIT | D11: ='RV Data'!D6 -> 264.45 | E11: ='RV Data'!E6 -> 1048.67 | F11: =D11*E11 -> 277320.78 | G11: ='RV Data'!I6 -> 3966.3 | H11: =F11+G11 -> 281287.08 | J11: ='RV Data'!K6 -> 89654.9 | K11: ='RV Data'!L6 -> 22413.725 | L11: ='RV Data'!M6 -> 13553.7 | N11: =$H11/J11 -> 3.1374424 | O11: =$H11/K11 -> 12.549769 | P11: =F11/L11 -> 20.460891
B12: ='RV Data'!C7 -> LTIMindtree | C12: LTIM.NS | D12: ='RV Data'!D7 -> 6197.5 | E12: ='RV Data'!E7 -> 29.65 | F12: =D12*E12 -> 183755.88 | G12: ='RV Data'!I7 -> -1205.6 | H12: =F12+G12 -> 182550.27 | J12: ='RV Data'!K7 -> 39667.5 | K12: ='RV Data'!L7 -> 7933.5 | L12: ='RV Data'!M7 -> 4851.1 | N12: =$H12/J12 -> 4.6020111 | O12: =$H12/K12 -> 23.010055 | P12: =F12/L12 -> 37.879218
B13: ='RV Data'!C8 -> Tech Mahindra | C13: TECHM.BO | D13: ='RV Data'!D8 -> 1612.5 | E13: ='RV Data'!E8 -> 97.97 | F13: =D13*E13 -> 157976.62 | G13: ='RV Data'!I8 -> -2587.8 | H13: =F13+G13 -> 155388.83 | J13: ='RV Data'!K8 -> 54015.7 | K13: ='RV Data'!L8 -> 8102.355 | L13: ='RV Data'!M8 -> 4461.2 | N13: =$H13/J13 -> 2.8767344 | O13: =$H13/K13 -> 19.17823 | P13: =F13/L13 -> 35.41124
B14: ='RV Data'!C9 -> Persistent Systems | C14: PERSISTENT.NS | D14: ='RV Data'!D9 -> 6358 | E14: ='RV Data'!E9 -> 15.78 | F14: =D14*E14 -> 100329.24 | G14: ='RV Data'!I9 -> -621.53 | H14: =F14+G14 -> 99707.71 | J14: ='RV Data'!K9 -> 13218.7 | K14: ='RV Data'!L9 -> 2643.74 | L14: ='RV Data'!M9 -> 1665.16 | N14: =$H14/J14 -> 7.5429286 | O14: =$H14/K14 -> 37.714643 | P14: =F14/L14 -> 60.252012
B15: ='RV Data'!C10 -> Oracle Fin.Serv. | C15: OFSS.BO | D15: ='RV Data'!D10 -> 7823.5 | E15: ='RV Data'!E10 -> 8.7 | F15: =D15*E15 -> 68064.45 | G15: ='RV Data'!I10 -> -5917.4 | H15: =F15+G15 -> 62147.05 | J15: ='RV Data'!K10 -> 7072.5 | K15: ='RV Data'!L10 -> 3394.8 | L15: ='RV Data'!M10 -> 2373.2 | N15: =$H15/J15 -> 8.7871403 | O15: =$H15/K15 -> 18.306542 | P15: =F15/L15 -> 28.680453
B16: ='RV Data'!C11 -> Coforge | C16: COFORGE.NS | D16: ='RV Data'!D11 -> 1845.4 | E16: ='RV Data'!E11 -> 33.5 | F16: =D16*E16 -> 61820.9 | G16: ='RV Data'!I11 -> 88.3 | H16: =F16+G16 -> 61909.2 | J16: ='RV Data'!K11 -> 14342.3 | K16: ='RV Data'!L11 -> 2438.191 | L16: ='RV Data'!M11 -> 1345 | N16: =$H16/J16 -> 4.3165462 | O16: =$H16/K16 -> 25.391448 | P16: =F16/L16 -> 45.963494
B17: ='RV Data'!C12 -> Mphasis | C17: MPHASIS.NS | D17: ='RV Data'!D12 -> 2890.2 | E17: ='RV Data'!E12 -> 19.06 | F17: =D17*E17 -> 55087.212 | G17: ='RV Data'!I12 -> 366.45 | H17: =F17+G17 -> 55453.662 | J17: ='RV Data'!K12 -> 14905.78 | K17: ='RV Data'!L12 -> 3130.2138 | L17: ='RV Data'!M12 -> 1785.07 | N17: =$H17/J17 -> 3.7202791 | O17: =$H17/K17 -> 17.715615 | P17: =F17/L17 -> 30.859973
B19: High | N19: =MAX(N8:N17) -> 8.7871403 | O19: =MAX(O8:O17) -> 37.714643 | P19: =MAX(P8:P17) -> 60.252012
B20: 75th Percentile | N20: =QUARTILE(N8:N17,3) -> 4.5991456 | O20: =QUARTILE(O8:O17,3) -> 22.052099 | P20: =QUARTILE(P8:P17,3) -> 37.262224
B21: Average | N21: =AVERAGE(N8:N17) -> 4.6923986 | O21: =AVERAGE(O8:O17) -> 19.973327 | P21: =AVERAGE(P8:P17) -> 33.324601
B22: Median | N22: =MEDIAN(N8:N17) -> 4.0724456 | O22: =MEDIAN(O8:O17) -> 18.011079 | P22: =MEDIAN(P8:P17) -> 29.770213
B23: 25th percentile | N23: =QUARTILE(N8:N17,1) -> 3.5715771 | O23: =QUARTILE(O8:O17,1) -> 15.442184 | P23: =QUARTILE(P8:P17,1) -> 24.485056
B24: Low | N24: =MIN(N8:N17) -> 2.8767344 | O24: =MIN(O8:O17) -> 12.549769 | P24: =MIN(P8:P17) -> 20.460891
B26: Infosys Comparable Valuation | N26: EV/ Revenue | O26: EV/ EBITDA | P26: P/E
B28: Implied Enterprize Value | N28: =N$22*J8 -> 690108.48 | O28: =O$22*K8 -> 793551.55 | P28: =P30+P29 -> 822599.42
B29: Net Debt | N29: =$G$8 -> -15700 | O29: =$G$8 -> -15700 | P29: =$G$8 -> -15700
B30: Implied Market Value | N30: =N28-N29 -> 705808.48 | O30: =O28-O29 -> 809251.55 | P30: =P22*L8 -> 838299.42
B31: Share Outstanding | N31: =$E$8 -> 405.47 | O31: =$E$8 -> 405.47 | P31: =$E$8 -> 405.47
B33: Implied value Per Share | N33: =N30/N31 -> 1740.7169 | O33: =O30/O31 -> 1995.8358 | P33: =P30/P31 -> 2067.4758
N35: =IF(N33>$D$8,"Undervalued", "Overvalued") -> Undervalued | O35: =IF(O33>$D$8,"Undervalued", "Overvalued") -> Undervalued | P35: =IF(P33>$D$8,"Undervalued", "Overvalued") -> Undervalued

Sheet Football Field
L3: Football Field Analysis - Data
N4: OpenLow | O4: Low | P4: OpenHigh | Q4: High
L5: Comps | N5: 1740.7169 | O5: 1740.7169 | P5: 2067.4758 | Q5: 2067.4758
L6: DCF Bear | N6: 975.095 | O6: 975.095 | P6: 3935.7246 | Q6: 3935.7246
L7: DCF Base | N7: 1171.85 | O7: 1171.85 | P7: -73780.803 | Q7: -73780.803
L8: DCF Bull | N8: -3465.8494 | O8: -3465.8494 | P8: -505.21981 | Q8: -505.21981
L9: 52w H/L | N9: 1307 | O9: 1307 | P9: 1982.8 | Q9: 1982.8

Sheet RV Data
B2: S.No. | C2: Name | D2: CMP Rs. | E2: No. Eq. Shares Cr. | F2: Market Capitalization | G2: Debt Rs.Cr. | H2: Cash End Rs.Cr. | I2: Net Debt | J2: EV | K2: Sales Rs.Cr. | L2: EBITDA | M2: NP 12M Rs.Cr.
B3: 1 | C3: TCS | D3: 3282 | E3: 361.81 | F3: =D3*E3 -> 1187460.4 | G3: 10932 | H3: 15463 | I3: =G3-H3 -> -4531 | J3: =F3+G3-H3 -> 1182929.4 | K3: 257688 | L3: 74729.52 | M3: 49687
B4: 2 | C4: Infosys | D4: 1638.7 | E4: 405.47 | F4: =D4*E4 -> 664443.69 | G4: 8755 | H4: 24455 | I4: =G4-H4 -> -15700 | J4: =F4+G4-H4 -> 648743.69 | K4: 169458 | L4: 44059.08 | M4: 28159
B5: 3 | C5: HCL Technologies | D5: 1642.4 | E5: 271.37 | F5: =D5*E5 -> 445698.09 | G5: 6780 | H5: 21289 | I5: =G5-H5 -> -14509 | J5: =F5+G5-H5 -> 431189.09 | K5: 122427 | L5: 28158.21 | M5: 16983
B6: 4 | C6: Wipro | D6: 264.45 | E6: 1048.67 | F6: =D6*E6 -> 277320.78 | G6: 16163.7 | H6: 12197.4 | I6: =G6-H6 -> 3966.3 | J6: =F6+G6-H6 -> 281287.08 | K6: 89654.9 | L6: 22413.725 | M6: 13553.7
B7: 5 | C7: LTIMindtree | D7: 6197.5 | E7: 29.65 | F7: =D7*E7 -> 183755.88 | G7: 2382.6 | H7: 3588.2 | I7: =G7-H7 -> -1205.6 | J7: =F7+G7-H7 -> 182550.27 | K7: 39667.5 | L7: 7933.5 | M7: 4851.1
B8: 6 | C8: Tech Mahindra | D8: 1612.5 | E8: 97.97 | F8: =D8*E8 -> 157976.62 | G8: 1954.4 | H8: 4542.2 | I8: =G8-H8 -> -2587.8 | J8: =F8+G8-H8 -> 155388.82 | K8: 54015.7 | L8: 8102.355 | M8: 4461.2
B9: 7 | C9: Persistent Systems | D9: 6358 | E9: 15.78 | F9: =D9*E9 -> 100329.24 | G9: 403.94 | H9: 1025.47 | I9: =G9-H9 -> -621.53 | J9: =F9+G9-H9 -> 99707.71 | K9: 13218.7 | L9: 2643.74 | M9: 1665.16
B10: 8 | C10: Oracle Fin.Serv. | D10: 7823.5 | E10: 8.7 | F10: =D10*E10 -> 68064.45 | G10: 34 | H10: 5951.4 | I10: =G10-H10 -> -5917.4 | J10: =F10+G10-H10 -> 62147.05 | K10: 7072.5 | L10: 3394.8 | M10: 2373.2
B11: 9 | C11: Coforge | D11: 1845.4 | E11: 33.5 | F11: =D11*E11 -> 61820.9 | G11: 971.5 | H11: 883.2 | I11: =G11-H11 -> 88.3 | J11: =F11+G11-H11 -> 61909.2 | K11: 14342.3 | L11: 2438.191 | M11: 1345
B12: 10 | C12: Mphasis | D12: 2890.2 | E12: 19.06 | F12: =D12*E12 -> 55087.212 | G12: 1979.03 | H12: 1612.58 | I12: =G12-H12 -> 366.45 | J12: =F12+G12-H12 -> 55453.662 | K12: 14905.78 | L12: 3130.2138 | M12: 1785.07

Sheet Historical FS
B2: ="Hiscorical financial Statement - "&'Data Sheet'!B1 -> Hiscorical financial Statement - INFOSYS LTD
B3: Years | C3: ='Data Sheet'!B16 -> 42460 | D3: ='Data Sheet'!C16 -> 42825 | E3: ='Data Sheet'!D16 -> 43190 | F3: ='Data Sheet'!E16 -> 43555 | G3: ='Data Sheet'!F16 -> 43921 | H3: ='Data Sheet'!G16 -> 44286 | I3: ='Data Sheet'!H16 -> 44651 | J3: ='Data Sheet'!I16 -> 45016 | ... L3: ='Data Sheet'!K16 -> 45747 | M3: LTM
A5: # | B5: Income Statement
B6: Sales | C6: =IFERROR('Data Sheet'!B17,0) -> 62441 | D6: =IFERROR('Data Sheet'!C17,0) -> 68484 | E6: =IFERROR('Data Sheet'!D17,0) -> 70522 | F6: =IFERROR('Data Sheet'!E17,0) -> 82675 | G6: =IFERROR('Data Sheet'!F17,0) -> 90791 | H6: =IFERROR('Data Sheet'!G17,0) -> 100472 | I6: =IFERROR('Data Sheet'!H17,0) -> 121641 | J6: =IFERROR('Data Sheet'!I17,0) -> 146767 | ... L6: =IFERROR('Data Sheet'!K17,0) -> 162990 | M6: =IFERROR(SUM('Data Sheet'!H42:K42),0) -> 169458
B7: Sales Growth | C7: 0 | D7: =D6/C6-1 -> 0.09677936 | E7: =E6/D6-1 -> 0.029758776 | F7: =F6/E6-1 -> 0.1723292 | G7: =G6/F6-1 -> 0.098167523 | H7: =H6/G6-1 -> 0.10662951 | I7: =I6/H6-1 -> 0.21069552 | J7: =J6/I6-1 -> 0.20655864 | K7: =K6/J6-1 -> 0.047033734 | ... M7: =M6/L6-1 -> 0.039683416
B9: COGS | C9: =IFERROR(SUM('Data Sheet'!B18,'Data Sheet'!B20:B22)-1*'Data Sheet'!B19,0) -> 40492 | D9: =IFERROR(SUM('Data Sheet'!C18,'Data Sheet'!C20:C22)-1*'Data Sheet'!C19,0) -> 44609 | E9: =IFERROR(SUM('Data Sheet'!D18,'Data Sheet'!D20:D22)-1*'Data Sheet'!D19,0) -> 46395 | F9: =IFERROR(SUM('Data Sheet'!E18,'Data Sheet'!E20:E22)-1*'Data Sheet'!E19,0) -> 55446 | G9: =IFERROR(SUM('Data Sheet'!F18,'Data Sheet'!F20:F22)-1*'Data Sheet'!F19,0) -> 62210 | H9: =IFERROR(SUM('Data Sheet'!G18,'Data Sheet'!G20:G22)-1*'Data Sheet'!G19,0) -> 68490 | I9: =IFERROR(SUM('Data Sheet'!H18,'Data Sheet'!H20:H22)-1*'Data Sheet'!H19,0) -> 84819 | J9: =IFERROR(SUM('Data Sheet'!I18,'Data Sheet'!I20:I22)-1*'Data Sheet'!I19,0) -> 104880 | ... L9: =IFERROR(SUM('Data Sheet'!K18,'Data Sheet'!K20:K22)-1*'Data Sheet'!K19,0) -> 116585 | M9: =IFERROR(SUM('Data Sheet'!H43:K43),0) -> 128991
B10: COGS % Sales | C10: =C9/C6 -> 0.64848417 | D10: =D9/D6 -> 0.65137842 | E10: =E9/E6 -> 0.65787981 | F10: =F9/F6 -> 0.67065014 | G10: =G9/G6 -> 0.68520007 | H10: =H9/H6 -> 0.68168246 | I10: =I9/I6 -> 0.69728957 | J10: =J9/J6 -> 0.71460206 | ... M10: =M9/M6 -> 0.76119746
B12: Gross Profit | C12: =C6-C9 -> 21949 | D12: =D6-D9 -> 23875 | E12: =E6-E9 -> 24127 | F12: =F6-F9 -> 27229 | G12: =G6-G9 -> 28581 | H12: =H6-H9 -> 31982 | I12: =I6-I9 -> 36822 | J12: =J6-J9 -> 41887 | ... M12: =M6-M9 -> 40467
B13: Gross Margin | C13: =C12/C6 -> 0.35151583 | D13: =D12/D6 -> 0.34862158 | E13: =E12/E6 -> 0.34212019 | F13: =F12/F6 -> 0.32934986 | G13: =G12/G6 -> 0.31479993 | H13: =H12/H6 -> 0.31831754 | I13: =I12/I6 -> 0.30271043 | J13: =J12/J6 -> 0.28539794 | ... M13: =M12/M6 -> 0.23880254
B15: Selling and General Expenses | C15: =IFERROR(SUM('Data Sheet'!B23:B24),0) -> 4870 | D15: =IFERROR(SUM('Data Sheet'!C23:C24),0) -> 5271 | E15: =IFERROR(SUM('Data Sheet'!D23:D24),0) -> 5305 | F15: =IFERROR(SUM('Data Sheet'!E23:E24),0) -> 7059 | G15: =IFERROR(SUM('Data Sheet'!F23:F24),0) -> 6314 | H15: =IFERROR(SUM('Data Sheet'!G23:G24),0) -> 4093 | I15: =IFERROR(SUM('Data Sheet'!H23:H24),0) -> 5331 | J15: =IFERROR(SUM('Data Sheet'!I23:I24),0) -> 6757 | ... L15: =IFERROR(SUM('Data Sheet'!K23:K24),0) -> 7169 | M15: 0
B16: S&G Exp % Sales | C16: =C15/C6 -> 0.077993626 | D16: =D15/D6 -> 0.076966883 | E16: =E15/E6 -> 0.075224753 | F16: =F15/F6 -> 0.085382522 | G16: =G15/G6 -> 0.069544338 | H16: =H15/H6 -> 0.040737718 | I16: =I15/I6 -> 0.043825684 | J16: =J15/J6 -> 0.04603896 | ... M16: =M15/M6 -> 0
B18: EBITDA | C18: =C12-C15 -> 17079 | D18: =D12-D15 -> 18604 | E18: =E12-E15 -> 18822 | F18: =F12-F15 -> 20170 | G18: =G12-G15 -> 22267 | H18: =H12-H15 -> 27889 | I18: =I12-I15 -> 31491 | J18: =J12-J15 -> 35130 | ... L18: =L12-L15 -> 39236 | M18: 0
B19: EBITDA Margin | C19: =C18/C6 -> 0.2735222 | D19: =D18/D6 -> 0.27165469 | E19: =E18/E6 -> 0.26689544 | F19: =F18/F6 -> 0.24396734 | G19: =G18/G6 -> 0.24525559 | H19: =H18/H6 -> 0.27757982 | I19: =I18/I6 -> 0.25888475 | J19: =J18/J6 -> 0.23935898 | ... M19: =M18/M6 -> 0
B21: Interest | C21: =IFERROR('Data Sheet'!B27,0) -> 0 | D21: =IFERROR('Data Sheet'!C27,0) -> 0 | E21: =IFERROR('Data Sheet'!D27,0) -> 0 | F21: =IFERROR('Data Sheet'!E27,0) -> 0 | G21: =IFERROR('Data Sheet'!F27,0) -> 170 | H21: =IFERROR('Data Sheet'!G27,0) -> 195 | I21: =IFERROR('Data Sheet'!H27,0) -> 200 | J21: =IFERROR('Data Sheet'!I27,0) -> 284 | ... L21: =IFERROR('Data Sheet'!K27,0) -> 416 | M21: =IFERROR(SUM('Data Sheet'!H46:K46),0) -> 414
B22: Interest % Sales | C22: =C21/C6 -> 0 | D22: =D21/D6 -> 0 | E22: =E21/E6 -> 0 | F22: =F21/F6 -> 0 | G22: =G21/G6 -> 0.0018724323 | H22: =H21/H6 -> 0.0019408392 | I22: =I21/I6 -> 0.0016441825 | J22: =J21/J6 -> 0.0019350399 | ... M22: =M21/M6 -> 0.0024430832
B24: Depreciation | C24: =IFERROR('Data Sheet'!B26,0) -> 1459 | D24: =IFERROR('Data Sheet'!C26,0) -> 1703 | E24: =IFERROR('Data Sheet'!D26,0) -> 1863 | F24: =IFERROR('Data Sheet'!E26,0) -> 2011 | G24: =IFERROR('Data Sheet'!F26,0) -> 2893 | H24: =IFERROR('Data Sheet'!G26,0) -> 3267 | I24: =IFERROR('Data Sheet'!H26,0) -> 3476 | J24: =IFERROR('Data Sheet'!I26,0) -> 4225 | ... L24: =IFERROR('Data Sheet'!K26,0) -> 4812 | M24: =IFERROR(SUM('Data Sheet'!H45:K45),0) -> 4824
B25: Depreciation % Sales | C25: =C24/C6 -> 0.023366058 | D25: =D24/D6 -> 0.024867122 | E25: =E24/E6 -> 0.026417288 | F25: =F24/F6 -> 0.024324161 | G25: =G24/G6 -> 0.031864392 | H25: =H24/H6 -> 0.032516522 | I25: =I24/I6 -> 0.028575891 | J25: =J24/J6 -> 0.028787125 | ... M25: =M24/M6 -> 0.028467231
B27: Earning Before Tax | C27: =IFERROR(C18-SUM(C21,C24),0) -> 15620 | D27: =IFERROR(D18-SUM(D21,D24),0) -> 16901 | E27: =IFERROR(E18-SUM(E21,E24),0) -> 16959 | F27: =IFERROR(F18-SUM(F21,F24),0) -> 18159 | G27: =IFERROR(G18-SUM(G21,G24),0) -> 19204 | H27: =IFERROR(H18-SUM(H21,H24),0) -> 24427 | I27: =IFERROR(I18-SUM(I21,I24),0) -> 27815 | J27: =IFERROR(J18-SUM(J21,J24),0) -> 30621 | ... M27: =IFERROR(M18-SUM(M21,M24),0) -> -5238
B28: EBT % Sales | C28: =C27/C6 -> 0.25015615 | D28: =D27/D6 -> 0.24678757 | E28: =E27/E6 -> 0.24047815 | F28: =F27/F6 -> 0.21964318 | G28: =G27/G6 -> 0.21151876 | H28: =H27/H6 -> 0.24312246 | I28: =I27/I6 -> 0.22866468 | J28: =J27/J6 -> 0.20863682 | ... M28: =M27/M6 -> -0.030910314
B30: Tax | C30: =IFERROR('Data Sheet'!B29,0) -> 5251 | D30: =IFERROR('Data Sheet'!C29,0) -> 5598 | E30: =IFERROR('Data Sheet'!D29,0) -> 4241 | F30: =IFERROR('Data Sheet'!E29,0) -> 5631 | G30: =IFERROR('Data Sheet'!F29,0) -> 5368 | H30: =IFERROR('Data Sheet'!G29,0) -> 7205 | I30: =IFERROR('Data Sheet'!H29,0) -> 7964 | J30: =IFERROR('Data Sheet'!I29,0) -> 9214 | ... L30: =IFERROR('Data Sheet'!K29,0) -> 10858 | M30: =IFERROR(SUM('Data Sheet'!H48:K48),0) -> 11143
B31: Effective Tax Rate | C31: =C30/C27 -> 0.33617157 | D31: =D30/D27 -> 0.331223 | E31: =E30/E27 -> 0.25007371 | F31: =F30/F27 -> 0.31009417 | G31: =G30/G27 -> 0.2795251 | H31: =H30/H27 -> 0.29496049 | I31: =I30/I27 -> 0.28632033 | J31: =J30/J27 -> 0.30090461 | ... M31: =M30/M27 -> -2.1273387
B33: Net Profit | C33: =IFERROR(C27-C30,0) -> 10369 | D33: =IFERROR(D27-D30,0) -> 11303 | E33: =IFERROR(E27-E30,0) -> 12718 | F33: =IFERROR(F27-F30,0) -> 12528 | G33: =IFERROR(G27-G30,0) -> 13836 | H33: =IFERROR(H27-H30,0) -> 17222 | I33: =IFERROR(I27-I30,0) -> 19851 | J33: =IFERROR(J27-J30,0) -> 21407 | ... L33: =IFERROR(L27-L30,0) -> 23150 | M33: =IFERROR(SUM('Data Sheet'!H49:K49),0) -> 28124
B34: Net Margin | C34: =C33/C6 -> 0.16606076 | D34: =D33/D6 -> 0.16504585 | E34: =E33/E6 -> 0.18034089 | F34: =F33/F6 -> 0.15153311 | G34: =G33/G6 -> 0.15239396 | H34: =H33/H6 -> 0.17141094 | I34: =I33/I6 -> 0.16319333 | J34: =J33/J6 -> 0.14585704 | ... M34: =M33/M6 -> 0.16596443
B36: No of Equity Share | C36: =IFERROR('Data Sheet'!B93,0) -> 459.39 | D36: =IFERROR('Data Sheet'!C93,0) -> 459.39 | E36: =IFERROR('Data Sheet'!D93,0) -> 436.82 | F36: =IFERROR('Data Sheet'!E93,0) -> 436.89 | G36: =IFERROR('Data Sheet'!F93,0) -> 425.9 | H36: =IFERROR('Data Sheet'!G93,0) -> 426.07 | I36: =IFERROR('Data Sheet'!H93,0) -> 420.67 | J36: =IFERROR('Data Sheet'!I93,0) -> 414.86 | ... L36: =IFERROR('Data Sheet'!K93,0) -> 415.33
B38: Earning per Share | C38: =IFERROR(C36/C33,0) -> 0.044304176 | D38: =IFERROR(D36/D33,0) -> 0.040643192 | E38: =IFERROR(E36/E33,0) -> 0.034346595 | F38: =IFERROR(F36/F33,0) -> 0.034873084 | G38: =IFERROR(G36/G33,0) -> 0.030782018 | H38: =IFERROR(H36/H33,0) -> 0.024739868 | I38: =IFERROR(I36/I33,0) -> 0.021191376 | J38: =IFERROR(J36/J33,0) -> 0.019379642 | ... L38: =IFERROR(L36/L33,0) -> 0.017940821
B39: EPS Growth % | C39: 0 | D39: =IFERROR(D38/C38-1,0) -> -0.082632929 | E39: =IFERROR(E38/D38-1,0) -> -0.15492377 | F39: =IFERROR(F38/E38-1,0) -> 0.015328708 | G39: =IFERROR(G38/F38-1,0) -> -0.11731301 | H39: =IFERROR(H38/G38-1,0) -> -0.19628831 | I39: =IFERROR(I38/H38-1,0) -> -0.14343213 | J39: =IFERROR(J38/I38-1,0) -> -0.08549391 | K39: =IFERROR(K38/J38-1,0) -> -0.0054850664 | L39: =IFERROR(L38/K38-1,0) -> -0.069138124
B41: Dividend per Share | C41: =IFERROR('Data Sheet'!B31/'Historical FS'!C36,0) -> 12.077755 | D41: =IFERROR('Data Sheet'!C31/'Historical FS'!D36,0) -> 12.824833 | E41: =IFERROR('Data Sheet'!D31/'Historical FS'!E36,0) -> 21.669337 | F41: =IFERROR('Data Sheet'!E31/'Historical FS'!F36,0) -> 21.109433 | G41: =IFERROR('Data Sheet'!F31/'Historical FS'!G36,0) -> 17.438366 | H41: =IFERROR('Data Sheet'!G31/'Historical FS'!H36,0) -> 26.91952 | I41: =IFERROR('Data Sheet'!H31/'Historical FS'!I36,0) -> 30.92115 | J41: =IFERROR('Data Sheet'!I31/'Historical FS'!J36,0) -> 33.913127 | ... L41: =IFERROR('Data Sheet'!K31/'Historical FS'!L36,0) -> 42.924422
B42: Dividend Payout Ratio | C42: =IFERROR(C41/C38,0) -> 272.60986 | D42: =IFERROR(D41/D38,0) -> 315.54689 | E42: =IFERROR(E41/E38,0) -> 630.90205 | F42: =IFERROR(F41/F38,0) -> 605.32164 | G42: =IFERROR(G41/G38,0) -> 566.51146 | H42: =IFERROR(H41/H38,0) -> 1088.1028 | I42: =IFERROR(I41/I38,0) -> 1459.1384 | J42: =IFERROR(J41/J38,0) -> 1749.9357 | ... L42: =IFERROR(L41/L38,0) -> 2392.5562
B44: Retained Earnings | C44: =IFERROR(IF(C38>C41,1-C42,0),0) -> 0 | D44: =IFERROR(IF(D38>D41,1-D42,0),0) -> 0 | E44: =IFERROR(IF(E38>E41,1-E42,0),0) -> 0 | F44: =IFERROR(IF(F38>F41,1-F42,0),0) -> 0 | G44: =IFERROR(IF(G38>G41,1-G42,0),0) -> 0 | H44: =IFERROR(IF(H38>H41,1-H42,0),0) -> 0 | I44: =IFERROR(IF(I38>I41,1-I42,0),0) -> 0 | J44: =IFERROR(IF(J38>J41,1-J42,0),0) -> 0 | ... L44: =IFERROR(IF(L38>L41,1-L42,0),0) -> 0
A46: # | B46: Balance Sheet
B47: Equity Share Capital | C47: =IFERROR('Data Sheet'!B57,0) -> 1144 | D47: =IFERROR('Data Sheet'!C57,0) -> 1144 | E47: =IFERROR('Data Sheet'!D57,0) -> 1088 | F47: =IFERROR('Data Sheet'!E57,0) -> 2170 | G47: =IFERROR('Data Sheet'!F57,0) -> 2122 | H47: =IFERROR('Data Sheet'!G57,0) -> 2124 | I47: =IFERROR('Data Sheet'!H57,0) -> 2098 | J47: =IFERROR('Data Sheet'!I57,0) -> 2069 | ... L47: =IFERROR('Data Sheet'!K57,0) -> 2073
B48: Reserves | C48: =IFERROR('Data Sheet'!B58,0) -> 60600 | D48: =IFERROR('Data Sheet'!C58,0) -> 67838 | E48: =IFERROR('Data Sheet'!D58,0) -> 63835 | F48: =IFERROR('Data Sheet'!E58,0) -> 62778 | G48: =IFERROR('Data Sheet'!F58,0) -> 63328 | H48: =IFERROR('Data Sheet'!G58,0) -> 74227 | I48: =IFERROR('Data Sheet'!H58,0) -> 73252 | J48: =IFERROR('Data Sheet'!I58,0) -> 73338 | ... L48: =IFERROR('Data Sheet'!K58,0) -> 93745
B49: Borrowings | C49: =IFERROR('Data Sheet'!B59,0) -> 0 | D49: =IFERROR('Data Sheet'!C59,0) -> 0 | E49: =IFERROR('Data Sheet'!D59,0) -> 0 | F49: =IFERROR('Data Sheet'!E59,0) -> 0 | G49: =IFERROR('Data Sheet'!F59,0) -> 4633 | H49: =IFERROR('Data Sheet'!G59,0) -> 5325 | I49: =IFERROR('Data Sheet'!H59,0) -> 5474 | J49: =IFERROR('Data Sheet'!I59,0) -> 8299 | ... L49: =IFERROR('Data Sheet'!K59,0) -> 8227
B50: Other Liabilities | C50: =IFERROR('Data Sheet'!B60,0) -> 13354 | D50: =IFERROR('Data Sheet'!C60,0) -> 14166 | E50: =IFERROR('Data Sheet'!D60,0) -> 14426 | F50: =IFERROR('Data Sheet'!E60,0) -> 19118 | G50: =IFERROR('Data Sheet'!F60,0) -> 21717 | H50: =IFERROR('Data Sheet'!G60,0) -> 25835 | I50: =IFERROR('Data Sheet'!H60,0) -> 35905 | J50: =IFERROR('Data Sheet'!I60,0) -> 40890 | ... L50: =IFERROR('Data Sheet'!K60,0) -> 43750
B51: Total Liabilities | C51: =IFERROR('Data Sheet'!B61,0) -> 75098 | D51: =IFERROR('Data Sheet'!C61,0) -> 83148 | E51: =IFERROR('Data Sheet'!D61,0) -> 79349 | F51: =IFERROR('Data Sheet'!E61,0) -> 84066 | G51: =IFERROR('Data Sheet'!F61,0) -> 91800 | H51: =IFERROR('Data Sheet'!G61,0) -> 107511 | I51: =IFERROR('Data Sheet'!H61,0) -> 116729 | J51: =IFERROR('Data Sheet'!I61,0) -> 124596 | ... L51: =IFERROR('Data Sheet'!K61,0) -> 147795
B53: Fixed Assets Net Block | C53: =IFERROR('Data Sheet'!B62,0) -> 13386 | D53: =IFERROR('Data Sheet'!C62,0) -> 14179 | E53: =IFERROR('Data Sheet'!D62,0) -> 12574 | F53: =IFERROR('Data Sheet'!E62,0) -> 15710 | G53: =IFERROR('Data Sheet'!F62,0) -> 23789 | H53: =IFERROR('Data Sheet'!G62,0) -> 25505 | I53: =IFERROR('Data Sheet'!H62,0) -> 25800 | J53: =IFERROR('Data Sheet'!I62,0) -> 29225 | ... L53: =IFERROR('Data Sheet'!K62,0) -> 30961
B54: Capital Work in Progress | C54: =IFERROR('Data Sheet'!B63,0) -> 960 | D54: =IFERROR('Data Sheet'!C63,0) -> 1365 | E54: =IFERROR('Data Sheet'!D63,0) -> 1606 | F54: =IFERROR('Data Sheet'!E63,0) -> 1388 | G54: =IFERROR('Data Sheet'!F63,0) -> 954 | H54: =IFERROR('Data Sheet'!G63,0) -> 922 | I54: =IFERROR('Data Sheet'!H63,0) -> 416 | J54: =IFERROR('Data Sheet'!I63,0) -> 288 | ... L54: =IFERROR('Data Sheet'!K63,0) -> 814
B55: Investments | C55: =IFERROR('Data Sheet'!B64,0) -> 1892 | D55: =IFERROR('Data Sheet'!C64,0) -> 16423 | E55: =IFERROR('Data Sheet'!D64,0) -> 12163 | F55: =IFERROR('Data Sheet'!E64,0) -> 11261 | G55: =IFERROR('Data Sheet'!F64,0) -> 8792 | H55: =IFERROR('Data Sheet'!G64,0) -> 14205 | I55: =IFERROR('Data Sheet'!H64,0) -> 20324 | J55: =IFERROR('Data Sheet'!I64,0) -> 19478 | ... L55: =IFERROR('Data Sheet'!K64,0) -> 23541
